<mujoco model="base">
  <compiler angle="radian" meshdir="meshes/"/>
  <option timestep="0.01" impratio="20" tolerance="1e-06" density="1.2" viscosity="2e-05" integrator="implicitfast" cone="elliptic" solver="CG" noslip_iterations="100"/>
  <size njmax="5000" nconmax="5000"/>
  <visual>
    <map znear="0.001"/>
  </visual>
  <statistic meansize="0.093767" extent="10.6098" center="1.11639 0 1.5"/>
  <extension>
    <plugin plugin="mujoco.elasticity.shell">
      <instance name="cloth_flexcomp_cloth">
        <config key="face" value="0 10 11 0 11 1 1 11 12 1 12 2 2 12 13 2 13 3 3 13 14 3 14 4 4 14 15 4 15 5 5 15 16 5 16 6 6 16 17 6 17 7 7 17 18 7 18 8 8 18 19 8 19 9 10 20 21 10 21 11 11 21 22 11 22 12 12 22 23 12 23 13 13 23 24 13 24 14 14 24 25 14 25 15 15 25 26 15 26 16 16 26 27 16 27 17 17 27 28 17 28 18 18 28 29 18 29 19 20 30 31 20 31 21 21 31 32 21 32 22 22 32 33 22 33 23 23 33 34 23 34 24 24 34 35 24 35 25 25 35 36 25 36 26 26 36 37 26 37 27 27 37 38 27 38 28 28 38 39 28 39 29 30 40 41 30 41 31 31 41 42 31 42 32 32 42 43 32 43 33 33 43 44 33 44 34 34 44 45 34 45 35 35 45 46 35 46 36 36 46 47 36 47 37 37 47 48 37 48 38 38 48 49 38 49 39 40 50 51 40 51 41 41 51 52 41 52 42 42 52 53 42 53 43 43 53 54 43 54 44 44 54 55 44 55 45 45 55 56 45 56 46 46 56 57 46 57 47 47 57 58 47 58 48 48 58 59 48 59 49 50 60 61 50 61 51 51 61 62 51 62 52 52 62 63 52 63 53 53 63 64 53 64 54 54 64 65 54 65 55 55 65 66 55 66 56 56 66 67 56 67 57 57 67 68 57 68 58 58 68 69 58 69 59 60 70 71 60 71 61 61 71 72 61 72 62 62 72 73 62 73 63 63 73 74 63 74 64 64 74 75 64 75 65 65 75 76 65 76 66 66 76 77 66 77 67 67 77 78 67 78 68 68 78 79 68 79 69 70 80 81 70 81 71 71 81 82 71 82 72 72 82 83 72 83 73 73 83 84 73 84 74 74 84 85 74 85 75 75 85 86 75 86 76 76 86 87 76 87 77 77 87 88 77 88 78 78 88 89 78 89 79 80 90 91 80 91 81 81 91 92 81 92 82 82 92 93 82 93 83 83 93 94 83 94 84 84 94 95 84 95 85 85 95 96 85 96 86 86 96 97 86 97 87 87 97 98 87 98 88 88 98 99 88 99 89 90 100 101 90 101 91 91 101 102 91 102 92 92 102 103 92 103 93 93 103 104 93 104 94 94 104 105 94 105 95 95 105 106 95 106 96 96 106 107 96 107 97 97 107 108 97 108 98 98 108 109 98 109 99 100 110 111 100 111 101 101 111 112 101 112 102 102 112 113 102 113 103 103 113 114 103 114 104 104 114 115 104 115 105 105 115 116 105 116 106 106 116 117 106 117 107 107 117 118 107 118 108 108 118 119 108 119 109 110 120 121 110 121 111 111 121 122 111 122 112 112 122 123 112 123 113 113 123 124 113 124 114 114 124 125 114 125 115 115 125 126 115 126 116 116 126 127 116 127 117 117 127 128 117 128 118 118 128 129 118 129 119 120 130 131 120 131 121 121 131 132 121 132 122 122 132 133 122 133 123 123 133 134 123 134 124 124 134 135 124 135 125 125 135 136 125 136 126 126 136 137 126 137 127 127 137 138 127 138 128 128 138 139 128 139 129 130 140 141 130 141 131 131 141 142 131 142 132 132 142 143 132 143 133 133 143 144 133 144 134 134 144 145 134 145 135 135 145 146 135 146 136 136 146 147 136 147 137 137 147 148 137 148 138 138 148 149 138 149 139 140 150 151 140 151 141 141 151 152 141 152 142 142 152 153 142 153 143 143 153 154 143 154 144 144 154 155 144 155 145 145 155 156 145 156 146 146 156 157 146 157 147 147 157 158 147 158 148 148 158 159 148 159 149 150 160 161 150 161 151 151 161 162 151 162 152 152 162 163 152 163 153 153 163 164 153 164 154 154 164 165 154 165 155 155 165 166 155 166 156 156 166 167 156 167 157 157 167 168 157 168 158 158 168 169 158 169 159 160 170 171 160 171 161 161 171 172 161 172 162 162 172 173 162 173 163 163 173 174 163 174 164 164 174 175 164 175 165 165 175 176 165 176 166 166 176 177 166 177 167 167 177 178 167 178 168 168 178 179 168 179 169 170 180 181 170 181 171 171 181 182 171 182 172 172 182 183 172 183 173 173 183 184 173 184 174 174 184 185 174 185 175 175 185 186 175 186 176 176 186 187 176 187 177 177 187 188 177 188 178 178 188 189 178 189 179 180 190 191 180 191 181 181 191 192 181 192 182 182 192 193 182 193 183 183 193 194 183 194 184 184 194 195 184 195 185 185 195 196 185 196 186 186 196 197 186 197 187 187 197 198 187 198 188 188 198 199 188 199 189"/>
        <config key="edge" value="0 1 2 3 4 1 5 6 3 7 8 6 9 10 7 11 12 10 13 14 11 15 16 14 17 18 15 19 20 18 21 22 19 23 24 22 25 26 23 27 28 26 29 30 27 31 32 30 33 34 31 35 36 34 37 38 39 40 0 38 41 42 40 43 5 42 44 45 43 46 9 45 47 48 46 49 13 48 50 51 49 52 17 51 53 54 52 55 21 54 56 57 55 58 25 57 59 60 58 61 29 60 62 63 61 64 33 63 65 66 67 68 37 66 69 70 68 71 41 70 72 73 71 74 44 73 75 76 74 77 47 76 78 79 77 80 50 79 81 82 80 83 53 82 84 85 83 86 56 85 87 88 86 89 59 88 90 91 89 92 62 91 93 94 95 96 65 94 97 98 96 99 69 98 100 101 99 102 72 101 103 104 102 105 75 104 106 107 105 108 78 107 109 110 108 111 81 110 112 113 111 114 84 113 115 116 114 117 87 116 118 119 117 120 90 119 121 122 123 124 93 122 125 126 124 127 97 126 128 129 127 130 100 129 131 132 130 133 103 132 134 135 133 136 106 135 137 138 136 139 109 138 140 141 139 142 112 141 143 144 142 145 115 144 146 147 145 148 118 147 149 150 151 152 121 150 153 154 152 155 125 154 156 157 155 158 128 157 159 160 158 161 131 160 162 163 161 164 134 163 165 166 164 167 137 166 168 169 167 170 140 169 171 172 170 173 143 172 174 175 173 176 146 175 177 178 179 180 149 178 181 182 180 183 153 182 184 185 183 186 156 185 187 188 186 189 159 188 190 191 189 192 162 191 193 194 192 195 165 194 196 197 195 198 168 197 199 200 198 201 171 200 202 203 201 204 174 203 205 206 207 208 177 206 209 210 208 211 181 210 212 213 211 214 184 213 215 216 214 217 187 216 218 219 217 220 190 219 221 222 220 223 193 222 224 225 223 226 196 225 227 228 226 229 199 228 230 231 229 232 202 231 233 234 235 236 205 234 237 238 236 239 209 238 240 241 239 242 212 241 243 244 242 245 215 244 246 247 245 248 218 247 249 250 248 251 221 250 252 253 251 254 224 253 255 256 254 257 227 256 258 259 257 260 230 259 261 262 263 264 233 262 265 266 264 267 237 266 268 269 267 270 240 269 271 272 270 273 243 272 274 275 273 276 246 275 277 278 276 279 249 278 280 281 279 282 252 281 283 284 282 285 255 284 286 287 285 288 258 287 289 290 291 292 261 290 293 294 292 295 265 294 296 297 295 298 268 297 299 300 298 301 271 300 302 303 301 304 274 303 305 306 304 307 277 306 308 309 307 310 280 309 311 312 310 313 283 312 314 315 313 316 286 315 317 318 319 320 289 318 321 322 320 323 293 322 324 325 323 326 296 325 327 328 326 329 299 328 330 331 329 332 302 331 333 334 332 335 305 334 336 337 335 338 308 337 339 340 338 341 311 340 342 343 341 344 314 343 345 346 347 348 317 346 349 350 348 351 321 350 352 353 351 354 324 353 355 356 354 357 327 356 358 359 357 360 330 359 361 362 360 363 333 362 364 365 363 366 336 365 367 368 366 369 339 368 370 371 369 372 342 371 373 374 375 376 345 374 377 378 376 379 349 378 380 381 379 382 352 381 383 384 382 385 355 384 386 387 385 388 358 387 389 390 388 391 361 390 392 393 391 394 364 393 395 396 394 397 367 396 398 399 397 400 370 399 401 402 403 404 373 402 405 406 404 407 377 406 408 409 407 410 380 409 411 412 410 413 383 412 414 415 413 416 386 415 417 418 416 419 389 418 420 421 419 422 392 421 423 424 422 425 395 424 426 427 425 428 398 427 429 430 431 432 401 430 433 434 432 435 405 434 436 437 435 438 408 437 439 440 438 441 411 440 442 443 441 444 414 443 445 446 444 447 417 446 448 449 447 450 420 449 451 452 450 453 423 452 454 455 453 456 426 455 457 458 459 460 429 458 461 462 460 463 433 462 464 465 463 466 436 465 467 468 466 469 439 468 470 471 469 472 442 471 473 474 472 475 445 474 476 477 475 478 448 477 479 480 478 481 451 480 482 483 481 484 454 483 485 486 487 488 457 486 489 490 488 491 461 490 492 493 491 494 464 493 495 496 494 497 467 496 498 499 497 500 470 499 501 502 500 503 473 502 504 505 503 506 476 505 507 508 506 509 479 508 510 511 509 512 482 511 513 514 515 516 485 514 517 518 516 519 489 518 520 521 519 522 492 521 523 524 522 525 495 524 526 527 525 528 498 527 529 530 528 531 501 530 532 533 531 534 504 533 535 536 534 537 507 536 538 539 537 540 510 539 0 0 0 0 0 0 0 0 0 0 0 0 0 0 0 0 0 0 0 0 0 0 0 0 0 0 0 0 0 0 0 0 0 0 0 0 0 0 0 0 0 0 0 0 0 0 0 0 0 0 0 0 0 0 0 0 0 0 0 0 0 0 0 0 0 0 0 0 0 0 0 0 0 0 0 0 0 0 0 0 0 0 0 0 0 0 0 0 0 0 0 0 0 0 0 0 0 0 0 0 0 0 0 0 0 0 0 0 0 0 0 0 0 0 0 0 0 0 0 0 0 0 0 0 0 0 0 0 0 0 0 0 0 0 0 0 0 0 0 0 0 0 0 0 0 0 0 0 0 0 0 0 0 0 0 0 0 0 0 0 0 0 0 0 0 0 0 0 0 0 0 0 0 0 0 0 0 0 0 0 0 0 0 0 0 0 0 0 0 0 0 0 0 0 0 0 0 0 0 0 0 0 0 0 0 0 0 0 0 0 0 0 0 0 0 0 0 0 0 0 0 0 0 0 0 0 0 0 0 0 0 0 0 0 0 0 0 0 0 0 0 0 0 0 0 0 0 0 0 0 0 0 0 0 0 0 0 0 0 0 0 0 0 0 0 0 0 0 0 0 0 0 0 0 0 0 0 0 0 0 0 0 0 0 0 0 0 0 0 0 0 0 0 0 0 0 0 0 0 0 0 0 0 0 0 0 0 0 0 0 0 0 0 0 0 0 0 0 0 0 0 0 0 0 0 0 0 0 0 0 0 0 0 0 0 0 0 0 0 0 0 0 0 0 0 0 0 0 0 0 0 0 0 0 0 0 0 0 0 0 0 0 0 0 0 0 0 0 0 0 0 0 0 0 0 0 0 0 0 0 0 0 0 0 0 0 0 0 0 0 0 0 0 0 0 0 0 0 0 0 0 0 0 0 0 0 0 0 0 0 0 0 0 0 0 0 0 0 0 0 0 0 0 0 0 0 0 0 0 0 0 0 0 0 0 0 0 0 0 0 0 0 0 0 0 0 0 0 0 0 0 0 0 0 0 0 0 0 0 0 0 0 0 0 0 0 0 0 0 0 0 0 0 0 0 0 0 0 0 0 0 0 0 0 0 0 0 0 0 0 0 0 0 0 0 0 0 0 0 0 0 0 0 0 0 0 0 0 0 0 0 0 0 0 0 0 0 0 0 0 0 0 0 0 0 0 0 0 0 0 0 0 0 0 0 0 0 0 0 0 0 0 0 0 0 0 0 0 0 0 0 0 0 0 0 0 0 0 0 0 0 0 0 0 0 0 0 0 0 0 0 0 0 0 0 0 0 0 0 0 0 0 0 0 0 0 0 0 0 0 0 0 0 0 0 0 0 0 0 0 0 0 0 0 0 0 0 0 0 0 0 0 0 0 0 0 0 0 0 0 0 0 0 0 0 0 0 0 0 0 0 0 0 0 0 0 0 0 0 0 0 0 0 0 0 0 0 0 0 0 0 0 0 0 0 0 0 0 0 0 0 0 0 0 0 0 0 0 0 0 0 0 0 0 0 0 0 0 0 0 0 0 0 0 0 0 0 0 0 0 0 0 0 0 0 0 0 0 0 0 0 0 0 0 0 0 0 0 0 0 0 0 0 0 0 0 0 0 0 0 0 0 0 0 0 0 0 0 0 0 0 0 0 0 0 0 0 0 0 0 0 0 0 0 0 0 0 0 0 0 0 0 0 0 0 0 0 0 0 0 0 0 0 0 0 0 0 0 0 0 0 0 0 0 0 0 0 0 0 0 0 0 0 0 0 0 0 0 0 0 0 0 0 0 0 0 0 0 0 0 0 0 0 0 0 0 0 0 0 0 0 0 0 0 0 0 0 0 0 0 0 0 0 0 0 0 0 0 0 0 0 0 0 0 0 0 0 0 0 0 0 0 0 0 0 0 0 0 0 0 0 0 0 0 0 0 0 0 0 0 0 0 0 0 0 0 0 0 0 0 0 0 0 0 0 0 0 0 0 0 0 0 0 0 0 0 0 0 0 0 0 0 0 0 0 0 0 0 0 0 0 0 0 0 0 0 0 0 0 0 0 0 0 0 0 0 0 0 0 0 0 0 0 0 0 0 0 0 0 0 0 0 0 0 0 0 0 0 0 0 0 0 0 0 0 0 0 0 0 0 0 0 0 0 0 0 0 0 0 0 0 0 0 0 0 0 0 0 0 0 0 0 0 0 0 0 0 0 0 0 0 0 0 0 0 0 0 0 0 0 0 0 0 0 0 0 0 0 0 0 0 0 0 0 0 0 0 0 0 0 0 0 0 0 0 0 0 0 0 0 0 0 0 0 0 0 0 0 0 0 0 0 0 0 0 0 0 0 0 0 0 0 0 0 0 0 0 0 0 0 0 0 0 0 0 0 0 0 0 0 0 0 0 0 0 0 0 0 0 0 0 0 0 0 0 0 0 0 0 0 0 0 0 0 0 0 0 0 0 0 0 0 0 0 0 0 0 0 0 0 0 0 0 0 0 0 0 0 0 0 0 0 0 0 0 0 0 0 0 0 0 0 0 0 0 0 0 0 0 0 0 0 0 0 0 0 0 0 0 0 0 0 0 0 0 0 0 0 0 0 0 0 0 0 0 0 0 0 0 0 0 0 0 0 0 0 0 0 0 0 0 0 0 0 0 0 0 0 0 0 0 0 0 0 0 0 0 0 0 0 0 0 0 0 0 0 0 0 0 0 0 0 0 0 0 0 0 0 0 0 0 0 0 0 0 0 0 0 0 0 0 0 0 0 0 0 0 0 0 0 0 0 0 0 0 0 0 0 0 0 0 0 0 0 0 0 0 0 0 0 0 0 0 0 0 0 0 0 0 0 0 0 0 0 0 0 0 0 0 0 0 0 0 0 0 0 0 0 0 0 0 0 0 0 0 0 0 0 0 0 0 0 0 0 0 0 0 0 0 0 0 0 0 0 0 0 0 0 0 0 0 0 0 0 0 0 0 0 0 0 0 0 0 0 0 0 0 0 0 0 0 0 0 0 0 0 0 0 0 0 0 0 0 0 0 0 0 0 0 0 0 0 0 0 0 0 0 0 0 0 0 0 0 0 0 0 0 0 0 0 0 0 0 0 0 0 0 0 0 0 0 0 0 0 0 0 0 0 0 0 0 0 0 0 0 0 0 0 0 0 0 0 0 0 0 0 0 0 0 0 0 0 0 0 0 0 0 0 0 0 0 0 0 0 0 0 0 0 0 0 0 0 0 0 0 0 0 0 0 0 0 0 0 0 0 0 0 0 0 0 0 0 0 0 0 0 0 0 0 0 0 0 0 0 0 0 0 0 0 0 0 0 0 0 0 0 0 0 0 0 0 0 0 0 0 0 0 0 0 0 0 0 0 0 0 0 0 0 0 0 0 0 0 0 0 0 0 0 0 0 0 0 0 0 0 0 0 0 0 0 0 0 0 0 0 0 0 0 0 0 0 0 0 0 0 0 0 0 0 0 0 0 0 0 0 0 0 0 0 0 0 0 0 0 0 0 0 0 0 0 0 0 0 0 0 0 0 0 0 0 0 0 0 0 0 0 0 0 0 0 0 0 0 0 0 0 0 0 0 0 0 0 0 0 0 0 0 0 0 0 0 0 0 0 0 0 0 0 0 0 0 0 0 0 0 0 0 0 0 0 0 0 0 0 0 0 0 0 0 0 0 0 0 0 0 0 0 0 0 0 0 0 0 0 0 0 0 0 0 0 0 0 0 0 0 0 0 0 0 0 0 0 0 0 0 0 0 0 0 0 0 0 0 0 0 0 0 0 0 0 0 0 0 0 0 0 0 0 0 0 0 0 0 0 0 0 0 0 0 0 0 0 0 0 0 0 0 0 0 0 0 0 0 0 0 0 0 0 0 0 0 0 0 0 0 0 0 0 0 0 0 0 0 0 0 0 0 0 0 0 0 0 0 0 0 0 0 0 0 0 0 0 0 0 0 0 0 0 0 0 0 0 0 0 0 0 0 0 0 0 0 0 0 0 0 0 0 0 0 0 0 0 0 0 0 0 0 0 0 0 0 0 0 0 0 0 0 0 0 0 0 0 0 0 0 0 0 0 0 0 0 0 0 0 0 0 0 0 0 0 0 0 0 0 0 0 0 0 0 0 0 0 0 0 0 0 0 0 0 0 0 0 0 0 0 0 0 0 0 0 0 0 0 0 0 0 0 0 0 0 0 0 0 0 0 0 0 0 0 0 0 0 0 0 0 0 0 0 0 0 0 0 0 0 0 0 0 0 0 0 0 0 0 0 0 0 0 0 0 0 0 0 0 0 0 0 0 0 0 0 0 0 0 0 0 0 0 0 0 0 0 0 0 0 0 0 0 0 0 0 0 0 0 0 0 0 0 0 0 0 0 0 0 0 0 0 0 0 0 0 0 0 0 0 0 0 0 0 0 0 0 0 0 0 0 0 0 0 0 0 0 0 0 0 0 0 0 0 0 0 0 0 0 0 0 0 0 0 0 0 0 0 0 0 0 0 0 0 0 0 0 0 0 0 0 0 0 0 0 0 0 0 0 0 0 0 0 0 0 0 0 0 0 0 0 0 0 0 0 0 0 0 0 0 0 0 0 0 0 0 0 0 0 0 0 0 0 0 0 0 0 0"/>
        <config key="young" value="85242.02369946481"/>
        <config key="poisson" value="0.4032740512363587"/>
        <config key="thickness" value="0.0005"/>
      </instance>
    </plugin>
  </extension>
  <asset>
    <texture type="skybox" builtin="gradient" rgb1="0.9 0.9 1" rgb2="0.2 0.3 0.4" width="256" height="1536"/>
    <texture type="2d" name="texplane" file="/home/sachin/miniconda3/envs/robosuite/lib/python3.8/site-packages/robosuite/models/assets/arenas/../textures/light-gray-floor-tile.png"/>
    <texture type="cube" name="tex-ceramic" file="/home/sachin/miniconda3/envs/robosuite/lib/python3.8/site-packages/robosuite/models/assets/arenas/../textures/ceramic.png"/>
    <texture type="cube" name="tex-steel-brushed" file="/home/sachin/miniconda3/envs/robosuite/lib/python3.8/site-packages/robosuite/models/assets/arenas/../textures/steel-brushed.png"/>
    <texture type="2d" name="tex-light-gray-plaster" file="/home/sachin/miniconda3/envs/robosuite/lib/python3.8/site-packages/robosuite/models/assets/arenas/../textures/light-gray-plaster.png"/>
    <texture type="cube" name="textable" builtin="flat" rgb1="0.5 0.5 0.5" width="512" height="3072"/>
    <material name="floorplane" texture="texplane" texuniform="true" texrepeat="2 2" specular="0" shininess="0" reflectance="0.01"/>
    <material name="table_ceramic" texture="tex-ceramic" specular="0.2" shininess="0"/>
    <material name="table_legs_metal" texture="tex-steel-brushed" shininess="0.8" reflectance="0.8"/>
    <material name="walls_mat" texture="tex-light-gray-plaster" texuniform="true" texrepeat="3 3" specular="0.1" shininess="0.1"/>
    <material name="table_mat" texture="textable"/>
    <material name="robot0_Face636_001" shininess="0.45" rgba="0.901961 0.921569 0.929412 1"/>
    <material name="robot0_Part__Feature017_001" shininess="0.45"/>
    <material name="robot0_Part__Feature018_001" shininess="0.45"/>
    <material name="robot0_Part__Feature019_001" shininess="0.45"/>
    <material name="robot0_Part__Feature022_001" shininess="0.45" rgba="0.901961 0.921569 0.929412 1"/>
    <material name="robot0_Part__Feature023_001" shininess="0.45" rgba="0.25098 0.25098 0.25098 1"/>
    <material name="robot0_Shell001_001" shininess="0.45" rgba="0.25098 0.25098 0.25098 1"/>
    <material name="robot0_Shell002_001" shininess="0.45" rgba="0.901961 0.921569 0.929412 1"/>
    <material name="robot0_Shell003_001" shininess="0.45" rgba="0.901961 0.921569 0.929412 1"/>
    <material name="robot0_Shell009_001" shininess="0.45" rgba="0.25098 0.25098 0.25098 1"/>
    <material name="robot0_Shell010_001" shininess="0.45" rgba="0.901961 0.921569 0.929412 1"/>
    <material name="robot0_Shell_001" shininess="0.45" rgba="0.25098 0.25098 0.25098 1"/>
    <material name="robot0_Part__Feature_001" shininess="0.45"/>
    <material name="robot0_Part__Feature024" shininess="0.45"/>
    <material name="robot0_Part__Feature001_010_001_002" shininess="0.45"/>
    <material name="robot0_Part__Feature002_007_001_002" shininess="0.45"/>
    <material name="robot0_Part__Feature003_004_001_002" shininess="0.45"/>
    <material name="robot0_Part__Feature_001_001_001_002" shininess="0.45" rgba="0.25098 0.25098 0.25098 1"/>
    <material name="robot0_Part__Feature001_001_003_001" shininess="0.45"/>
    <material name="robot0_Part__Feature002_001_003_001" shininess="0.45" rgba="0.25098 0.25098 0.25098 1"/>
    <material name="robot0_Part__Feature003_001_003_001" shininess="0.45"/>
    <material name="robot0_Part__Feature_002_003_001" shininess="0.45"/>
    <material name="robot0_Part__Feature_002_004_003" shininess="0.45"/>
    <material name="robot0_Shell001_001_001_003" shininess="0.45" rgba="0.25 0.25 0.25 1"/>
    <material name="robot0_Shell_001_001_003" shininess="0.45"/>
    <material name="robot0_Face064_002_001_002_001" shininess="0.45" rgba="1 0 0 1"/>
    <material name="robot0_Face065_002_001_002_001" shininess="0.45" rgba="0 1 0 1"/>
    <material name="robot0_Face374_002_001_002_001" shininess="0.45"/>
    <material name="robot0_Face539_002_001_002_001" shininess="0.45" rgba="0.25098 0.25098 0.25098 1"/>
    <material name="robot0_Part__Feature001_009_001_002_001" shininess="0.45" rgba="0.25098 0.25098 0.25098 1"/>
    <material name="robot0_Part__Feature002_006_001_002_001" shininess="0.45" rgba="0.25098 0.25098 0.25098 1"/>
    <material name="robot0_Shell002_002_001_002_001" shininess="0.45"/>
    <material name="robot0_Shell003_002_001_002_001" shininess="0.45"/>
    <material name="robot0_Shell004_001_001_002_001" shininess="0.45"/>
    <material name="robot0_Shell005_001_001_002_001" shininess="0.45"/>
    <material name="robot0_Shell006_003_002_001" shininess="0.45" rgba="0.901961 0.921569 0.929412 1"/>
    <material name="robot0_Shell007_002_002_001" shininess="0.45" rgba="0.25 0.25 0.25 1"/>
    <material name="robot0_Shell011_002_002_001" shininess="0.45"/>
    <material name="robot0_Shell012_002_002_001" shininess="0.45"/>
    <material name="robot0_Shell_003_001_002_001" shininess="0.45" rgba="0.25098 0.25098 0.25098 1"/>
    <material name="robot0_Union001_001_001_002_001" shininess="0.45" rgba="0.039216 0.541176 0.780392 1"/>
    <material name="robot0_Union_001_001_002_001" shininess="0.45" rgba="0.039216 0.541176 0.780392 1"/>
    <material name="robot0_Part__Mirroring001_004_002" shininess="0.45" rgba="0.25098 0.25098 0.25098 1"/>
    <material name="robot0_Part__Mirroring002_004_001" shininess="0.45" rgba="0.25098 0.25098 0.25098 1"/>
    <material name="robot0_Part__Mirroring003_004_001" shininess="0.45" rgba="0.25098 0.25098 0.25098 1"/>
    <material name="robot0_Part__Mirroring004_004_002" shininess="0.45"/>
    <material name="robot0_Part__Mirroring005_004_001" shininess="0.45" rgba="0.25098 0.25098 0.25098 1"/>
    <material name="robot0_Part__Mirroring006_004_001" shininess="0.45" rgba="0.25098 0.25098 0.25098 1"/>
    <material name="robot0_Part__Mirroring007_004_001" shininess="0.45" rgba="0.25098 0.25098 0.25098 1"/>
    <material name="robot0_Part__Mirroring_004_001" shininess="0.45" rgba="0.898039 0.917647 0.929412 1"/>
    <mesh name="robot0_link0" file="/home/sachin/miniconda3/envs/robosuite/lib/python3.8/site-packages/robosuite/models/assets/robots/panda/meshes/link0.stl"/>
    <mesh name="robot0_link1" file="/home/sachin/miniconda3/envs/robosuite/lib/python3.8/site-packages/robosuite/models/assets/robots/panda/meshes/link1.stl"/>
    <mesh name="robot0_link2" file="/home/sachin/miniconda3/envs/robosuite/lib/python3.8/site-packages/robosuite/models/assets/robots/panda/meshes/link2.stl"/>
    <mesh name="robot0_link3" file="/home/sachin/miniconda3/envs/robosuite/lib/python3.8/site-packages/robosuite/models/assets/robots/panda/meshes/link3.stl"/>
    <mesh name="robot0_link4" file="/home/sachin/miniconda3/envs/robosuite/lib/python3.8/site-packages/robosuite/models/assets/robots/panda/meshes/link4.stl"/>
    <mesh name="robot0_link5" file="/home/sachin/miniconda3/envs/robosuite/lib/python3.8/site-packages/robosuite/models/assets/robots/panda/meshes/link5.stl"/>
    <mesh name="robot0_link6" file="/home/sachin/miniconda3/envs/robosuite/lib/python3.8/site-packages/robosuite/models/assets/robots/panda/meshes/link6.stl"/>
    <mesh name="robot0_link7" file="/home/sachin/miniconda3/envs/robosuite/lib/python3.8/site-packages/robosuite/models/assets/robots/panda/meshes/link7.stl"/>
    <mesh name="robot0_link0_vis_0" file="/home/sachin/miniconda3/envs/robosuite/lib/python3.8/site-packages/robosuite/models/assets/robots/panda/obj_meshes/link0_vis/link0_vis_0.obj"/>
    <mesh name="robot0_link0_vis_1" file="/home/sachin/miniconda3/envs/robosuite/lib/python3.8/site-packages/robosuite/models/assets/robots/panda/obj_meshes/link0_vis/link0_vis_1.obj"/>
    <mesh name="robot0_link0_vis_2" file="/home/sachin/miniconda3/envs/robosuite/lib/python3.8/site-packages/robosuite/models/assets/robots/panda/obj_meshes/link0_vis/link0_vis_2.obj"/>
    <mesh name="robot0_link0_vis_3" file="/home/sachin/miniconda3/envs/robosuite/lib/python3.8/site-packages/robosuite/models/assets/robots/panda/obj_meshes/link0_vis/link0_vis_3.obj"/>
    <mesh name="robot0_link0_vis_4" file="/home/sachin/miniconda3/envs/robosuite/lib/python3.8/site-packages/robosuite/models/assets/robots/panda/obj_meshes/link0_vis/link0_vis_4.obj"/>
    <mesh name="robot0_link0_vis_5" file="/home/sachin/miniconda3/envs/robosuite/lib/python3.8/site-packages/robosuite/models/assets/robots/panda/obj_meshes/link0_vis/link0_vis_5.obj"/>
    <mesh name="robot0_link0_vis_6" file="/home/sachin/miniconda3/envs/robosuite/lib/python3.8/site-packages/robosuite/models/assets/robots/panda/obj_meshes/link0_vis/link0_vis_6.obj"/>
    <mesh name="robot0_link0_vis_7" file="/home/sachin/miniconda3/envs/robosuite/lib/python3.8/site-packages/robosuite/models/assets/robots/panda/obj_meshes/link0_vis/link0_vis_7.obj"/>
    <mesh name="robot0_link0_vis_8" file="/home/sachin/miniconda3/envs/robosuite/lib/python3.8/site-packages/robosuite/models/assets/robots/panda/obj_meshes/link0_vis/link0_vis_8.obj"/>
    <mesh name="robot0_link0_vis_9" file="/home/sachin/miniconda3/envs/robosuite/lib/python3.8/site-packages/robosuite/models/assets/robots/panda/obj_meshes/link0_vis/link0_vis_9.obj"/>
    <mesh name="robot0_link0_vis_10" file="/home/sachin/miniconda3/envs/robosuite/lib/python3.8/site-packages/robosuite/models/assets/robots/panda/obj_meshes/link0_vis/link0_vis_10.obj"/>
    <mesh name="robot0_link0_vis_11" file="/home/sachin/miniconda3/envs/robosuite/lib/python3.8/site-packages/robosuite/models/assets/robots/panda/obj_meshes/link0_vis/link0_vis_11.obj"/>
    <mesh name="robot0_link1_vis" file="/home/sachin/miniconda3/envs/robosuite/lib/python3.8/site-packages/robosuite/models/assets/robots/panda/obj_meshes/link1_vis/link1_vis.obj"/>
    <mesh name="robot0_link2_vis" file="/home/sachin/miniconda3/envs/robosuite/lib/python3.8/site-packages/robosuite/models/assets/robots/panda/obj_meshes/link2_vis/link2_vis.obj"/>
    <mesh name="robot0_link3_vis_0" file="/home/sachin/miniconda3/envs/robosuite/lib/python3.8/site-packages/robosuite/models/assets/robots/panda/obj_meshes/link3_vis/link3_vis_0.obj"/>
    <mesh name="robot0_link3_vis_1" file="/home/sachin/miniconda3/envs/robosuite/lib/python3.8/site-packages/robosuite/models/assets/robots/panda/obj_meshes/link3_vis/link3_vis_1.obj"/>
    <mesh name="robot0_link3_vis_2" file="/home/sachin/miniconda3/envs/robosuite/lib/python3.8/site-packages/robosuite/models/assets/robots/panda/obj_meshes/link3_vis/link3_vis_2.obj"/>
    <mesh name="robot0_link3_vis_3" file="/home/sachin/miniconda3/envs/robosuite/lib/python3.8/site-packages/robosuite/models/assets/robots/panda/obj_meshes/link3_vis/link3_vis_3.obj"/>
    <mesh name="robot0_link4_vis_0" file="/home/sachin/miniconda3/envs/robosuite/lib/python3.8/site-packages/robosuite/models/assets/robots/panda/obj_meshes/link4_vis/link4_vis_0.obj"/>
    <mesh name="robot0_link4_vis_1" file="/home/sachin/miniconda3/envs/robosuite/lib/python3.8/site-packages/robosuite/models/assets/robots/panda/obj_meshes/link4_vis/link4_vis_1.obj"/>
    <mesh name="robot0_link4_vis_2" file="/home/sachin/miniconda3/envs/robosuite/lib/python3.8/site-packages/robosuite/models/assets/robots/panda/obj_meshes/link4_vis/link4_vis_2.obj"/>
    <mesh name="robot0_link4_vis_3" file="/home/sachin/miniconda3/envs/robosuite/lib/python3.8/site-packages/robosuite/models/assets/robots/panda/obj_meshes/link4_vis/link4_vis_3.obj"/>
    <mesh name="robot0_link5_vis_0" file="/home/sachin/miniconda3/envs/robosuite/lib/python3.8/site-packages/robosuite/models/assets/robots/panda/obj_meshes/link5_vis/link5_vis_0.obj"/>
    <mesh name="robot0_link5_vis_1" file="/home/sachin/miniconda3/envs/robosuite/lib/python3.8/site-packages/robosuite/models/assets/robots/panda/obj_meshes/link5_vis/link5_vis_1.obj"/>
    <mesh name="robot0_link5_vis_2" file="/home/sachin/miniconda3/envs/robosuite/lib/python3.8/site-packages/robosuite/models/assets/robots/panda/obj_meshes/link5_vis/link5_vis_2.obj"/>
    <mesh name="robot0_link6_vis_0" file="/home/sachin/miniconda3/envs/robosuite/lib/python3.8/site-packages/robosuite/models/assets/robots/panda/obj_meshes/link6_vis/link6_vis_0.obj"/>
    <mesh name="robot0_link6_vis_1" file="/home/sachin/miniconda3/envs/robosuite/lib/python3.8/site-packages/robosuite/models/assets/robots/panda/obj_meshes/link6_vis/link6_vis_1.obj"/>
    <mesh name="robot0_link6_vis_2" file="/home/sachin/miniconda3/envs/robosuite/lib/python3.8/site-packages/robosuite/models/assets/robots/panda/obj_meshes/link6_vis/link6_vis_2.obj"/>
    <mesh name="robot0_link6_vis_3" file="/home/sachin/miniconda3/envs/robosuite/lib/python3.8/site-packages/robosuite/models/assets/robots/panda/obj_meshes/link6_vis/link6_vis_3.obj"/>
    <mesh name="robot0_link6_vis_4" file="/home/sachin/miniconda3/envs/robosuite/lib/python3.8/site-packages/robosuite/models/assets/robots/panda/obj_meshes/link6_vis/link6_vis_4.obj"/>
    <mesh name="robot0_link6_vis_5" file="/home/sachin/miniconda3/envs/robosuite/lib/python3.8/site-packages/robosuite/models/assets/robots/panda/obj_meshes/link6_vis/link6_vis_5.obj"/>
    <mesh name="robot0_link6_vis_6" file="/home/sachin/miniconda3/envs/robosuite/lib/python3.8/site-packages/robosuite/models/assets/robots/panda/obj_meshes/link6_vis/link6_vis_6.obj"/>
    <mesh name="robot0_link6_vis_7" file="/home/sachin/miniconda3/envs/robosuite/lib/python3.8/site-packages/robosuite/models/assets/robots/panda/obj_meshes/link6_vis/link6_vis_7.obj"/>
    <mesh name="robot0_link6_vis_8" file="/home/sachin/miniconda3/envs/robosuite/lib/python3.8/site-packages/robosuite/models/assets/robots/panda/obj_meshes/link6_vis/link6_vis_8.obj"/>
    <mesh name="robot0_link6_vis_9" file="/home/sachin/miniconda3/envs/robosuite/lib/python3.8/site-packages/robosuite/models/assets/robots/panda/obj_meshes/link6_vis/link6_vis_9.obj"/>
    <mesh name="robot0_link6_vis_10" file="/home/sachin/miniconda3/envs/robosuite/lib/python3.8/site-packages/robosuite/models/assets/robots/panda/obj_meshes/link6_vis/link6_vis_10.obj"/>
    <mesh name="robot0_link6_vis_11" file="/home/sachin/miniconda3/envs/robosuite/lib/python3.8/site-packages/robosuite/models/assets/robots/panda/obj_meshes/link6_vis/link6_vis_11.obj"/>
    <mesh name="robot0_link6_vis_12" file="/home/sachin/miniconda3/envs/robosuite/lib/python3.8/site-packages/robosuite/models/assets/robots/panda/obj_meshes/link6_vis/link6_vis_12.obj"/>
    <mesh name="robot0_link6_vis_13" file="/home/sachin/miniconda3/envs/robosuite/lib/python3.8/site-packages/robosuite/models/assets/robots/panda/obj_meshes/link6_vis/link6_vis_13.obj"/>
    <mesh name="robot0_link6_vis_14" file="/home/sachin/miniconda3/envs/robosuite/lib/python3.8/site-packages/robosuite/models/assets/robots/panda/obj_meshes/link6_vis/link6_vis_14.obj"/>
    <mesh name="robot0_link6_vis_15" file="/home/sachin/miniconda3/envs/robosuite/lib/python3.8/site-packages/robosuite/models/assets/robots/panda/obj_meshes/link6_vis/link6_vis_15.obj"/>
    <mesh name="robot0_link6_vis_16" file="/home/sachin/miniconda3/envs/robosuite/lib/python3.8/site-packages/robosuite/models/assets/robots/panda/obj_meshes/link6_vis/link6_vis_16.obj"/>
    <mesh name="robot0_link7_vis_0" file="/home/sachin/miniconda3/envs/robosuite/lib/python3.8/site-packages/robosuite/models/assets/robots/panda/obj_meshes/link7_vis/link7_vis_0.obj"/>
    <mesh name="robot0_link7_vis_1" file="/home/sachin/miniconda3/envs/robosuite/lib/python3.8/site-packages/robosuite/models/assets/robots/panda/obj_meshes/link7_vis/link7_vis_1.obj"/>
    <mesh name="robot0_link7_vis_2" file="/home/sachin/miniconda3/envs/robosuite/lib/python3.8/site-packages/robosuite/models/assets/robots/panda/obj_meshes/link7_vis/link7_vis_2.obj"/>
    <mesh name="robot0_link7_vis_3" file="/home/sachin/miniconda3/envs/robosuite/lib/python3.8/site-packages/robosuite/models/assets/robots/panda/obj_meshes/link7_vis/link7_vis_3.obj"/>
    <mesh name="robot0_link7_vis_4" file="/home/sachin/miniconda3/envs/robosuite/lib/python3.8/site-packages/robosuite/models/assets/robots/panda/obj_meshes/link7_vis/link7_vis_4.obj"/>
    <mesh name="robot0_link7_vis_5" file="/home/sachin/miniconda3/envs/robosuite/lib/python3.8/site-packages/robosuite/models/assets/robots/panda/obj_meshes/link7_vis/link7_vis_5.obj"/>
    <mesh name="robot0_link7_vis_6" file="/home/sachin/miniconda3/envs/robosuite/lib/python3.8/site-packages/robosuite/models/assets/robots/panda/obj_meshes/link7_vis/link7_vis_6.obj"/>
    <mesh name="robot0_link7_vis_7" file="/home/sachin/miniconda3/envs/robosuite/lib/python3.8/site-packages/robosuite/models/assets/robots/panda/obj_meshes/link7_vis/link7_vis_7.obj"/>
    <mesh name="mount0_pedestal" file="/home/sachin/miniconda3/envs/robosuite/lib/python3.8/site-packages/robosuite/models/assets/mounts/meshes/rethink_mount/pedestal.stl"/>
    <mesh name="gripper0_hand" file="/home/sachin/miniconda3/envs/robosuite/lib/python3.8/site-packages/robosuite/models/assets/grippers/meshes/panda_gripper/hand.stl"/>
    <mesh name="gripper0_hand_vis" file="/home/sachin/miniconda3/envs/robosuite/lib/python3.8/site-packages/robosuite/models/assets/grippers/meshes/panda_gripper/hand_vis.stl"/>
    <mesh name="gripper0_finger" file="/home/sachin/miniconda3/envs/robosuite/lib/python3.8/site-packages/robosuite/models/assets/grippers/meshes/panda_gripper/finger.stl"/>
    <mesh name="gripper0_finger_vis" file="/home/sachin/miniconda3/envs/robosuite/lib/python3.8/site-packages/robosuite/models/assets/grippers/meshes/panda_gripper/finger_vis.stl"/>
    <mesh name="gripper0_finger_vis2" file="/home/sachin/miniconda3/envs/robosuite/lib/python3.8/site-packages/robosuite/models/assets/grippers/meshes/panda_gripper/finger_longer.stl"/>
  </asset>
  <worldbody>
    <geom name="floor" size="3 3 0.125" type="plane" group="1" material="floorplane"/>
    <geom name="wall_leftcorner_visual" size="1.06 1.5 0.01" pos="-1.25 2.25 1.5" quat="0.653281 0.653281 0.270598 0.270598" type="box" contype="0" conaffinity="0" group="1" material="walls_mat"/>
    <geom name="wall_rightcorner_visual" size="1.06 1.5 0.01" pos="-1.25 -2.25 1.5" quat="0.653281 0.653281 -0.270598 -0.270598" type="box" contype="0" conaffinity="0" group="1" material="walls_mat"/>
    <geom name="wall_left_visual" size="1.75 1.5 0.01" pos="1.25 3 1.5" quat="0.707107 0.707107 0 0" type="box" contype="0" conaffinity="0" group="1" material="walls_mat"/>
    <geom name="wall_right_visual" size="1.75 1.5 0.01" pos="1.25 -3 1.5" quat="0.707107 -0.707107 0 0" type="box" contype="0" conaffinity="0" group="1" material="walls_mat"/>
    <geom name="wall_rear_visual" size="1.5 1.5 0.01" pos="-2 0 1.5" quat="0.5 0.5 0.5 0.5" type="box" contype="0" conaffinity="0" group="1" material="walls_mat"/>
    <geom name="wall_front_visual" size="3 1.5 0.01" pos="3 0 1.5" quat="0.5 0.5 -0.5 -0.5" type="box" contype="0" conaffinity="0" group="1" material="walls_mat"/>
    <camera name="frontview" pos="1.6 0 1.45" quat="0.560842 0.430646 0.430646 0.560842"/>
    <camera name="birdview" pos="-0.2 0 3" quat="0.707107 0 0 0.707107"/>
    <camera name="agentview" pos="0.5 0 1.35" quat="0.653098 0.271041 0.271041 0.653098"/>
    <camera name="sideview" pos="-0.0565177 1.27612 1.48796" quat="0.00990507 0.00687796 0.591223 0.806418"/>
    <camera name="qdp" pos="0 0 2" quat="0.707107 0 0 0.707107"/>
    <light pos="1 1 1.5" dir="-0.19245 -0.19245 -0.96225" directional="true" castshadow="false"/>
    <body name="table" pos="0 0 0.775">
      <geom name="table_collision" size="0.4 0.4 0.025" type="box" rgba="0.5 0.5 0 1"/>
      <geom name="table_visual" size="0.4 0.4 0.025" type="box" contype="0" conaffinity="0" group="1" material="table_ceramic"/>
      <geom name="table_leg1_visual" size="0.025 0.3875" pos="0.3 0.3 -0.3875" type="cylinder" contype="0" conaffinity="0" group="1" material="table_legs_metal"/>
      <geom name="table_leg2_visual" size="0.025 0.3875" pos="-0.3 0.3 -0.3875" type="cylinder" contype="0" conaffinity="0" group="1" material="table_legs_metal"/>
      <geom name="table_leg3_visual" size="0.025 0.3875" pos="-0.3 -0.3 -0.3875" type="cylinder" contype="0" conaffinity="0" group="1" material="table_legs_metal"/>
      <geom name="table_leg4_visual" size="0.025 0.3875" pos="0.3 -0.3 -0.3875" type="cylinder" contype="0" conaffinity="0" group="1" material="table_legs_metal"/>
      <site name="table_top" pos="0 0 0.025" size="1e-08" rgba="0 0 0 0"/>
    </body>
    <body name="robot0_base" pos="-0.56 0 0.912">
      <inertial pos="0 0 0" mass="0" diaginertia="0 0 0"/>
      <camera name="robot0_robotview" pos="1 0 0.4" quat="0.653098 0.271041 0.271041 0.653098"/>
      <body name="robot0_link0">
        <inertial pos="0 0 0.05" mass="4" diaginertia="0.4 0.4 0.4"/>
        <geom name="robot0_g0_vis" type="mesh" contype="0" conaffinity="0" group="1" material="robot0_Shell010_001" mesh="robot0_link0_vis_0"/>
        <geom name="robot0_g1_vis" type="mesh" contype="0" conaffinity="0" group="1" material="robot0_Shell009_001" mesh="robot0_link0_vis_1"/>
        <geom name="robot0_g2_vis" type="mesh" contype="0" conaffinity="0" group="1" material="robot0_Shell003_001" mesh="robot0_link0_vis_2"/>
        <geom name="robot0_g3_vis" type="mesh" contype="0" conaffinity="0" group="1" material="robot0_Shell_001" mesh="robot0_link0_vis_3"/>
        <geom name="robot0_g4_vis" type="mesh" contype="0" conaffinity="0" group="1" material="robot0_Shell002_001" mesh="robot0_link0_vis_4"/>
        <geom name="robot0_g5_vis" type="mesh" contype="0" conaffinity="0" group="1" material="robot0_Shell001_001" mesh="robot0_link0_vis_5"/>
        <geom name="robot0_g6_vis" type="mesh" contype="0" conaffinity="0" group="1" material="robot0_Face636_001" mesh="robot0_link0_vis_6"/>
        <geom name="robot0_g7_vis" type="mesh" contype="0" conaffinity="0" group="1" material="robot0_Part__Feature018_001" mesh="robot0_link0_vis_7"/>
        <geom name="robot0_g8_vis" type="mesh" contype="0" conaffinity="0" group="1" material="robot0_Part__Feature019_001" mesh="robot0_link0_vis_8"/>
        <geom name="robot0_g9_vis" type="mesh" contype="0" conaffinity="0" group="1" material="robot0_Part__Feature023_001" mesh="robot0_link0_vis_9"/>
        <geom name="robot0_g10_vis" type="mesh" contype="0" conaffinity="0" group="1" material="robot0_Part__Feature022_001" mesh="robot0_link0_vis_10"/>
        <geom name="robot0_g11_vis" type="mesh" contype="0" conaffinity="0" group="1" material="robot0_Part__Feature017_001" mesh="robot0_link0_vis_11"/>
        <geom name="robot0_link0_collision" type="mesh" rgba="0 0.5 0 1" mesh="robot0_link0"/>
        <body name="robot0_link1" pos="0 0 0.333">
          <inertial pos="0 0 -0.07" mass="3" diaginertia="0.3 0.3 0.3"/>
          <joint name="robot0_joint1" pos="0 0 0" axis="0 0 1" range="-2.8973 2.8973" armature="5" damping="0.1" frictionloss="0.1"/>
          <geom name="robot0_g12_vis" type="mesh" contype="0" conaffinity="0" group="1" material="robot0_Part__Feature_001" mesh="robot0_link1_vis"/>
          <geom name="robot0_link1_collision" type="mesh" rgba="0 0.5 0 1" mesh="robot0_link1"/>
          <body name="robot0_link2" quat="0.707107 -0.707107 0 0">
            <inertial pos="0 -0.1 0" mass="3" diaginertia="0.3 0.3 0.3"/>
            <joint name="robot0_joint2" pos="0 0 0" axis="0 0 1" range="-1.7628 1.7628" armature="2.5" damping="0.1" frictionloss="0.1"/>
            <geom name="robot0_g13_vis" type="mesh" contype="0" conaffinity="0" group="1" material="robot0_Part__Feature024" mesh="robot0_link2_vis"/>
            <geom name="robot0_link2_collision" type="mesh" rgba="0 0.5 0 1" mesh="robot0_link2"/>
            <body name="robot0_link3" pos="0 -0.316 0" quat="0.707107 0.707107 0 0">
              <inertial pos="0.04 0 -0.05" mass="2" diaginertia="0.2 0.2 0.2"/>
              <joint name="robot0_joint3" pos="0 0 0" axis="0 0 1" range="-2.8973 2.8973" armature="1.66667" damping="0.1" frictionloss="0.1"/>
              <geom name="robot0_g14_vis" type="mesh" contype="0" conaffinity="0" group="1" material="robot0_Part__Feature003_004_001_002" mesh="robot0_link3_vis_0"/>
              <geom name="robot0_g15_vis" type="mesh" contype="0" conaffinity="0" group="1" material="robot0_Part__Feature002_007_001_002" mesh="robot0_link3_vis_1"/>
              <geom name="robot0_g16_vis" type="mesh" contype="0" conaffinity="0" group="1" material="robot0_Part__Feature001_010_001_002" mesh="robot0_link3_vis_2"/>
              <geom name="robot0_g17_vis" type="mesh" contype="0" conaffinity="0" group="1" material="robot0_Part__Feature_001_001_001_002" mesh="robot0_link3_vis_3"/>
              <geom name="robot0_link3_collision" type="mesh" rgba="0 0.5 0 1" mesh="robot0_link3"/>
              <body name="robot0_link4" pos="0.0825 0 0" quat="0.707107 0.707107 0 0">
                <inertial pos="-0.04 0.05 0" mass="2" diaginertia="0.2 0.2 0.2"/>
                <joint name="robot0_joint4" pos="0 0 0" axis="0 0 1" range="-3.0718 -0.0698" armature="1.25" damping="0.1" frictionloss="0.1"/>
                <geom name="robot0_g18_vis" type="mesh" contype="0" conaffinity="0" group="1" material="robot0_Part__Feature001_001_003_001" mesh="robot0_link4_vis_0"/>
                <geom name="robot0_g19_vis" type="mesh" contype="0" conaffinity="0" group="1" material="robot0_Part__Feature003_001_003_001" mesh="robot0_link4_vis_1"/>
                <geom name="robot0_g20_vis" type="mesh" contype="0" conaffinity="0" group="1" material="robot0_Part__Feature002_001_003_001" mesh="robot0_link4_vis_2"/>
                <geom name="robot0_g21_vis" type="mesh" contype="0" conaffinity="0" group="1" material="robot0_Part__Feature_002_003_001" mesh="robot0_link4_vis_3"/>
                <geom name="robot0_link4_collision" type="mesh" rgba="0 0.5 0 1" mesh="robot0_link4"/>
                <body name="robot0_link5" pos="-0.0825 0.384 0" quat="0.707107 -0.707107 0 0">
                  <inertial pos="0 0 -0.15" mass="2" diaginertia="0.2 0.2 0.2"/>
                  <joint name="robot0_joint5" pos="0 0 0" axis="0 0 1" range="-2.8973 2.8973" armature="1" damping="0.1" frictionloss="0.1"/>
                  <geom name="robot0_g22_vis" type="mesh" contype="0" conaffinity="0" group="1" material="robot0_Shell001_001_001_003" mesh="robot0_link5_vis_0"/>
                  <geom name="robot0_g23_vis" type="mesh" contype="0" conaffinity="0" group="1" material="robot0_Shell_001_001_003" mesh="robot0_link5_vis_1"/>
                  <geom name="robot0_g24_vis" type="mesh" contype="0" conaffinity="0" group="1" material="robot0_Part__Feature_002_004_003" mesh="robot0_link5_vis_2"/>
                  <geom name="robot0_link5_collision" type="mesh" rgba="0 0.5 0 1" mesh="robot0_link5"/>
                  <body name="robot0_link6" quat="0.707107 0.707107 0 0">
                    <inertial pos="0.06 0 0" mass="1.5" diaginertia="0.1 0.1 0.1"/>
                    <joint name="robot0_joint6" pos="0 0 0" axis="0 0 1" range="-0.0175 3.7525" armature="0.833333" damping="0.01" frictionloss="0.1"/>
                    <geom name="robot0_g25_vis" type="mesh" contype="0" conaffinity="0" group="1" material="robot0_Shell006_003_002_001" mesh="robot0_link6_vis_0"/>
                    <geom name="robot0_g26_vis" type="mesh" contype="0" conaffinity="0" group="1" material="robot0_Shell011_002_002_001" mesh="robot0_link6_vis_1"/>
                    <geom name="robot0_g27_vis" type="mesh" contype="0" conaffinity="0" group="1" material="robot0_Shell007_002_002_001" mesh="robot0_link6_vis_2"/>
                    <geom name="robot0_g28_vis" type="mesh" contype="0" conaffinity="0" group="1" material="robot0_Shell005_001_001_002_001" mesh="robot0_link6_vis_3"/>
                    <geom name="robot0_g29_vis" type="mesh" contype="0" conaffinity="0" group="1" material="robot0_Shell004_001_001_002_001" mesh="robot0_link6_vis_4"/>
                    <geom name="robot0_g30_vis" type="mesh" contype="0" conaffinity="0" group="1" material="robot0_Shell003_002_001_002_001" mesh="robot0_link6_vis_5"/>
                    <geom name="robot0_g31_vis" type="mesh" contype="0" conaffinity="0" group="1" material="robot0_Shell002_002_001_002_001" mesh="robot0_link6_vis_6"/>
                    <geom name="robot0_g32_vis" type="mesh" contype="0" conaffinity="0" group="1" material="robot0_Union001_001_001_002_001" mesh="robot0_link6_vis_7"/>
                    <geom name="robot0_g33_vis" type="mesh" contype="0" conaffinity="0" group="1" material="robot0_Union_001_001_002_001" mesh="robot0_link6_vis_8"/>
                    <geom name="robot0_g34_vis" type="mesh" contype="0" conaffinity="0" group="1" material="robot0_Face539_002_001_002_001" mesh="robot0_link6_vis_9"/>
                    <geom name="robot0_g35_vis" type="mesh" contype="0" conaffinity="0" group="1" material="robot0_Shell_003_001_002_001" mesh="robot0_link6_vis_10"/>
                    <geom name="robot0_g36_vis" type="mesh" contype="0" conaffinity="0" group="1" material="robot0_Face374_002_001_002_001" mesh="robot0_link6_vis_11"/>
                    <geom name="robot0_g37_vis" type="mesh" contype="0" conaffinity="0" group="1" material="robot0_Face065_002_001_002_001" mesh="robot0_link6_vis_12"/>
                    <geom name="robot0_g38_vis" type="mesh" contype="0" conaffinity="0" group="1" material="robot0_Face064_002_001_002_001" mesh="robot0_link6_vis_13"/>
                    <geom name="robot0_g39_vis" type="mesh" contype="0" conaffinity="0" group="1" material="robot0_Part__Feature002_006_001_002_001" mesh="robot0_link6_vis_14"/>
                    <geom name="robot0_g40_vis" type="mesh" contype="0" conaffinity="0" group="1" material="robot0_Part__Feature001_009_001_002_001" mesh="robot0_link6_vis_15"/>
                    <geom name="robot0_g41_vis" type="mesh" contype="0" conaffinity="0" group="1" material="robot0_Shell012_002_002_001" mesh="robot0_link6_vis_16"/>
                    <geom name="robot0_link6_collision" type="mesh" rgba="0 0.5 0 1" mesh="robot0_link6"/>
                    <body name="robot0_link7" pos="0.088 0 0" quat="0.707107 0.707107 0 0">
                      <inertial pos="0 0 0.08" mass="0.5" diaginertia="0.05 0.05 0.05"/>
                      <joint name="robot0_joint7" pos="0 0 0" axis="0 0 1" range="-2.8973 2.8973" armature="0.714286" damping="0.01" frictionloss="0.1"/>
                      <geom name="robot0_g42_vis" type="mesh" contype="0" conaffinity="0" group="1" material="robot0_Part__Mirroring004_004_002" mesh="robot0_link7_vis_0"/>
                      <geom name="robot0_g43_vis" type="mesh" contype="0" conaffinity="0" group="1" material="robot0_Part__Mirroring001_004_002" mesh="robot0_link7_vis_1"/>
                      <geom name="robot0_g44_vis" type="mesh" contype="0" conaffinity="0" group="1" material="robot0_Part__Mirroring007_004_001" mesh="robot0_link7_vis_2"/>
                      <geom name="robot0_g45_vis" type="mesh" contype="0" conaffinity="0" group="1" material="robot0_Part__Mirroring006_004_001" mesh="robot0_link7_vis_3"/>
                      <geom name="robot0_g46_vis" type="mesh" contype="0" conaffinity="0" group="1" material="robot0_Part__Mirroring005_004_001" mesh="robot0_link7_vis_4"/>
                      <geom name="robot0_g47_vis" type="mesh" contype="0" conaffinity="0" group="1" material="robot0_Part__Mirroring003_004_001" mesh="robot0_link7_vis_5"/>
                      <geom name="robot0_g48_vis" type="mesh" contype="0" conaffinity="0" group="1" material="robot0_Part__Mirroring002_004_001" mesh="robot0_link7_vis_6"/>
                      <geom name="robot0_g49_vis" type="mesh" contype="0" conaffinity="0" group="1" material="robot0_Part__Mirroring_004_001" mesh="robot0_link7_vis_7"/>
                      <body name="robot0_right_hand" pos="0 0 0.1065" quat="0.923785 0 0 -0.382911">
                        <inertial pos="0 0 0" mass="0.5" diaginertia="0.05 0.05 0.05"/>
                        <camera name="robot0_eye_in_hand" pos="0.05 0 0" quat="0 0.707107 0.707107 0" fovy="75"/>
                        <body name="gripper0_right_gripper" quat="0.707107 0 0 -0.707107">
                          <inertial pos="0 0 0.17" quat="0.707107 0.707107 0 0" mass="0.3" diaginertia="0.09 0.07 0.05"/>
                          <geom name="gripper0_hand_visual" quat="0.707107 0 0 0.707107" type="mesh" contype="0" conaffinity="0" group="1" rgba="1 1 1 1" mesh="gripper0_hand_vis"/>
                          <geom name="gripper0_hand_collision" quat="0.707107 0 0 0.707107" type="mesh" rgba="0 0 0.5 1" mesh="gripper0_hand"/>
                          <site name="gripper0_ft_frame" pos="0 0 0" size="1e-08" group="1" rgba="1 0 0 1"/>
                          <body name="gripper0_eef" pos="0 0 0.097">
                            <site name="gripper0_grip_site" pos="0 0 0" size="1e-08" group="1" rgba="1 0 0 0.5"/>
                            <site name="gripper0_ee_x" pos="0.1 0 0" quat="0.707105 0 0.707108 0" size="1e-08 1e-08" group="1" type="cylinder" rgba="1 0 0 0"/>
                            <site name="gripper0_ee_y" pos="0 0.1 0" quat="0.707105 0.707108 0 0" size="1e-08 1e-08" group="1" type="cylinder" rgba="0 1 0 0"/>
                            <site name="gripper0_ee_z" pos="0 0 0.1" size="1e-08 1e-08" group="1" type="cylinder" rgba="0 0 1 0"/>
                            <site name="gripper0_grip_site_cylinder" pos="0 0 0" size="1e-08 1e-08" group="1" type="cylinder" rgba="0 1 0 0.3"/>
                          </body>
                          <body name="gripper0_leftfinger" pos="0 0 0.0524" quat="0.707107 0 0 0.707107">
                            <inertial pos="0 0 0.05" mass="0.1" diaginertia="0.01 0.01 0.005"/>
                            <joint name="gripper0_finger_joint1" pos="0 0 0" axis="0 1 0" type="slide" range="0 0.04" armature="1" damping="100" frictionloss="1"/>
                            <geom name="gripper0_finger1_visual" type="mesh" contype="0" conaffinity="0" group="1" rgba="0.499 0.499 0.499 1" mesh="gripper0_finger_vis"/>
                            <geom name="gripper0_finger1_collision" type="mesh" contype="0" condim="4" rgba="0 0 0.5 1" mesh="gripper0_finger"/>
                            <body name="gripper0_finger_joint1_tip" pos="0 0.0085 0.056">
                              <inertial pos="0 0 0" quat="0 0 0 1" mass="0.01" diaginertia="0.01 0.01 0.01"/>
                              <geom name="gripper0_finger1_pad_collision" size="0.008 0.004 0.008" pos="0 -0.005 -0.015" quat="0 0 0 1" type="box" friction="2 0.05 0.0001" solref="0.01 0.5" rgba="0 0 0.5 1"/>
                            </body>
                          </body>
                          <body name="gripper0_rightfinger" pos="0 0 0.0524" quat="0.707107 0 0 0.707107">
                            <inertial pos="0 0 0.05" mass="0.1" diaginertia="0.01 0.01 0.005"/>
                            <joint name="gripper0_finger_joint2" pos="0 0 0" axis="0 1 0" type="slide" range="-0.04 0" armature="1" damping="100" frictionloss="1"/>
                            <geom name="gripper0_finger2_visual" quat="0 0 0 1" type="mesh" contype="0" conaffinity="0" group="1" rgba="0.499 0.499 0.499 1" mesh="gripper0_finger_vis"/>
                            <geom name="gripper0_finger2_collision" quat="0 0 0 1" type="mesh" contype="0" condim="4" rgba="0 0 0.5 1" mesh="gripper0_finger"/>
                            <body name="gripper0_finger_joint2_tip" pos="0 -0.0085 0.056">
                              <inertial pos="0 0 0" quat="0 0 0 1" mass="0.01" diaginertia="0.01 0.01 0.01"/>
                              <geom name="gripper0_finger2_pad_collision" size="0.008 0.004 0.008" pos="0 0.005 -0.015" quat="0 0 0 1" type="box" friction="2 0.05 0.0001" solref="0.01 0.5" rgba="0 0 0.5 1"/>
                            </body>
                          </body>
                        </body>
                      </body>
                    </body>
                  </body>
                </body>
              </body>
            </body>
          </body>
        </body>
      </body>
      <body name="mount0_base" pos="0 0 0.01">
        <body name="mount0_controller_box">
          <inertial pos="-0.325 0 -0.38" mass="46.64" diaginertia="1.71363 1.27988 0.809981"/>
          <geom name="mount0_controller_box_col" size="0.11 0.2 0.265" pos="-0.325 0 -0.38" type="box" rgba="0.5 0.5 0 1"/>
        </body>
        <body name="mount0_pedestal_feet">
          <inertial pos="-0.1225 0 -0.758" mass="167.09" diaginertia="8.16095 9.59375 15.0785"/>
          <geom name="mount0_pedestal_feet_col" size="0.385 0.35 0.155" pos="-0.1225 0 -0.758" type="box" rgba="0.5 0.5 0 1"/>
        </body>
        <body name="mount0_torso">
          <inertial pos="0 0 0" mass="0.0001" diaginertia="1e-08 1e-08 1e-08"/>
          <geom name="mount0_torso_vis" size="0.05 0.05 0.05" pos="0 0 -0.05" type="box" contype="0" conaffinity="0" group="1" rgba="0.2 0.2 0.2 1"/>
        </body>
        <body name="mount0_pedestal">
          <inertial pos="0 0 0" quat="0.659267 -0.259505 -0.260945 0.655692" mass="60.864" diaginertia="6.0869 5.81635 4.20915"/>
          <geom name="mount0_pedestal_vis" type="mesh" contype="0" conaffinity="0" group="1" rgba="0.2 0.2 0.2 1" mesh="mount0_pedestal"/>
          <geom name="mount0_pedestal_col" size="0.18 0.31" pos="-0.02 0 -0.29" type="cylinder" rgba="0.5 0.5 0 1"/>
        </body>
      </body>
    </body>
    <body name="cloth_main" pos="0 0 0.83">
      <site name="cloth_bottom_site" pos="0 0 -0.045" size="1e-08" rgba="0 0 0 0"/>
      <site name="cloth_top_site" pos="0 0 0.03" size="1e-08" rgba="0 0 0 0"/>
      <site name="cloth_horizontal_radius_site" pos="0.03 0.03 0" size="1e-08" rgba="0 0 0 0"/>
      <site name="cloth_default_site" pos="0 0 0" size="1e-08" rgba="1 0 0 0"/>
      <body name="cloth_0" pos="-0.13 -0.13 0.00076">
        <inertial pos="0 0 0" mass="0.0025" diaginertia="4.16667e-08 4.16667e-08 4.16667e-08"/>
        <joint pos="0 0 0" axis="1 0 0" type="slide"/>
        <joint pos="0 0 0" axis="0 1 0" type="slide"/>
        <joint pos="0 0 0" axis="0 0 1" type="slide"/>
        <plugin instance="cloth_flexcomp_cloth"/>
      </body>
      <body name="cloth_1" pos="-0.17 -0.11 0.00076">
        <inertial pos="0 0 0" mass="0.0025" diaginertia="4.16667e-08 4.16667e-08 4.16667e-08"/>
        <joint pos="0 0 0" axis="1 0 0" type="slide"/>
        <joint pos="0 0 0" axis="0 1 0" type="slide"/>
        <joint pos="0 0 0" axis="0 0 1" type="slide"/>
        <plugin instance="cloth_flexcomp_cloth"/>
      </body>
      <body name="cloth_2" pos="-0.21 -0.079 0.00076">
        <inertial pos="0 0 0" mass="0.0025" diaginertia="4.16667e-08 4.16667e-08 4.16667e-08"/>
        <joint pos="0 0 0" axis="1 0 0" type="slide"/>
        <joint pos="0 0 0" axis="0 1 0" type="slide"/>
        <joint pos="0 0 0" axis="0 0 1" type="slide"/>
        <plugin instance="cloth_flexcomp_cloth"/>
      </body>
      <body name="cloth_3" pos="-0.25 -0.051 0.00075">
        <inertial pos="0 0 0" mass="0.0025" diaginertia="4.16667e-08 4.16667e-08 4.16667e-08"/>
        <joint pos="0 0 0" axis="1 0 0" type="slide"/>
        <joint pos="0 0 0" axis="0 1 0" type="slide"/>
        <joint pos="0 0 0" axis="0 0 1" type="slide"/>
        <plugin instance="cloth_flexcomp_cloth"/>
      </body>
      <body name="cloth_4" pos="-0.22 -0.0073 0.00058">
        <inertial pos="0 0 0" mass="0.0025" diaginertia="4.16667e-08 4.16667e-08 4.16667e-08"/>
        <joint pos="0 0 0" axis="1 0 0" type="slide"/>
        <joint pos="0 0 0" axis="0 1 0" type="slide"/>
        <joint pos="0 0 0" axis="0 0 1" type="slide"/>
        <plugin instance="cloth_flexcomp_cloth"/>
      </body>
      <body name="cloth_5" pos="-0.26 0.032 0.0077">
        <inertial pos="0 0 0" mass="0.0025" diaginertia="4.16667e-08 4.16667e-08 4.16667e-08"/>
        <joint pos="0 0 0" axis="1 0 0" type="slide"/>
        <joint pos="0 0 0" axis="0 1 0" type="slide"/>
        <joint pos="0 0 0" axis="0 0 1" type="slide"/>
        <plugin instance="cloth_flexcomp_cloth"/>
      </body>
      <body name="cloth_6" pos="-0.29 -0.0048 0.00066">
        <inertial pos="0 0 0" mass="0.0025" diaginertia="4.16667e-08 4.16667e-08 4.16667e-08"/>
        <joint pos="0 0 0" axis="1 0 0" type="slide"/>
        <joint pos="0 0 0" axis="0 1 0" type="slide"/>
        <joint pos="0 0 0" axis="0 0 1" type="slide"/>
        <plugin instance="cloth_flexcomp_cloth"/>
      </body>
      <body name="cloth_7" pos="-0.33 0.023 0.00075">
        <inertial pos="0 0 0" mass="0.0025" diaginertia="4.16667e-08 4.16667e-08 4.16667e-08"/>
        <joint pos="0 0 0" axis="1 0 0" type="slide"/>
        <joint pos="0 0 0" axis="0 1 0" type="slide"/>
        <joint pos="0 0 0" axis="0 0 1" type="slide"/>
        <plugin instance="cloth_flexcomp_cloth"/>
      </body>
      <body name="cloth_8" pos="-0.37 0.053 0.00076">
        <inertial pos="0 0 0" mass="0.0025" diaginertia="4.16667e-08 4.16667e-08 4.16667e-08"/>
        <joint pos="0 0 0" axis="1 0 0" type="slide"/>
        <joint pos="0 0 0" axis="0 1 0" type="slide"/>
        <joint pos="0 0 0" axis="0 0 1" type="slide"/>
        <plugin instance="cloth_flexcomp_cloth"/>
      </body>
      <body name="cloth_9" pos="-0.41 0.083 0.00076">
        <inertial pos="0 0 0" mass="0.0025" diaginertia="4.16667e-08 4.16667e-08 4.16667e-08"/>
        <joint pos="0 0 0" axis="1 0 0" type="slide"/>
        <joint pos="0 0 0" axis="0 1 0" type="slide"/>
        <joint pos="0 0 0" axis="0 0 1" type="slide"/>
        <plugin instance="cloth_flexcomp_cloth"/>
      </body>
      <body name="cloth_10" pos="-0.1 -0.09 0.00076">
        <inertial pos="0 0 0" mass="0.0025" diaginertia="4.16667e-08 4.16667e-08 4.16667e-08"/>
        <joint pos="0 0 0" axis="1 0 0" type="slide"/>
        <joint pos="0 0 0" axis="0 1 0" type="slide"/>
        <joint pos="0 0 0" axis="0 0 1" type="slide"/>
        <plugin instance="cloth_flexcomp_cloth"/>
      </body>
      <body name="cloth_11" pos="-0.14 -0.063 0.00076">
        <inertial pos="0 0 0" mass="0.0025" diaginertia="4.16667e-08 4.16667e-08 4.16667e-08"/>
        <joint pos="0 0 0" axis="1 0 0" type="slide"/>
        <joint pos="0 0 0" axis="0 1 0" type="slide"/>
        <joint pos="0 0 0" axis="0 0 1" type="slide"/>
        <plugin instance="cloth_flexcomp_cloth"/>
      </body>
      <body name="cloth_12" pos="-0.18 -0.037 0.00075">
        <inertial pos="0 0 0" mass="0.0025" diaginertia="4.16667e-08 4.16667e-08 4.16667e-08"/>
        <joint pos="0 0 0" axis="1 0 0" type="slide"/>
        <joint pos="0 0 0" axis="0 1 0" type="slide"/>
        <joint pos="0 0 0" axis="0 0 1" type="slide"/>
        <plugin instance="cloth_flexcomp_cloth"/>
      </body>
      <body name="cloth_13" pos="-0.22 -0.0094 0.00067">
        <inertial pos="0 0 0" mass="0.0025" diaginertia="4.16667e-08 4.16667e-08 4.16667e-08"/>
        <joint pos="0 0 0" axis="1 0 0" type="slide"/>
        <joint pos="0 0 0" axis="0 1 0" type="slide"/>
        <joint pos="0 0 0" axis="0 0 1" type="slide"/>
        <plugin instance="cloth_flexcomp_cloth"/>
      </body>
      <body name="cloth_14" pos="-0.23 -0.0027 0.049">
        <inertial pos="0 0 0" mass="0.0025" diaginertia="4.16667e-08 4.16667e-08 4.16667e-08"/>
        <joint pos="0 0 0" axis="1 0 0" type="slide"/>
        <joint pos="0 0 0" axis="0 1 0" type="slide"/>
        <joint pos="0 0 0" axis="0 0 1" type="slide"/>
        <plugin instance="cloth_flexcomp_cloth"/>
      </body>
      <body name="cloth_15" pos="-0.28 0.0035 0.04">
        <inertial pos="0 0 0" mass="0.0025" diaginertia="4.16667e-08 4.16667e-08 4.16667e-08"/>
        <joint pos="0 0 0" axis="1 0 0" type="slide"/>
        <joint pos="0 0 0" axis="0 1 0" type="slide"/>
        <joint pos="0 0 0" axis="0 0 1" type="slide"/>
        <plugin instance="cloth_flexcomp_cloth"/>
      </body>
      <body name="cloth_16" pos="-0.32 0.018 0.021">
        <inertial pos="0 0 0" mass="0.0025" diaginertia="4.16667e-08 4.16667e-08 4.16667e-08"/>
        <joint pos="0 0 0" axis="1 0 0" type="slide"/>
        <joint pos="0 0 0" axis="0 1 0" type="slide"/>
        <joint pos="0 0 0" axis="0 0 1" type="slide"/>
        <plugin instance="cloth_flexcomp_cloth"/>
      </body>
      <body name="cloth_17" pos="-0.3 0.063 0.017">
        <inertial pos="0 0 0" mass="0.0025" diaginertia="4.16667e-08 4.16667e-08 4.16667e-08"/>
        <joint pos="0 0 0" axis="1 0 0" type="slide"/>
        <joint pos="0 0 0" axis="0 1 0" type="slide"/>
        <joint pos="0 0 0" axis="0 0 1" type="slide"/>
        <plugin instance="cloth_flexcomp_cloth"/>
      </body>
      <body name="cloth_18" pos="-0.34 0.093 0.00072">
        <inertial pos="0 0 0" mass="0.0025" diaginertia="4.16667e-08 4.16667e-08 4.16667e-08"/>
        <joint pos="0 0 0" axis="1 0 0" type="slide"/>
        <joint pos="0 0 0" axis="0 1 0" type="slide"/>
        <joint pos="0 0 0" axis="0 0 1" type="slide"/>
        <plugin instance="cloth_flexcomp_cloth"/>
      </body>
      <body name="cloth_19" pos="-0.38 0.12 0.00076">
        <inertial pos="0 0 0" mass="0.0025" diaginertia="4.16667e-08 4.16667e-08 4.16667e-08"/>
        <joint pos="0 0 0" axis="1 0 0" type="slide"/>
        <joint pos="0 0 0" axis="0 1 0" type="slide"/>
        <joint pos="0 0 0" axis="0 0 1" type="slide"/>
        <plugin instance="cloth_flexcomp_cloth"/>
      </body>
      <body name="cloth_20" pos="-0.073 -0.049 0.00076">
        <inertial pos="0 0 0" mass="0.0025" diaginertia="4.16667e-08 4.16667e-08 4.16667e-08"/>
        <joint pos="0 0 0" axis="1 0 0" type="slide"/>
        <joint pos="0 0 0" axis="0 1 0" type="slide"/>
        <joint pos="0 0 0" axis="0 0 1" type="slide"/>
        <plugin instance="cloth_flexcomp_cloth"/>
      </body>
      <body name="cloth_21" pos="-0.11 -0.02 0.00084">
        <inertial pos="0 0 0" mass="0.0025" diaginertia="4.16667e-08 4.16667e-08 4.16667e-08"/>
        <joint pos="0 0 0" axis="1 0 0" type="slide"/>
        <joint pos="0 0 0" axis="0 1 0" type="slide"/>
        <joint pos="0 0 0" axis="0 0 1" type="slide"/>
        <plugin instance="cloth_flexcomp_cloth"/>
      </body>
      <body name="cloth_22" pos="-0.16 0.0065 0.00084">
        <inertial pos="0 0 0" mass="0.0025" diaginertia="4.16667e-08 4.16667e-08 4.16667e-08"/>
        <joint pos="0 0 0" axis="1 0 0" type="slide"/>
        <joint pos="0 0 0" axis="0 1 0" type="slide"/>
        <joint pos="0 0 0" axis="0 0 1" type="slide"/>
        <plugin instance="cloth_flexcomp_cloth"/>
      </body>
      <body name="cloth_23" pos="-0.2 0.029 0.02">
        <inertial pos="0 0 0" mass="0.0025" diaginertia="4.16667e-08 4.16667e-08 4.16667e-08"/>
        <joint pos="0 0 0" axis="1 0 0" type="slide"/>
        <joint pos="0 0 0" axis="0 1 0" type="slide"/>
        <joint pos="0 0 0" axis="0 0 1" type="slide"/>
        <plugin instance="cloth_flexcomp_cloth"/>
      </body>
      <body name="cloth_24" pos="-0.24 0.046 0.041">
        <inertial pos="0 0 0" mass="0.0025" diaginertia="4.16667e-08 4.16667e-08 4.16667e-08"/>
        <joint pos="0 0 0" axis="1 0 0" type="slide"/>
        <joint pos="0 0 0" axis="0 1 0" type="slide"/>
        <joint pos="0 0 0" axis="0 0 1" type="slide"/>
        <plugin instance="cloth_flexcomp_cloth"/>
      </body>
      <body name="cloth_25" pos="-0.28 0.041 0.073">
        <inertial pos="0 0 0" mass="0.0025" diaginertia="4.16667e-08 4.16667e-08 4.16667e-08"/>
        <joint pos="0 0 0" axis="1 0 0" type="slide"/>
        <joint pos="0 0 0" axis="0 1 0" type="slide"/>
        <joint pos="0 0 0" axis="0 0 1" type="slide"/>
        <plugin instance="cloth_flexcomp_cloth"/>
      </body>
      <body name="cloth_26" pos="-0.33 0.052 0.058">
        <inertial pos="0 0 0" mass="0.0025" diaginertia="4.16667e-08 4.16667e-08 4.16667e-08"/>
        <joint pos="0 0 0" axis="1 0 0" type="slide"/>
        <joint pos="0 0 0" axis="0 1 0" type="slide"/>
        <joint pos="0 0 0" axis="0 0 1" type="slide"/>
        <plugin instance="cloth_flexcomp_cloth"/>
      </body>
      <body name="cloth_27" pos="-0.35 0.083 0.023">
        <inertial pos="0 0 0" mass="0.0025" diaginertia="4.16667e-08 4.16667e-08 4.16667e-08"/>
        <joint pos="0 0 0" axis="1 0 0" type="slide"/>
        <joint pos="0 0 0" axis="0 1 0" type="slide"/>
        <joint pos="0 0 0" axis="0 0 1" type="slide"/>
        <plugin instance="cloth_flexcomp_cloth"/>
      </body>
      <body name="cloth_28" pos="-0.33 0.13 0.037">
        <inertial pos="0 0 0" mass="0.0025" diaginertia="4.16667e-08 4.16667e-08 4.16667e-08"/>
        <joint pos="0 0 0" axis="1 0 0" type="slide"/>
        <joint pos="0 0 0" axis="0 1 0" type="slide"/>
        <joint pos="0 0 0" axis="0 0 1" type="slide"/>
        <plugin instance="cloth_flexcomp_cloth"/>
      </body>
      <body name="cloth_29" pos="-0.35 0.16 0.0044">
        <inertial pos="0 0 0" mass="0.0025" diaginertia="4.16667e-08 4.16667e-08 4.16667e-08"/>
        <joint pos="0 0 0" axis="1 0 0" type="slide"/>
        <joint pos="0 0 0" axis="0 1 0" type="slide"/>
        <joint pos="0 0 0" axis="0 0 1" type="slide"/>
        <plugin instance="cloth_flexcomp_cloth"/>
      </body>
      <body name="cloth_30" pos="-0.1 -0.089 0.00078">
        <inertial pos="0 0 0" mass="0.0025" diaginertia="4.16667e-08 4.16667e-08 4.16667e-08"/>
        <joint pos="0 0 0" axis="1 0 0" type="slide"/>
        <joint pos="0 0 0" axis="0 1 0" type="slide"/>
        <joint pos="0 0 0" axis="0 0 1" type="slide"/>
        <plugin instance="cloth_flexcomp_cloth"/>
      </body>
      <body name="cloth_31" pos="-0.14 -0.059 0.00048">
        <inertial pos="0 0 0" mass="0.0025" diaginertia="4.16667e-08 4.16667e-08 4.16667e-08"/>
        <joint pos="0 0 0" axis="1 0 0" type="slide"/>
        <joint pos="0 0 0" axis="0 1 0" type="slide"/>
        <joint pos="0 0 0" axis="0 0 1" type="slide"/>
        <plugin instance="cloth_flexcomp_cloth"/>
      </body>
      <body name="cloth_32" pos="-0.18 -0.034 0.016">
        <inertial pos="0 0 0" mass="0.0025" diaginertia="4.16667e-08 4.16667e-08 4.16667e-08"/>
        <joint pos="0 0 0" axis="1 0 0" type="slide"/>
        <joint pos="0 0 0" axis="0 1 0" type="slide"/>
        <joint pos="0 0 0" axis="0 0 1" type="slide"/>
        <plugin instance="cloth_flexcomp_cloth"/>
      </body>
      <body name="cloth_33" pos="-0.2 -0.008 0.053">
        <inertial pos="0 0 0" mass="0.0025" diaginertia="4.16667e-08 4.16667e-08 4.16667e-08"/>
        <joint pos="0 0 0" axis="1 0 0" type="slide"/>
        <joint pos="0 0 0" axis="0 1 0" type="slide"/>
        <joint pos="0 0 0" axis="0 0 1" type="slide"/>
        <plugin instance="cloth_flexcomp_cloth"/>
      </body>
      <body name="cloth_34" pos="-0.25 0.0026 0.065">
        <inertial pos="0 0 0" mass="0.0025" diaginertia="4.16667e-08 4.16667e-08 4.16667e-08"/>
        <joint pos="0 0 0" axis="1 0 0" type="slide"/>
        <joint pos="0 0 0" axis="0 1 0" type="slide"/>
        <joint pos="0 0 0" axis="0 0 1" type="slide"/>
        <plugin instance="cloth_flexcomp_cloth"/>
      </body>
      <body name="cloth_35" pos="-0.3 0.0012 0.045">
        <inertial pos="0 0 0" mass="0.0025" diaginertia="4.16667e-08 4.16667e-08 4.16667e-08"/>
        <joint pos="0 0 0" axis="1 0 0" type="slide"/>
        <joint pos="0 0 0" axis="0 1 0" type="slide"/>
        <joint pos="0 0 0" axis="0 0 1" type="slide"/>
        <plugin instance="cloth_flexcomp_cloth"/>
      </body>
      <body name="cloth_36" pos="-0.31 0.036 0.013">
        <inertial pos="0 0 0" mass="0.0025" diaginertia="4.16667e-08 4.16667e-08 4.16667e-08"/>
        <joint pos="0 0 0" axis="1 0 0" type="slide"/>
        <joint pos="0 0 0" axis="0 1 0" type="slide"/>
        <joint pos="0 0 0" axis="0 0 1" type="slide"/>
        <plugin instance="cloth_flexcomp_cloth"/>
      </body>
      <body name="cloth_37" pos="-0.3 0.083 0.00037">
        <inertial pos="0 0 0" mass="0.0025" diaginertia="4.16667e-08 4.16667e-08 4.16667e-08"/>
        <joint pos="0 0 0" axis="1 0 0" type="slide"/>
        <joint pos="0 0 0" axis="0 1 0" type="slide"/>
        <joint pos="0 0 0" axis="0 0 1" type="slide"/>
        <plugin instance="cloth_flexcomp_cloth"/>
      </body>
      <body name="cloth_38" pos="-0.3 0.13 0.0005">
        <inertial pos="0 0 0" mass="0.0025" diaginertia="4.16667e-08 4.16667e-08 4.16667e-08"/>
        <joint pos="0 0 0" axis="1 0 0" type="slide"/>
        <joint pos="0 0 0" axis="0 1 0" type="slide"/>
        <joint pos="0 0 0" axis="0 0 1" type="slide"/>
        <plugin instance="cloth_flexcomp_cloth"/>
      </body>
      <body name="cloth_39" pos="-0.3 0.18 0.001">
        <inertial pos="0 0 0" mass="0.0025" diaginertia="4.16667e-08 4.16667e-08 4.16667e-08"/>
        <joint pos="0 0 0" axis="1 0 0" type="slide"/>
        <joint pos="0 0 0" axis="0 1 0" type="slide"/>
        <joint pos="0 0 0" axis="0 0 1" type="slide"/>
        <plugin instance="cloth_flexcomp_cloth"/>
      </body>
      <body name="cloth_40" pos="-0.14 -0.13 0.00069">
        <inertial pos="0 0 0" mass="0.0025" diaginertia="4.16667e-08 4.16667e-08 4.16667e-08"/>
        <joint pos="0 0 0" axis="1 0 0" type="slide"/>
        <joint pos="0 0 0" axis="0 1 0" type="slide"/>
        <joint pos="0 0 0" axis="0 0 1" type="slide"/>
        <plugin instance="cloth_flexcomp_cloth"/>
      </body>
      <body name="cloth_41" pos="-0.18 -0.094 0.0025">
        <inertial pos="0 0 0" mass="0.0025" diaginertia="4.16667e-08 4.16667e-08 4.16667e-08"/>
        <joint pos="0 0 0" axis="1 0 0" type="slide"/>
        <joint pos="0 0 0" axis="0 1 0" type="slide"/>
        <joint pos="0 0 0" axis="0 0 1" type="slide"/>
        <plugin instance="cloth_flexcomp_cloth"/>
      </body>
      <body name="cloth_42" pos="-0.19 -0.073 0.045">
        <inertial pos="0 0 0" mass="0.0025" diaginertia="4.16667e-08 4.16667e-08 4.16667e-08"/>
        <joint pos="0 0 0" axis="1 0 0" type="slide"/>
        <joint pos="0 0 0" axis="0 1 0" type="slide"/>
        <joint pos="0 0 0" axis="0 0 1" type="slide"/>
        <plugin instance="cloth_flexcomp_cloth"/>
      </body>
      <body name="cloth_43" pos="-0.23 -0.047 0.071">
        <inertial pos="0 0 0" mass="0.0025" diaginertia="4.16667e-08 4.16667e-08 4.16667e-08"/>
        <joint pos="0 0 0" axis="1 0 0" type="slide"/>
        <joint pos="0 0 0" axis="0 1 0" type="slide"/>
        <joint pos="0 0 0" axis="0 0 1" type="slide"/>
        <plugin instance="cloth_flexcomp_cloth"/>
      </body>
      <body name="cloth_44" pos="-0.27 -0.038 0.039">
        <inertial pos="0 0 0" mass="0.0025" diaginertia="4.16667e-08 4.16667e-08 4.16667e-08"/>
        <joint pos="0 0 0" axis="1 0 0" type="slide"/>
        <joint pos="0 0 0" axis="0 1 0" type="slide"/>
        <joint pos="0 0 0" axis="0 0 1" type="slide"/>
        <plugin instance="cloth_flexcomp_cloth"/>
      </body>
      <body name="cloth_45" pos="-0.27 -0.0047 0.00076">
        <inertial pos="0 0 0" mass="0.0025" diaginertia="4.16667e-08 4.16667e-08 4.16667e-08"/>
        <joint pos="0 0 0" axis="1 0 0" type="slide"/>
        <joint pos="0 0 0" axis="0 1 0" type="slide"/>
        <joint pos="0 0 0" axis="0 0 1" type="slide"/>
        <plugin instance="cloth_flexcomp_cloth"/>
      </body>
      <body name="cloth_46" pos="-0.27 0.045 0.00023">
        <inertial pos="0 0 0" mass="0.0025" diaginertia="4.16667e-08 4.16667e-08 4.16667e-08"/>
        <joint pos="0 0 0" axis="1 0 0" type="slide"/>
        <joint pos="0 0 0" axis="0 1 0" type="slide"/>
        <joint pos="0 0 0" axis="0 0 1" type="slide"/>
        <plugin instance="cloth_flexcomp_cloth"/>
      </body>
      <body name="cloth_47" pos="-0.26 0.087 0.025">
        <inertial pos="0 0 0" mass="0.0025" diaginertia="4.16667e-08 4.16667e-08 4.16667e-08"/>
        <joint pos="0 0 0" axis="1 0 0" type="slide"/>
        <joint pos="0 0 0" axis="0 1 0" type="slide"/>
        <joint pos="0 0 0" axis="0 0 1" type="slide"/>
        <plugin instance="cloth_flexcomp_cloth"/>
      </body>
      <body name="cloth_48" pos="-0.25 0.13 0.0007">
        <inertial pos="0 0 0" mass="0.0025" diaginertia="4.16667e-08 4.16667e-08 4.16667e-08"/>
        <joint pos="0 0 0" axis="1 0 0" type="slide"/>
        <joint pos="0 0 0" axis="0 1 0" type="slide"/>
        <joint pos="0 0 0" axis="0 0 1" type="slide"/>
        <plugin instance="cloth_flexcomp_cloth"/>
      </body>
      <body name="cloth_49" pos="-0.25 0.18 0.00076">
        <inertial pos="0 0 0" mass="0.0025" diaginertia="4.16667e-08 4.16667e-08 4.16667e-08"/>
        <joint pos="0 0 0" axis="1 0 0" type="slide"/>
        <joint pos="0 0 0" axis="0 1 0" type="slide"/>
        <joint pos="0 0 0" axis="0 0 1" type="slide"/>
        <plugin instance="cloth_flexcomp_cloth"/>
      </body>
      <body name="cloth_50" pos="-0.13 -0.1 0.044">
        <inertial pos="0 0 0" mass="0.0025" diaginertia="4.16667e-08 4.16667e-08 4.16667e-08"/>
        <joint pos="0 0 0" axis="1 0 0" type="slide"/>
        <joint pos="0 0 0" axis="0 1 0" type="slide"/>
        <joint pos="0 0 0" axis="0 0 1" type="slide"/>
        <plugin instance="cloth_flexcomp_cloth"/>
      </body>
      <body name="cloth_51" pos="-0.18 -0.1 0.05">
        <inertial pos="0 0 0" mass="0.0025" diaginertia="4.16667e-08 4.16667e-08 4.16667e-08"/>
        <joint pos="0 0 0" axis="1 0 0" type="slide"/>
        <joint pos="0 0 0" axis="0 1 0" type="slide"/>
        <joint pos="0 0 0" axis="0 0 1" type="slide"/>
        <plugin instance="cloth_flexcomp_cloth"/>
      </body>
      <body name="cloth_52" pos="-0.23 -0.1 0.048">
        <inertial pos="0 0 0" mass="0.0025" diaginertia="4.16667e-08 4.16667e-08 4.16667e-08"/>
        <joint pos="0 0 0" axis="1 0 0" type="slide"/>
        <joint pos="0 0 0" axis="0 1 0" type="slide"/>
        <joint pos="0 0 0" axis="0 0 1" type="slide"/>
        <plugin instance="cloth_flexcomp_cloth"/>
      </body>
      <body name="cloth_53" pos="-0.26 -0.061 0.04">
        <inertial pos="0 0 0" mass="0.0025" diaginertia="4.16667e-08 4.16667e-08 4.16667e-08"/>
        <joint pos="0 0 0" axis="1 0 0" type="slide"/>
        <joint pos="0 0 0" axis="0 1 0" type="slide"/>
        <joint pos="0 0 0" axis="0 0 1" type="slide"/>
        <plugin instance="cloth_flexcomp_cloth"/>
      </body>
      <body name="cloth_54" pos="-0.23 -0.05 0.0012">
        <inertial pos="0 0 0" mass="0.0025" diaginertia="4.16667e-08 4.16667e-08 4.16667e-08"/>
        <joint pos="0 0 0" axis="1 0 0" type="slide"/>
        <joint pos="0 0 0" axis="0 1 0" type="slide"/>
        <joint pos="0 0 0" axis="0 0 1" type="slide"/>
        <plugin instance="cloth_flexcomp_cloth"/>
      </body>
      <body name="cloth_55" pos="-0.22 -0.0031 0.00036">
        <inertial pos="0 0 0" mass="0.0025" diaginertia="4.16667e-08 4.16667e-08 4.16667e-08"/>
        <joint pos="0 0 0" axis="1 0 0" type="slide"/>
        <joint pos="0 0 0" axis="0 1 0" type="slide"/>
        <joint pos="0 0 0" axis="0 0 1" type="slide"/>
        <plugin instance="cloth_flexcomp_cloth"/>
      </body>
      <body name="cloth_56" pos="-0.22 0.045 0.00077">
        <inertial pos="0 0 0" mass="0.0025" diaginertia="4.16667e-08 4.16667e-08 4.16667e-08"/>
        <joint pos="0 0 0" axis="1 0 0" type="slide"/>
        <joint pos="0 0 0" axis="0 1 0" type="slide"/>
        <joint pos="0 0 0" axis="0 0 1" type="slide"/>
        <plugin instance="cloth_flexcomp_cloth"/>
      </body>
      <body name="cloth_57" pos="-0.22 0.095 0.00071">
        <inertial pos="0 0 0" mass="0.0025" diaginertia="4.16667e-08 4.16667e-08 4.16667e-08"/>
        <joint pos="0 0 0" axis="1 0 0" type="slide"/>
        <joint pos="0 0 0" axis="0 1 0" type="slide"/>
        <joint pos="0 0 0" axis="0 0 1" type="slide"/>
        <plugin instance="cloth_flexcomp_cloth"/>
      </body>
      <body name="cloth_58" pos="-0.21 0.14 0.025">
        <inertial pos="0 0 0" mass="0.0025" diaginertia="4.16667e-08 4.16667e-08 4.16667e-08"/>
        <joint pos="0 0 0" axis="1 0 0" type="slide"/>
        <joint pos="0 0 0" axis="0 1 0" type="slide"/>
        <joint pos="0 0 0" axis="0 0 1" type="slide"/>
        <plugin instance="cloth_flexcomp_cloth"/>
      </body>
      <body name="cloth_59" pos="-0.2 0.18 0.00071">
        <inertial pos="0 0 0" mass="0.0025" diaginertia="4.16667e-08 4.16667e-08 4.16667e-08"/>
        <joint pos="0 0 0" axis="1 0 0" type="slide"/>
        <joint pos="0 0 0" axis="0 1 0" type="slide"/>
        <joint pos="0 0 0" axis="0 0 1" type="slide"/>
        <plugin instance="cloth_flexcomp_cloth"/>
      </body>
      <body name="cloth_60" pos="-0.14 -0.07 0.0058">
        <inertial pos="0 0 0" mass="0.0025" diaginertia="4.16667e-08 4.16667e-08 4.16667e-08"/>
        <joint pos="0 0 0" axis="1 0 0" type="slide"/>
        <joint pos="0 0 0" axis="0 1 0" type="slide"/>
        <joint pos="0 0 0" axis="0 0 1" type="slide"/>
        <plugin instance="cloth_flexcomp_cloth"/>
      </body>
      <body name="cloth_61" pos="-0.19 -0.093 0.00074">
        <inertial pos="0 0 0" mass="0.0025" diaginertia="4.16667e-08 4.16667e-08 4.16667e-08"/>
        <joint pos="0 0 0" axis="1 0 0" type="slide"/>
        <joint pos="0 0 0" axis="0 1 0" type="slide"/>
        <joint pos="0 0 0" axis="0 0 1" type="slide"/>
        <plugin instance="cloth_flexcomp_cloth"/>
      </body>
      <body name="cloth_62" pos="-0.23 -0.095 0.00037">
        <inertial pos="0 0 0" mass="0.0025" diaginertia="4.16667e-08 4.16667e-08 4.16667e-08"/>
        <joint pos="0 0 0" axis="1 0 0" type="slide"/>
        <joint pos="0 0 0" axis="0 1 0" type="slide"/>
        <joint pos="0 0 0" axis="0 0 1" type="slide"/>
        <plugin instance="cloth_flexcomp_cloth"/>
      </body>
      <body name="cloth_63" pos="-0.24 -0.046 0.00037">
        <inertial pos="0 0 0" mass="0.0025" diaginertia="4.16667e-08 4.16667e-08 4.16667e-08"/>
        <joint pos="0 0 0" axis="1 0 0" type="slide"/>
        <joint pos="0 0 0" axis="0 1 0" type="slide"/>
        <joint pos="0 0 0" axis="0 0 1" type="slide"/>
        <plugin instance="cloth_flexcomp_cloth"/>
      </body>
      <body name="cloth_64" pos="-0.22 -0.0073 0.023">
        <inertial pos="0 0 0" mass="0.0025" diaginertia="4.16667e-08 4.16667e-08 4.16667e-08"/>
        <joint pos="0 0 0" axis="1 0 0" type="slide"/>
        <joint pos="0 0 0" axis="0 1 0" type="slide"/>
        <joint pos="0 0 0" axis="0 0 1" type="slide"/>
        <plugin instance="cloth_flexcomp_cloth"/>
      </body>
      <body name="cloth_65" pos="-0.17 -0.0095 0.00086">
        <inertial pos="0 0 0" mass="0.0025" diaginertia="4.16667e-08 4.16667e-08 4.16667e-08"/>
        <joint pos="0 0 0" axis="1 0 0" type="slide"/>
        <joint pos="0 0 0" axis="0 1 0" type="slide"/>
        <joint pos="0 0 0" axis="0 0 1" type="slide"/>
        <plugin instance="cloth_flexcomp_cloth"/>
      </body>
      <body name="cloth_66" pos="-0.17 0.041 0.00074">
        <inertial pos="0 0 0" mass="0.0025" diaginertia="4.16667e-08 4.16667e-08 4.16667e-08"/>
        <joint pos="0 0 0" axis="1 0 0" type="slide"/>
        <joint pos="0 0 0" axis="0 1 0" type="slide"/>
        <joint pos="0 0 0" axis="0 0 1" type="slide"/>
        <plugin instance="cloth_flexcomp_cloth"/>
      </body>
      <body name="cloth_67" pos="-0.17 0.092 0.00076">
        <inertial pos="0 0 0" mass="0.0025" diaginertia="4.16667e-08 4.16667e-08 4.16667e-08"/>
        <joint pos="0 0 0" axis="1 0 0" type="slide"/>
        <joint pos="0 0 0" axis="0 1 0" type="slide"/>
        <joint pos="0 0 0" axis="0 0 1" type="slide"/>
        <plugin instance="cloth_flexcomp_cloth"/>
      </body>
      <body name="cloth_68" pos="-0.17 0.14 0.00071">
        <inertial pos="0 0 0" mass="0.0025" diaginertia="4.16667e-08 4.16667e-08 4.16667e-08"/>
        <joint pos="0 0 0" axis="1 0 0" type="slide"/>
        <joint pos="0 0 0" axis="0 1 0" type="slide"/>
        <joint pos="0 0 0" axis="0 0 1" type="slide"/>
        <plugin instance="cloth_flexcomp_cloth"/>
      </body>
      <body name="cloth_69" pos="-0.16 0.19 0.022">
        <inertial pos="0 0 0" mass="0.0025" diaginertia="4.16667e-08 4.16667e-08 4.16667e-08"/>
        <joint pos="0 0 0" axis="1 0 0" type="slide"/>
        <joint pos="0 0 0" axis="0 1 0" type="slide"/>
        <joint pos="0 0 0" axis="0 0 1" type="slide"/>
        <plugin instance="cloth_flexcomp_cloth"/>
      </body>
      <body name="cloth_70" pos="-0.17 -0.027 0.00076">
        <inertial pos="0 0 0" mass="0.0025" diaginertia="4.16667e-08 4.16667e-08 4.16667e-08"/>
        <joint pos="0 0 0" axis="1 0 0" type="slide"/>
        <joint pos="0 0 0" axis="0 1 0" type="slide"/>
        <joint pos="0 0 0" axis="0 0 1" type="slide"/>
        <plugin instance="cloth_flexcomp_cloth"/>
      </body>
      <body name="cloth_71" pos="-0.21 -0.051 0.0026">
        <inertial pos="0 0 0" mass="0.0025" diaginertia="4.16667e-08 4.16667e-08 4.16667e-08"/>
        <joint pos="0 0 0" axis="1 0 0" type="slide"/>
        <joint pos="0 0 0" axis="0 1 0" type="slide"/>
        <joint pos="0 0 0" axis="0 0 1" type="slide"/>
        <plugin instance="cloth_flexcomp_cloth"/>
      </body>
      <body name="cloth_72" pos="-0.24 -0.068 0.04">
        <inertial pos="0 0 0" mass="0.0025" diaginertia="4.16667e-08 4.16667e-08 4.16667e-08"/>
        <joint pos="0 0 0" axis="1 0 0" type="slide"/>
        <joint pos="0 0 0" axis="0 1 0" type="slide"/>
        <joint pos="0 0 0" axis="0 0 1" type="slide"/>
        <plugin instance="cloth_flexcomp_cloth"/>
      </body>
      <body name="cloth_73" pos="-0.2 -0.037 0.031">
        <inertial pos="0 0 0" mass="0.0025" diaginertia="4.16667e-08 4.16667e-08 4.16667e-08"/>
        <joint pos="0 0 0" axis="1 0 0" type="slide"/>
        <joint pos="0 0 0" axis="0 1 0" type="slide"/>
        <joint pos="0 0 0" axis="0 0 1" type="slide"/>
        <plugin instance="cloth_flexcomp_cloth"/>
      </body>
      <body name="cloth_74" pos="-0.17 -0.011 0.00069">
        <inertial pos="0 0 0" mass="0.0025" diaginertia="4.16667e-08 4.16667e-08 4.16667e-08"/>
        <joint pos="0 0 0" axis="1 0 0" type="slide"/>
        <joint pos="0 0 0" axis="0 1 0" type="slide"/>
        <joint pos="0 0 0" axis="0 0 1" type="slide"/>
        <plugin instance="cloth_flexcomp_cloth"/>
      </body>
      <body name="cloth_75" pos="-0.17 0.04 0.00017">
        <inertial pos="0 0 0" mass="0.0025" diaginertia="4.16667e-08 4.16667e-08 4.16667e-08"/>
        <joint pos="0 0 0" axis="1 0 0" type="slide"/>
        <joint pos="0 0 0" axis="0 1 0" type="slide"/>
        <joint pos="0 0 0" axis="0 0 1" type="slide"/>
        <plugin instance="cloth_flexcomp_cloth"/>
      </body>
      <body name="cloth_76" pos="-0.12 0.039 0.006">
        <inertial pos="0 0 0" mass="0.0025" diaginertia="4.16667e-08 4.16667e-08 4.16667e-08"/>
        <joint pos="0 0 0" axis="1 0 0" type="slide"/>
        <joint pos="0 0 0" axis="0 1 0" type="slide"/>
        <joint pos="0 0 0" axis="0 0 1" type="slide"/>
        <plugin instance="cloth_flexcomp_cloth"/>
      </body>
      <body name="cloth_77" pos="-0.12 0.089 0.00056">
        <inertial pos="0 0 0" mass="0.0025" diaginertia="4.16667e-08 4.16667e-08 4.16667e-08"/>
        <joint pos="0 0 0" axis="1 0 0" type="slide"/>
        <joint pos="0 0 0" axis="0 1 0" type="slide"/>
        <joint pos="0 0 0" axis="0 0 1" type="slide"/>
        <plugin instance="cloth_flexcomp_cloth"/>
      </body>
      <body name="cloth_78" pos="-0.12 0.14 0.00046">
        <inertial pos="0 0 0" mass="0.0025" diaginertia="4.16667e-08 4.16667e-08 4.16667e-08"/>
        <joint pos="0 0 0" axis="1 0 0" type="slide"/>
        <joint pos="0 0 0" axis="0 1 0" type="slide"/>
        <joint pos="0 0 0" axis="0 0 1" type="slide"/>
        <plugin instance="cloth_flexcomp_cloth"/>
      </body>
      <body name="cloth_79" pos="-0.11 0.19 0.0014">
        <inertial pos="0 0 0" mass="0.0025" diaginertia="4.16667e-08 4.16667e-08 4.16667e-08"/>
        <joint pos="0 0 0" axis="1 0 0" type="slide"/>
        <joint pos="0 0 0" axis="0 1 0" type="slide"/>
        <joint pos="0 0 0" axis="0 0 1" type="slide"/>
        <plugin instance="cloth_flexcomp_cloth"/>
      </body>
      <body name="cloth_80" pos="-0.21 -0.052 0.00066">
        <inertial pos="0 0 0" mass="0.0025" diaginertia="4.16667e-08 4.16667e-08 4.16667e-08"/>
        <joint pos="0 0 0" axis="1 0 0" type="slide"/>
        <joint pos="0 0 0" axis="0 1 0" type="slide"/>
        <joint pos="0 0 0" axis="0 0 1" type="slide"/>
        <plugin instance="cloth_flexcomp_cloth"/>
      </body>
      <body name="cloth_81" pos="-0.24 -0.0082 0.0007">
        <inertial pos="0 0 0" mass="0.0025" diaginertia="4.16667e-08 4.16667e-08 4.16667e-08"/>
        <joint pos="0 0 0" axis="1 0 0" type="slide"/>
        <joint pos="0 0 0" axis="0 1 0" type="slide"/>
        <joint pos="0 0 0" axis="0 0 1" type="slide"/>
        <plugin instance="cloth_flexcomp_cloth"/>
      </body>
      <body name="cloth_82" pos="-0.27 -0.028 0.033">
        <inertial pos="0 0 0" mass="0.0025" diaginertia="4.16667e-08 4.16667e-08 4.16667e-08"/>
        <joint pos="0 0 0" axis="1 0 0" type="slide"/>
        <joint pos="0 0 0" axis="0 1 0" type="slide"/>
        <joint pos="0 0 0" axis="0 0 1" type="slide"/>
        <plugin instance="cloth_flexcomp_cloth"/>
      </body>
      <body name="cloth_83" pos="-0.23 -0.0064 0.0057">
        <inertial pos="0 0 0" mass="0.0025" diaginertia="4.16667e-08 4.16667e-08 4.16667e-08"/>
        <joint pos="0 0 0" axis="1 0 0" type="slide"/>
        <joint pos="0 0 0" axis="0 1 0" type="slide"/>
        <joint pos="0 0 0" axis="0 0 1" type="slide"/>
        <plugin instance="cloth_flexcomp_cloth"/>
      </body>
      <body name="cloth_84" pos="-0.2 0.03 0.007">
        <inertial pos="0 0 0" mass="0.0025" diaginertia="4.16667e-08 4.16667e-08 4.16667e-08"/>
        <joint pos="0 0 0" axis="1 0 0" type="slide"/>
        <joint pos="0 0 0" axis="0 1 0" type="slide"/>
        <joint pos="0 0 0" axis="0 0 1" type="slide"/>
        <plugin instance="cloth_flexcomp_cloth"/>
      </body>
      <body name="cloth_85" pos="-0.17 0.043 0.048">
        <inertial pos="0 0 0" mass="0.0025" diaginertia="4.16667e-08 4.16667e-08 4.16667e-08"/>
        <joint pos="0 0 0" axis="1 0 0" type="slide"/>
        <joint pos="0 0 0" axis="0 1 0" type="slide"/>
        <joint pos="0 0 0" axis="0 0 1" type="slide"/>
        <plugin instance="cloth_flexcomp_cloth"/>
      </body>
      <body name="cloth_86" pos="-0.13 0.065 0.048">
        <inertial pos="0 0 0" mass="0.0025" diaginertia="4.16667e-08 4.16667e-08 4.16667e-08"/>
        <joint pos="0 0 0" axis="1 0 0" type="slide"/>
        <joint pos="0 0 0" axis="0 1 0" type="slide"/>
        <joint pos="0 0 0" axis="0 0 1" type="slide"/>
        <plugin instance="cloth_flexcomp_cloth"/>
      </body>
      <body name="cloth_87" pos="-0.087 0.094 0.038">
        <inertial pos="0 0 0" mass="0.0025" diaginertia="4.16667e-08 4.16667e-08 4.16667e-08"/>
        <joint pos="0 0 0" axis="1 0 0" type="slide"/>
        <joint pos="0 0 0" axis="0 1 0" type="slide"/>
        <joint pos="0 0 0" axis="0 0 1" type="slide"/>
        <plugin instance="cloth_flexcomp_cloth"/>
      </body>
      <body name="cloth_88" pos="-0.11 0.14 0.049">
        <inertial pos="0 0 0" mass="0.0025" diaginertia="4.16667e-08 4.16667e-08 4.16667e-08"/>
        <joint pos="0 0 0" axis="1 0 0" type="slide"/>
        <joint pos="0 0 0" axis="0 1 0" type="slide"/>
        <joint pos="0 0 0" axis="0 0 1" type="slide"/>
        <plugin instance="cloth_flexcomp_cloth"/>
      </body>
      <body name="cloth_89" pos="-0.083 0.18 0.042">
        <inertial pos="0 0 0" mass="0.0025" diaginertia="4.16667e-08 4.16667e-08 4.16667e-08"/>
        <joint pos="0 0 0" axis="1 0 0" type="slide"/>
        <joint pos="0 0 0" axis="0 1 0" type="slide"/>
        <joint pos="0 0 0" axis="0 0 1" type="slide"/>
        <plugin instance="cloth_flexcomp_cloth"/>
      </body>
      <body name="cloth_90" pos="-0.26 -0.067 0.00098">
        <inertial pos="0 0 0" mass="0.0025" diaginertia="4.16667e-08 4.16667e-08 4.16667e-08"/>
        <joint pos="0 0 0" axis="1 0 0" type="slide"/>
        <joint pos="0 0 0" axis="0 1 0" type="slide"/>
        <joint pos="0 0 0" axis="0 0 1" type="slide"/>
        <plugin instance="cloth_flexcomp_cloth"/>
      </body>
      <body name="cloth_91" pos="-0.27 -0.027 0.03">
        <inertial pos="0 0 0" mass="0.0025" diaginertia="4.16667e-08 4.16667e-08 4.16667e-08"/>
        <joint pos="0 0 0" axis="1 0 0" type="slide"/>
        <joint pos="0 0 0" axis="0 1 0" type="slide"/>
        <joint pos="0 0 0" axis="0 0 1" type="slide"/>
        <plugin instance="cloth_flexcomp_cloth"/>
      </body>
      <body name="cloth_92" pos="-0.28 0.02 0.046">
        <inertial pos="0 0 0" mass="0.0025" diaginertia="4.16667e-08 4.16667e-08 4.16667e-08"/>
        <joint pos="0 0 0" axis="1 0 0" type="slide"/>
        <joint pos="0 0 0" axis="0 1 0" type="slide"/>
        <joint pos="0 0 0" axis="0 0 1" type="slide"/>
        <plugin instance="cloth_flexcomp_cloth"/>
      </body>
      <body name="cloth_93" pos="-0.27 0.034 0.00069">
        <inertial pos="0 0 0" mass="0.0025" diaginertia="4.16667e-08 4.16667e-08 4.16667e-08"/>
        <joint pos="0 0 0" axis="1 0 0" type="slide"/>
        <joint pos="0 0 0" axis="0 1 0" type="slide"/>
        <joint pos="0 0 0" axis="0 0 1" type="slide"/>
        <plugin instance="cloth_flexcomp_cloth"/>
      </body>
      <body name="cloth_94" pos="-0.23 0.06 0.028">
        <inertial pos="0 0 0" mass="0.0025" diaginertia="4.16667e-08 4.16667e-08 4.16667e-08"/>
        <joint pos="0 0 0" axis="1 0 0" type="slide"/>
        <joint pos="0 0 0" axis="0 1 0" type="slide"/>
        <joint pos="0 0 0" axis="0 0 1" type="slide"/>
        <plugin instance="cloth_flexcomp_cloth"/>
      </body>
      <body name="cloth_95" pos="-0.19 0.089 0.043">
        <inertial pos="0 0 0" mass="0.0025" diaginertia="4.16667e-08 4.16667e-08 4.16667e-08"/>
        <joint pos="0 0 0" axis="1 0 0" type="slide"/>
        <joint pos="0 0 0" axis="0 1 0" type="slide"/>
        <joint pos="0 0 0" axis="0 0 1" type="slide"/>
        <plugin instance="cloth_flexcomp_cloth"/>
      </body>
      <body name="cloth_96" pos="-0.15 0.11 0.051">
        <inertial pos="0 0 0" mass="0.0025" diaginertia="4.16667e-08 4.16667e-08 4.16667e-08"/>
        <joint pos="0 0 0" axis="1 0 0" type="slide"/>
        <joint pos="0 0 0" axis="0 1 0" type="slide"/>
        <joint pos="0 0 0" axis="0 0 1" type="slide"/>
        <plugin instance="cloth_flexcomp_cloth"/>
      </body>
      <body name="cloth_97" pos="-0.11 0.13 0.063">
        <inertial pos="0 0 0" mass="0.0025" diaginertia="4.16667e-08 4.16667e-08 4.16667e-08"/>
        <joint pos="0 0 0" axis="1 0 0" type="slide"/>
        <joint pos="0 0 0" axis="0 1 0" type="slide"/>
        <joint pos="0 0 0" axis="0 0 1" type="slide"/>
        <plugin instance="cloth_flexcomp_cloth"/>
      </body>
      <body name="cloth_98" pos="-0.064 0.16 0.057">
        <inertial pos="0 0 0" mass="0.0025" diaginertia="4.16667e-08 4.16667e-08 4.16667e-08"/>
        <joint pos="0 0 0" axis="1 0 0" type="slide"/>
        <joint pos="0 0 0" axis="0 1 0" type="slide"/>
        <joint pos="0 0 0" axis="0 0 1" type="slide"/>
        <plugin instance="cloth_flexcomp_cloth"/>
      </body>
      <body name="cloth_99" pos="-0.055 0.16 0.0075">
        <inertial pos="0 0 0" mass="0.0025" diaginertia="4.16667e-08 4.16667e-08 4.16667e-08"/>
        <joint pos="0 0 0" axis="1 0 0" type="slide"/>
        <joint pos="0 0 0" axis="0 1 0" type="slide"/>
        <joint pos="0 0 0" axis="0 0 1" type="slide"/>
        <plugin instance="cloth_flexcomp_cloth"/>
      </body>
      <body name="cloth_100" pos="-0.31 -0.068 0.00063">
        <inertial pos="0 0 0" mass="0.0025" diaginertia="4.16667e-08 4.16667e-08 4.16667e-08"/>
        <joint pos="0 0 0" axis="1 0 0" type="slide"/>
        <joint pos="0 0 0" axis="0 1 0" type="slide"/>
        <joint pos="0 0 0" axis="0 0 1" type="slide"/>
        <plugin instance="cloth_flexcomp_cloth"/>
      </body>
      <body name="cloth_101" pos="-0.31 -0.017 0.00085">
        <inertial pos="0 0 0" mass="0.0025" diaginertia="4.16667e-08 4.16667e-08 4.16667e-08"/>
        <joint pos="0 0 0" axis="1 0 0" type="slide"/>
        <joint pos="0 0 0" axis="0 1 0" type="slide"/>
        <joint pos="0 0 0" axis="0 0 1" type="slide"/>
        <plugin instance="cloth_flexcomp_cloth"/>
      </body>
      <body name="cloth_102" pos="-0.3 0.032 0.00065">
        <inertial pos="0 0 0" mass="0.0025" diaginertia="4.16667e-08 4.16667e-08 4.16667e-08"/>
        <joint pos="0 0 0" axis="1 0 0" type="slide"/>
        <joint pos="0 0 0" axis="0 1 0" type="slide"/>
        <joint pos="0 0 0" axis="0 0 1" type="slide"/>
        <plugin instance="cloth_flexcomp_cloth"/>
      </body>
      <body name="cloth_103" pos="-0.29 0.079 0.0055">
        <inertial pos="0 0 0" mass="0.0025" diaginertia="4.16667e-08 4.16667e-08 4.16667e-08"/>
        <joint pos="0 0 0" axis="1 0 0" type="slide"/>
        <joint pos="0 0 0" axis="0 1 0" type="slide"/>
        <joint pos="0 0 0" axis="0 0 1" type="slide"/>
        <plugin instance="cloth_flexcomp_cloth"/>
      </body>
      <body name="cloth_104" pos="-0.24 0.099 0.00032">
        <inertial pos="0 0 0" mass="0.0025" diaginertia="4.16667e-08 4.16667e-08 4.16667e-08"/>
        <joint pos="0 0 0" axis="1 0 0" type="slide"/>
        <joint pos="0 0 0" axis="0 1 0" type="slide"/>
        <joint pos="0 0 0" axis="0 0 1" type="slide"/>
        <plugin instance="cloth_flexcomp_cloth"/>
      </body>
      <body name="cloth_105" pos="-0.2 0.11 0.0007">
        <inertial pos="0 0 0" mass="0.0025" diaginertia="4.16667e-08 4.16667e-08 4.16667e-08"/>
        <joint pos="0 0 0" axis="1 0 0" type="slide"/>
        <joint pos="0 0 0" axis="0 1 0" type="slide"/>
        <joint pos="0 0 0" axis="0 0 1" type="slide"/>
        <plugin instance="cloth_flexcomp_cloth"/>
      </body>
      <body name="cloth_106" pos="-0.15 0.13 0.0071">
        <inertial pos="0 0 0" mass="0.0025" diaginertia="4.16667e-08 4.16667e-08 4.16667e-08"/>
        <joint pos="0 0 0" axis="1 0 0" type="slide"/>
        <joint pos="0 0 0" axis="0 1 0" type="slide"/>
        <joint pos="0 0 0" axis="0 0 1" type="slide"/>
        <plugin instance="cloth_flexcomp_cloth"/>
      </body>
      <body name="cloth_107" pos="-0.11 0.16 0.02">
        <inertial pos="0 0 0" mass="0.0025" diaginertia="4.16667e-08 4.16667e-08 4.16667e-08"/>
        <joint pos="0 0 0" axis="1 0 0" type="slide"/>
        <joint pos="0 0 0" axis="0 1 0" type="slide"/>
        <joint pos="0 0 0" axis="0 0 1" type="slide"/>
        <plugin instance="cloth_flexcomp_cloth"/>
      </body>
      <body name="cloth_108" pos="-0.095 0.2 0.046">
        <inertial pos="0 0 0" mass="0.0025" diaginertia="4.16667e-08 4.16667e-08 4.16667e-08"/>
        <joint pos="0 0 0" axis="1 0 0" type="slide"/>
        <joint pos="0 0 0" axis="0 1 0" type="slide"/>
        <joint pos="0 0 0" axis="0 0 1" type="slide"/>
        <plugin instance="cloth_flexcomp_cloth"/>
      </body>
      <body name="cloth_109" pos="-0.099 0.18 0.00045">
        <inertial pos="0 0 0" mass="0.0025" diaginertia="4.16667e-08 4.16667e-08 4.16667e-08"/>
        <joint pos="0 0 0" axis="1 0 0" type="slide"/>
        <joint pos="0 0 0" axis="0 1 0" type="slide"/>
        <joint pos="0 0 0" axis="0 0 1" type="slide"/>
        <plugin instance="cloth_flexcomp_cloth"/>
      </body>
      <body name="cloth_110" pos="-0.26 -0.072 0.0044">
        <inertial pos="0 0 0" mass="0.0025" diaginertia="4.16667e-08 4.16667e-08 4.16667e-08"/>
        <joint pos="0 0 0" axis="1 0 0" type="slide"/>
        <joint pos="0 0 0" axis="0 1 0" type="slide"/>
        <joint pos="0 0 0" axis="0 0 1" type="slide"/>
        <plugin instance="cloth_flexcomp_cloth"/>
      </body>
      <body name="cloth_111" pos="-0.26 -0.024 0.021">
        <inertial pos="0 0 0" mass="0.0025" diaginertia="4.16667e-08 4.16667e-08 4.16667e-08"/>
        <joint pos="0 0 0" axis="1 0 0" type="slide"/>
        <joint pos="0 0 0" axis="0 1 0" type="slide"/>
        <joint pos="0 0 0" axis="0 0 1" type="slide"/>
        <plugin instance="cloth_flexcomp_cloth"/>
      </body>
      <body name="cloth_112" pos="-0.26 0.026 0.03">
        <inertial pos="0 0 0" mass="0.0025" diaginertia="4.16667e-08 4.16667e-08 4.16667e-08"/>
        <joint pos="0 0 0" axis="1 0 0" type="slide"/>
        <joint pos="0 0 0" axis="0 1 0" type="slide"/>
        <joint pos="0 0 0" axis="0 0 1" type="slide"/>
        <plugin instance="cloth_flexcomp_cloth"/>
      </body>
      <body name="cloth_113" pos="-0.25 0.075 0.037">
        <inertial pos="0 0 0" mass="0.0025" diaginertia="4.16667e-08 4.16667e-08 4.16667e-08"/>
        <joint pos="0 0 0" axis="1 0 0" type="slide"/>
        <joint pos="0 0 0" axis="0 1 0" type="slide"/>
        <joint pos="0 0 0" axis="0 0 1" type="slide"/>
        <plugin instance="cloth_flexcomp_cloth"/>
      </body>
      <body name="cloth_114" pos="-0.25 0.13 0.041">
        <inertial pos="0 0 0" mass="0.0025" diaginertia="4.16667e-08 4.16667e-08 4.16667e-08"/>
        <joint pos="0 0 0" axis="1 0 0" type="slide"/>
        <joint pos="0 0 0" axis="0 1 0" type="slide"/>
        <joint pos="0 0 0" axis="0 0 1" type="slide"/>
        <plugin instance="cloth_flexcomp_cloth"/>
      </body>
      <body name="cloth_115" pos="-0.21 0.16 0.019">
        <inertial pos="0 0 0" mass="0.0025" diaginertia="4.16667e-08 4.16667e-08 4.16667e-08"/>
        <joint pos="0 0 0" axis="1 0 0" type="slide"/>
        <joint pos="0 0 0" axis="0 1 0" type="slide"/>
        <joint pos="0 0 0" axis="0 0 1" type="slide"/>
        <plugin instance="cloth_flexcomp_cloth"/>
      </body>
      <body name="cloth_116" pos="-0.17 0.18 0.00077">
        <inertial pos="0 0 0" mass="0.0025" diaginertia="4.16667e-08 4.16667e-08 4.16667e-08"/>
        <joint pos="0 0 0" axis="1 0 0" type="slide"/>
        <joint pos="0 0 0" axis="0 1 0" type="slide"/>
        <joint pos="0 0 0" axis="0 0 1" type="slide"/>
        <plugin instance="cloth_flexcomp_cloth"/>
      </body>
      <body name="cloth_117" pos="-0.12 0.2 0.0008">
        <inertial pos="0 0 0" mass="0.0025" diaginertia="4.16667e-08 4.16667e-08 4.16667e-08"/>
        <joint pos="0 0 0" axis="1 0 0" type="slide"/>
        <joint pos="0 0 0" axis="0 1 0" type="slide"/>
        <joint pos="0 0 0" axis="0 0 1" type="slide"/>
        <plugin instance="cloth_flexcomp_cloth"/>
      </body>
      <body name="cloth_118" pos="-0.078 0.22 0.0013">
        <inertial pos="0 0 0" mass="0.0025" diaginertia="4.16667e-08 4.16667e-08 4.16667e-08"/>
        <joint pos="0 0 0" axis="1 0 0" type="slide"/>
        <joint pos="0 0 0" axis="0 1 0" type="slide"/>
        <joint pos="0 0 0" axis="0 0 1" type="slide"/>
        <plugin instance="cloth_flexcomp_cloth"/>
      </body>
      <body name="cloth_119" pos="-0.049 0.17 0.00057">
        <inertial pos="0 0 0" mass="0.0025" diaginertia="4.16667e-08 4.16667e-08 4.16667e-08"/>
        <joint pos="0 0 0" axis="1 0 0" type="slide"/>
        <joint pos="0 0 0" axis="0 1 0" type="slide"/>
        <joint pos="0 0 0" axis="0 0 1" type="slide"/>
        <plugin instance="cloth_flexcomp_cloth"/>
      </body>
      <body name="cloth_120" pos="-0.21 -0.067 0.00082">
        <inertial pos="0 0 0" mass="0.0025" diaginertia="4.16667e-08 4.16667e-08 4.16667e-08"/>
        <joint pos="0 0 0" axis="1 0 0" type="slide"/>
        <joint pos="0 0 0" axis="0 1 0" type="slide"/>
        <joint pos="0 0 0" axis="0 0 1" type="slide"/>
        <plugin instance="cloth_flexcomp_cloth"/>
      </body>
      <body name="cloth_121" pos="-0.22 -0.019 0.00068">
        <inertial pos="0 0 0" mass="0.0025" diaginertia="4.16667e-08 4.16667e-08 4.16667e-08"/>
        <joint pos="0 0 0" axis="1 0 0" type="slide"/>
        <joint pos="0 0 0" axis="0 1 0" type="slide"/>
        <joint pos="0 0 0" axis="0 0 1" type="slide"/>
        <plugin instance="cloth_flexcomp_cloth"/>
      </body>
      <body name="cloth_122" pos="-0.22 0.029 0.00059">
        <inertial pos="0 0 0" mass="0.0025" diaginertia="4.16667e-08 4.16667e-08 4.16667e-08"/>
        <joint pos="0 0 0" axis="1 0 0" type="slide"/>
        <joint pos="0 0 0" axis="0 1 0" type="slide"/>
        <joint pos="0 0 0" axis="0 0 1" type="slide"/>
        <plugin instance="cloth_flexcomp_cloth"/>
      </body>
      <body name="cloth_123" pos="-0.22 0.078 0.0031">
        <inertial pos="0 0 0" mass="0.0025" diaginertia="4.16667e-08 4.16667e-08 4.16667e-08"/>
        <joint pos="0 0 0" axis="1 0 0" type="slide"/>
        <joint pos="0 0 0" axis="0 1 0" type="slide"/>
        <joint pos="0 0 0" axis="0 0 1" type="slide"/>
        <plugin instance="cloth_flexcomp_cloth"/>
      </body>
      <body name="cloth_124" pos="-0.2 0.12 0.02">
        <inertial pos="0 0 0" mass="0.0025" diaginertia="4.16667e-08 4.16667e-08 4.16667e-08"/>
        <joint pos="0 0 0" axis="1 0 0" type="slide"/>
        <joint pos="0 0 0" axis="0 1 0" type="slide"/>
        <joint pos="0 0 0" axis="0 0 1" type="slide"/>
        <plugin instance="cloth_flexcomp_cloth"/>
      </body>
      <body name="cloth_125" pos="-0.18 0.15 0.055">
        <inertial pos="0 0 0" mass="0.0025" diaginertia="4.16667e-08 4.16667e-08 4.16667e-08"/>
        <joint pos="0 0 0" axis="1 0 0" type="slide"/>
        <joint pos="0 0 0" axis="0 1 0" type="slide"/>
        <joint pos="0 0 0" axis="0 0 1" type="slide"/>
        <plugin instance="cloth_flexcomp_cloth"/>
      </body>
      <body name="cloth_126" pos="-0.14 0.14 0.024">
        <inertial pos="0 0 0" mass="0.0025" diaginertia="4.16667e-08 4.16667e-08 4.16667e-08"/>
        <joint pos="0 0 0" axis="1 0 0" type="slide"/>
        <joint pos="0 0 0" axis="0 1 0" type="slide"/>
        <joint pos="0 0 0" axis="0 0 1" type="slide"/>
        <plugin instance="cloth_flexcomp_cloth"/>
      </body>
      <body name="cloth_127" pos="-0.1 0.16 0.00063">
        <inertial pos="0 0 0" mass="0.0025" diaginertia="4.16667e-08 4.16667e-08 4.16667e-08"/>
        <joint pos="0 0 0" axis="1 0 0" type="slide"/>
        <joint pos="0 0 0" axis="0 1 0" type="slide"/>
        <joint pos="0 0 0" axis="0 0 1" type="slide"/>
        <plugin instance="cloth_flexcomp_cloth"/>
      </body>
      <body name="cloth_128" pos="-0.064 0.17 0.028">
        <inertial pos="0 0 0" mass="0.0025" diaginertia="4.16667e-08 4.16667e-08 4.16667e-08"/>
        <joint pos="0 0 0" axis="1 0 0" type="slide"/>
        <joint pos="0 0 0" axis="0 1 0" type="slide"/>
        <joint pos="0 0 0" axis="0 0 1" type="slide"/>
        <plugin instance="cloth_flexcomp_cloth"/>
      </body>
      <body name="cloth_129" pos="-0.02 0.2 0.034">
        <inertial pos="0 0 0" mass="0.0025" diaginertia="4.16667e-08 4.16667e-08 4.16667e-08"/>
        <joint pos="0 0 0" axis="1 0 0" type="slide"/>
        <joint pos="0 0 0" axis="0 1 0" type="slide"/>
        <joint pos="0 0 0" axis="0 0 1" type="slide"/>
        <plugin instance="cloth_flexcomp_cloth"/>
      </body>
      <body name="cloth_130" pos="-0.16 -0.054 0.00076">
        <inertial pos="0 0 0" mass="0.0025" diaginertia="4.16667e-08 4.16667e-08 4.16667e-08"/>
        <joint pos="0 0 0" axis="1 0 0" type="slide"/>
        <joint pos="0 0 0" axis="0 1 0" type="slide"/>
        <joint pos="0 0 0" axis="0 0 1" type="slide"/>
        <plugin instance="cloth_flexcomp_cloth"/>
      </body>
      <body name="cloth_131" pos="-0.17 -0.0063 0.00077">
        <inertial pos="0 0 0" mass="0.0025" diaginertia="4.16667e-08 4.16667e-08 4.16667e-08"/>
        <joint pos="0 0 0" axis="1 0 0" type="slide"/>
        <joint pos="0 0 0" axis="0 1 0" type="slide"/>
        <joint pos="0 0 0" axis="0 0 1" type="slide"/>
        <plugin instance="cloth_flexcomp_cloth"/>
      </body>
      <body name="cloth_132" pos="-0.18 0.034 0.029">
        <inertial pos="0 0 0" mass="0.0025" diaginertia="4.16667e-08 4.16667e-08 4.16667e-08"/>
        <joint pos="0 0 0" axis="1 0 0" type="slide"/>
        <joint pos="0 0 0" axis="0 1 0" type="slide"/>
        <joint pos="0 0 0" axis="0 0 1" type="slide"/>
        <plugin instance="cloth_flexcomp_cloth"/>
      </body>
      <body name="cloth_133" pos="-0.17 0.071 0.00051">
        <inertial pos="0 0 0" mass="0.0025" diaginertia="4.16667e-08 4.16667e-08 4.16667e-08"/>
        <joint pos="0 0 0" axis="1 0 0" type="slide"/>
        <joint pos="0 0 0" axis="0 1 0" type="slide"/>
        <joint pos="0 0 0" axis="0 0 1" type="slide"/>
        <plugin instance="cloth_flexcomp_cloth"/>
      </body>
      <body name="cloth_134" pos="-0.16 0.12 0.00019">
        <inertial pos="0 0 0" mass="0.0025" diaginertia="4.16667e-08 4.16667e-08 4.16667e-08"/>
        <joint pos="0 0 0" axis="1 0 0" type="slide"/>
        <joint pos="0 0 0" axis="0 1 0" type="slide"/>
        <joint pos="0 0 0" axis="0 0 1" type="slide"/>
        <plugin instance="cloth_flexcomp_cloth"/>
      </body>
      <body name="cloth_135" pos="-0.14 0.14 0.037">
        <inertial pos="0 0 0" mass="0.0025" diaginertia="4.16667e-08 4.16667e-08 4.16667e-08"/>
        <joint pos="0 0 0" axis="1 0 0" type="slide"/>
        <joint pos="0 0 0" axis="0 1 0" type="slide"/>
        <joint pos="0 0 0" axis="0 0 1" type="slide"/>
        <plugin instance="cloth_flexcomp_cloth"/>
      </body>
      <body name="cloth_136" pos="-0.12 0.18 0.045">
        <inertial pos="0 0 0" mass="0.0025" diaginertia="4.16667e-08 4.16667e-08 4.16667e-08"/>
        <joint pos="0 0 0" axis="1 0 0" type="slide"/>
        <joint pos="0 0 0" axis="0 1 0" type="slide"/>
        <joint pos="0 0 0" axis="0 0 1" type="slide"/>
        <plugin instance="cloth_flexcomp_cloth"/>
      </body>
      <body name="cloth_137" pos="-0.11 0.2 0.00062">
        <inertial pos="0 0 0" mass="0.0025" diaginertia="4.16667e-08 4.16667e-08 4.16667e-08"/>
        <joint pos="0 0 0" axis="1 0 0" type="slide"/>
        <joint pos="0 0 0" axis="0 1 0" type="slide"/>
        <joint pos="0 0 0" axis="0 0 1" type="slide"/>
        <plugin instance="cloth_flexcomp_cloth"/>
      </body>
      <body name="cloth_138" pos="-0.062 0.21 5e-05">
        <inertial pos="0 0 0" mass="0.0025" diaginertia="4.16667e-08 4.16667e-08 4.16667e-08"/>
        <joint pos="0 0 0" axis="1 0 0" type="slide"/>
        <joint pos="0 0 0" axis="0 1 0" type="slide"/>
        <joint pos="0 0 0" axis="0 0 1" type="slide"/>
        <plugin instance="cloth_flexcomp_cloth"/>
      </body>
      <body name="cloth_139" pos="-0.044 0.24 0.036">
        <inertial pos="0 0 0" mass="0.0025" diaginertia="4.16667e-08 4.16667e-08 4.16667e-08"/>
        <joint pos="0 0 0" axis="1 0 0" type="slide"/>
        <joint pos="0 0 0" axis="0 1 0" type="slide"/>
        <joint pos="0 0 0" axis="0 0 1" type="slide"/>
        <plugin instance="cloth_flexcomp_cloth"/>
      </body>
      <body name="cloth_140" pos="-0.11 -0.036 0.00082">
        <inertial pos="0 0 0" mass="0.0025" diaginertia="4.16667e-08 4.16667e-08 4.16667e-08"/>
        <joint pos="0 0 0" axis="1 0 0" type="slide"/>
        <joint pos="0 0 0" axis="0 1 0" type="slide"/>
        <joint pos="0 0 0" axis="0 0 1" type="slide"/>
        <plugin instance="cloth_flexcomp_cloth"/>
      </body>
      <body name="cloth_141" pos="-0.13 0.01 0.00076">
        <inertial pos="0 0 0" mass="0.0025" diaginertia="4.16667e-08 4.16667e-08 4.16667e-08"/>
        <joint pos="0 0 0" axis="1 0 0" type="slide"/>
        <joint pos="0 0 0" axis="0 1 0" type="slide"/>
        <joint pos="0 0 0" axis="0 0 1" type="slide"/>
        <plugin instance="cloth_flexcomp_cloth"/>
      </body>
      <body name="cloth_142" pos="-0.14 0.058 0.0027">
        <inertial pos="0 0 0" mass="0.0025" diaginertia="4.16667e-08 4.16667e-08 4.16667e-08"/>
        <joint pos="0 0 0" axis="1 0 0" type="slide"/>
        <joint pos="0 0 0" axis="0 1 0" type="slide"/>
        <joint pos="0 0 0" axis="0 0 1" type="slide"/>
        <plugin instance="cloth_flexcomp_cloth"/>
      </body>
      <body name="cloth_143" pos="-0.14 0.095 0.035">
        <inertial pos="0 0 0" mass="0.0025" diaginertia="4.16667e-08 4.16667e-08 4.16667e-08"/>
        <joint pos="0 0 0" axis="1 0 0" type="slide"/>
        <joint pos="0 0 0" axis="0 1 0" type="slide"/>
        <joint pos="0 0 0" axis="0 0 1" type="slide"/>
        <plugin instance="cloth_flexcomp_cloth"/>
      </body>
      <body name="cloth_144" pos="-0.11 0.11 0.00041">
        <inertial pos="0 0 0" mass="0.0025" diaginertia="4.16667e-08 4.16667e-08 4.16667e-08"/>
        <joint pos="0 0 0" axis="1 0 0" type="slide"/>
        <joint pos="0 0 0" axis="0 1 0" type="slide"/>
        <joint pos="0 0 0" axis="0 0 1" type="slide"/>
        <plugin instance="cloth_flexcomp_cloth"/>
      </body>
      <body name="cloth_145" pos="-0.1 0.16 0.0037">
        <inertial pos="0 0 0" mass="0.0025" diaginertia="4.16667e-08 4.16667e-08 4.16667e-08"/>
        <joint pos="0 0 0" axis="1 0 0" type="slide"/>
        <joint pos="0 0 0" axis="0 1 0" type="slide"/>
        <joint pos="0 0 0" axis="0 0 1" type="slide"/>
        <plugin instance="cloth_flexcomp_cloth"/>
      </body>
      <body name="cloth_146" pos="-0.071 0.17 0.041">
        <inertial pos="0 0 0" mass="0.0025" diaginertia="4.16667e-08 4.16667e-08 4.16667e-08"/>
        <joint pos="0 0 0" axis="1 0 0" type="slide"/>
        <joint pos="0 0 0" axis="0 1 0" type="slide"/>
        <joint pos="0 0 0" axis="0 0 1" type="slide"/>
        <plugin instance="cloth_flexcomp_cloth"/>
      </body>
      <body name="cloth_147" pos="-0.062 0.2 0.0049">
        <inertial pos="0 0 0" mass="0.0025" diaginertia="4.16667e-08 4.16667e-08 4.16667e-08"/>
        <joint pos="0 0 0" axis="1 0 0" type="slide"/>
        <joint pos="0 0 0" axis="0 1 0" type="slide"/>
        <joint pos="0 0 0" axis="0 0 1" type="slide"/>
        <plugin instance="cloth_flexcomp_cloth"/>
      </body>
      <body name="cloth_148" pos="-0.065 0.23 0.047">
        <inertial pos="0 0 0" mass="0.0025" diaginertia="4.16667e-08 4.16667e-08 4.16667e-08"/>
        <joint pos="0 0 0" axis="1 0 0" type="slide"/>
        <joint pos="0 0 0" axis="0 1 0" type="slide"/>
        <joint pos="0 0 0" axis="0 0 1" type="slide"/>
        <plugin instance="cloth_flexcomp_cloth"/>
      </body>
      <body name="cloth_149" pos="-0.084 0.27 0.03">
        <inertial pos="0 0 0" mass="0.0025" diaginertia="4.16667e-08 4.16667e-08 4.16667e-08"/>
        <joint pos="0 0 0" axis="1 0 0" type="slide"/>
        <joint pos="0 0 0" axis="0 1 0" type="slide"/>
        <joint pos="0 0 0" axis="0 0 1" type="slide"/>
        <plugin instance="cloth_flexcomp_cloth"/>
      </body>
      <body name="cloth_150" pos="-0.063 -0.018 0.0073">
        <inertial pos="0 0 0" mass="0.0025" diaginertia="4.16667e-08 4.16667e-08 4.16667e-08"/>
        <joint pos="0 0 0" axis="1 0 0" type="slide"/>
        <joint pos="0 0 0" axis="0 1 0" type="slide"/>
        <joint pos="0 0 0" axis="0 0 1" type="slide"/>
        <plugin instance="cloth_flexcomp_cloth"/>
      </body>
      <body name="cloth_151" pos="-0.08 0.029 0.00063">
        <inertial pos="0 0 0" mass="0.0025" diaginertia="4.16667e-08 4.16667e-08 4.16667e-08"/>
        <joint pos="0 0 0" axis="1 0 0" type="slide"/>
        <joint pos="0 0 0" axis="0 1 0" type="slide"/>
        <joint pos="0 0 0" axis="0 0 1" type="slide"/>
        <plugin instance="cloth_flexcomp_cloth"/>
      </body>
      <body name="cloth_152" pos="-0.098 0.075 0.00077">
        <inertial pos="0 0 0" mass="0.0025" diaginertia="4.16667e-08 4.16667e-08 4.16667e-08"/>
        <joint pos="0 0 0" axis="1 0 0" type="slide"/>
        <joint pos="0 0 0" axis="0 1 0" type="slide"/>
        <joint pos="0 0 0" axis="0 0 1" type="slide"/>
        <plugin instance="cloth_flexcomp_cloth"/>
      </body>
      <body name="cloth_153" pos="-0.097 0.082 0.051">
        <inertial pos="0 0 0" mass="0.0025" diaginertia="4.16667e-08 4.16667e-08 4.16667e-08"/>
        <joint pos="0 0 0" axis="1 0 0" type="slide"/>
        <joint pos="0 0 0" axis="0 1 0" type="slide"/>
        <joint pos="0 0 0" axis="0 0 1" type="slide"/>
        <plugin instance="cloth_flexcomp_cloth"/>
      </body>
      <body name="cloth_154" pos="-0.07 0.12 0.029">
        <inertial pos="0 0 0" mass="0.0025" diaginertia="4.16667e-08 4.16667e-08 4.16667e-08"/>
        <joint pos="0 0 0" axis="1 0 0" type="slide"/>
        <joint pos="0 0 0" axis="0 1 0" type="slide"/>
        <joint pos="0 0 0" axis="0 0 1" type="slide"/>
        <plugin instance="cloth_flexcomp_cloth"/>
      </body>
      <body name="cloth_155" pos="-0.051 0.15 0.00029">
        <inertial pos="0 0 0" mass="0.0025" diaginertia="4.16667e-08 4.16667e-08 4.16667e-08"/>
        <joint pos="0 0 0" axis="1 0 0" type="slide"/>
        <joint pos="0 0 0" axis="0 1 0" type="slide"/>
        <joint pos="0 0 0" axis="0 0 1" type="slide"/>
        <plugin instance="cloth_flexcomp_cloth"/>
      </body>
      <body name="cloth_156" pos="-0.046 0.2 0.013">
        <inertial pos="0 0 0" mass="0.0025" diaginertia="4.16667e-08 4.16667e-08 4.16667e-08"/>
        <joint pos="0 0 0" axis="1 0 0" type="slide"/>
        <joint pos="0 0 0" axis="0 1 0" type="slide"/>
        <joint pos="0 0 0" axis="0 0 1" type="slide"/>
        <plugin instance="cloth_flexcomp_cloth"/>
      </body>
      <body name="cloth_157" pos="-0.07 0.24 0.037">
        <inertial pos="0 0 0" mass="0.0025" diaginertia="4.16667e-08 4.16667e-08 4.16667e-08"/>
        <joint pos="0 0 0" axis="1 0 0" type="slide"/>
        <joint pos="0 0 0" axis="0 1 0" type="slide"/>
        <joint pos="0 0 0" axis="0 0 1" type="slide"/>
        <plugin instance="cloth_flexcomp_cloth"/>
      </body>
      <body name="cloth_158" pos="-0.11 0.22 0.048">
        <inertial pos="0 0 0" mass="0.0025" diaginertia="4.16667e-08 4.16667e-08 4.16667e-08"/>
        <joint pos="0 0 0" axis="1 0 0" type="slide"/>
        <joint pos="0 0 0" axis="0 1 0" type="slide"/>
        <joint pos="0 0 0" axis="0 0 1" type="slide"/>
        <plugin instance="cloth_flexcomp_cloth"/>
      </body>
      <body name="cloth_159" pos="-0.12 0.25 0.0057">
        <inertial pos="0 0 0" mass="0.0025" diaginertia="4.16667e-08 4.16667e-08 4.16667e-08"/>
        <joint pos="0 0 0" axis="1 0 0" type="slide"/>
        <joint pos="0 0 0" axis="0 1 0" type="slide"/>
        <joint pos="0 0 0" axis="0 0 1" type="slide"/>
        <plugin instance="cloth_flexcomp_cloth"/>
      </body>
      <body name="cloth_160" pos="-0.082 0.026 0.00073">
        <inertial pos="0 0 0" mass="0.0025" diaginertia="4.16667e-08 4.16667e-08 4.16667e-08"/>
        <joint pos="0 0 0" axis="1 0 0" type="slide"/>
        <joint pos="0 0 0" axis="0 1 0" type="slide"/>
        <joint pos="0 0 0" axis="0 0 1" type="slide"/>
        <plugin instance="cloth_flexcomp_cloth"/>
      </body>
      <body name="cloth_161" pos="-0.042 0.05 0.023">
        <inertial pos="0 0 0" mass="0.0025" diaginertia="4.16667e-08 4.16667e-08 4.16667e-08"/>
        <joint pos="0 0 0" axis="1 0 0" type="slide"/>
        <joint pos="0 0 0" axis="0 1 0" type="slide"/>
        <joint pos="0 0 0" axis="0 0 1" type="slide"/>
        <plugin instance="cloth_flexcomp_cloth"/>
      </body>
      <body name="cloth_162" pos="-0.051 0.093 0.00049">
        <inertial pos="0 0 0" mass="0.0025" diaginertia="4.16667e-08 4.16667e-08 4.16667e-08"/>
        <joint pos="0 0 0" axis="1 0 0" type="slide"/>
        <joint pos="0 0 0" axis="0 1 0" type="slide"/>
        <joint pos="0 0 0" axis="0 0 1" type="slide"/>
        <plugin instance="cloth_flexcomp_cloth"/>
      </body>
      <body name="cloth_163" pos="-0.06 0.12 0.044">
        <inertial pos="0 0 0" mass="0.0025" diaginertia="4.16667e-08 4.16667e-08 4.16667e-08"/>
        <joint pos="0 0 0" axis="1 0 0" type="slide"/>
        <joint pos="0 0 0" axis="0 1 0" type="slide"/>
        <joint pos="0 0 0" axis="0 0 1" type="slide"/>
        <plugin instance="cloth_flexcomp_cloth"/>
      </body>
      <body name="cloth_164" pos="-0.092 0.15 0.05">
        <inertial pos="0 0 0" mass="0.0025" diaginertia="4.16667e-08 4.16667e-08 4.16667e-08"/>
        <joint pos="0 0 0" axis="1 0 0" type="slide"/>
        <joint pos="0 0 0" axis="0 1 0" type="slide"/>
        <joint pos="0 0 0" axis="0 0 1" type="slide"/>
        <plugin instance="cloth_flexcomp_cloth"/>
      </body>
      <body name="cloth_165" pos="-0.056 0.19 0.031">
        <inertial pos="0 0 0" mass="0.0025" diaginertia="4.16667e-08 4.16667e-08 4.16667e-08"/>
        <joint pos="0 0 0" axis="1 0 0" type="slide"/>
        <joint pos="0 0 0" axis="0 1 0" type="slide"/>
        <joint pos="0 0 0" axis="0 0 1" type="slide"/>
        <plugin instance="cloth_flexcomp_cloth"/>
      </body>
      <body name="cloth_166" pos="-0.095 0.2 0.0033">
        <inertial pos="0 0 0" mass="0.0025" diaginertia="4.16667e-08 4.16667e-08 4.16667e-08"/>
        <joint pos="0 0 0" axis="1 0 0" type="slide"/>
        <joint pos="0 0 0" axis="0 1 0" type="slide"/>
        <joint pos="0 0 0" axis="0 0 1" type="slide"/>
        <plugin instance="cloth_flexcomp_cloth"/>
      </body>
      <body name="cloth_167" pos="-0.11 0.2 0.049">
        <inertial pos="0 0 0" mass="0.0025" diaginertia="4.16667e-08 4.16667e-08 4.16667e-08"/>
        <joint pos="0 0 0" axis="1 0 0" type="slide"/>
        <joint pos="0 0 0" axis="0 1 0" type="slide"/>
        <joint pos="0 0 0" axis="0 0 1" type="slide"/>
        <plugin instance="cloth_flexcomp_cloth"/>
      </body>
      <body name="cloth_168" pos="-0.12 0.2 0.00088">
        <inertial pos="0 0 0" mass="0.0025" diaginertia="4.16667e-08 4.16667e-08 4.16667e-08"/>
        <joint pos="0 0 0" axis="1 0 0" type="slide"/>
        <joint pos="0 0 0" axis="0 1 0" type="slide"/>
        <joint pos="0 0 0" axis="0 0 1" type="slide"/>
        <plugin instance="cloth_flexcomp_cloth"/>
      </body>
      <body name="cloth_169" pos="-0.17 0.23 0.00067">
        <inertial pos="0 0 0" mass="0.0025" diaginertia="4.16667e-08 4.16667e-08 4.16667e-08"/>
        <joint pos="0 0 0" axis="1 0 0" type="slide"/>
        <joint pos="0 0 0" axis="0 1 0" type="slide"/>
        <joint pos="0 0 0" axis="0 0 1" type="slide"/>
        <plugin instance="cloth_flexcomp_cloth"/>
      </body>
      <body name="cloth_170" pos="-0.046 0.06 0.00076">
        <inertial pos="0 0 0" mass="0.0025" diaginertia="4.16667e-08 4.16667e-08 4.16667e-08"/>
        <joint pos="0 0 0" axis="1 0 0" type="slide"/>
        <joint pos="0 0 0" axis="0 1 0" type="slide"/>
        <joint pos="0 0 0" axis="0 0 1" type="slide"/>
        <plugin instance="cloth_flexcomp_cloth"/>
      </body>
      <body name="cloth_171" pos="-0.073 0.087 0.034">
        <inertial pos="0 0 0" mass="0.0025" diaginertia="4.16667e-08 4.16667e-08 4.16667e-08"/>
        <joint pos="0 0 0" axis="1 0 0" type="slide"/>
        <joint pos="0 0 0" axis="0 1 0" type="slide"/>
        <joint pos="0 0 0" axis="0 0 1" type="slide"/>
        <plugin instance="cloth_flexcomp_cloth"/>
      </body>
      <body name="cloth_172" pos="-0.037 0.12 0.038">
        <inertial pos="0 0 0" mass="0.0025" diaginertia="4.16667e-08 4.16667e-08 4.16667e-08"/>
        <joint pos="0 0 0" axis="1 0 0" type="slide"/>
        <joint pos="0 0 0" axis="0 1 0" type="slide"/>
        <joint pos="0 0 0" axis="0 0 1" type="slide"/>
        <plugin instance="cloth_flexcomp_cloth"/>
      </body>
      <body name="cloth_173" pos="-0.063 0.16 0.019">
        <inertial pos="0 0 0" mass="0.0025" diaginertia="4.16667e-08 4.16667e-08 4.16667e-08"/>
        <joint pos="0 0 0" axis="1 0 0" type="slide"/>
        <joint pos="0 0 0" axis="0 1 0" type="slide"/>
        <joint pos="0 0 0" axis="0 0 1" type="slide"/>
        <plugin instance="cloth_flexcomp_cloth"/>
      </body>
      <body name="cloth_174" pos="-0.052 0.18 0.062">
        <inertial pos="0 0 0" mass="0.0025" diaginertia="4.16667e-08 4.16667e-08 4.16667e-08"/>
        <joint pos="0 0 0" axis="1 0 0" type="slide"/>
        <joint pos="0 0 0" axis="0 1 0" type="slide"/>
        <joint pos="0 0 0" axis="0 0 1" type="slide"/>
        <plugin instance="cloth_flexcomp_cloth"/>
      </body>
      <body name="cloth_175" pos="-0.078 0.22 0.05">
        <inertial pos="0 0 0" mass="0.0025" diaginertia="4.16667e-08 4.16667e-08 4.16667e-08"/>
        <joint pos="0 0 0" axis="1 0 0" type="slide"/>
        <joint pos="0 0 0" axis="0 1 0" type="slide"/>
        <joint pos="0 0 0" axis="0 0 1" type="slide"/>
        <plugin instance="cloth_flexcomp_cloth"/>
      </body>
      <body name="cloth_176" pos="-0.12 0.2 0.048">
        <inertial pos="0 0 0" mass="0.0025" diaginertia="4.16667e-08 4.16667e-08 4.16667e-08"/>
        <joint pos="0 0 0" axis="1 0 0" type="slide"/>
        <joint pos="0 0 0" axis="0 1 0" type="slide"/>
        <joint pos="0 0 0" axis="0 0 1" type="slide"/>
        <plugin instance="cloth_flexcomp_cloth"/>
      </body>
      <body name="cloth_177" pos="-0.12 0.15 0.046">
        <inertial pos="0 0 0" mass="0.0025" diaginertia="4.16667e-08 4.16667e-08 4.16667e-08"/>
        <joint pos="0 0 0" axis="1 0 0" type="slide"/>
        <joint pos="0 0 0" axis="0 1 0" type="slide"/>
        <joint pos="0 0 0" axis="0 0 1" type="slide"/>
        <plugin instance="cloth_flexcomp_cloth"/>
      </body>
      <body name="cloth_178" pos="-0.14 0.16 0.0038">
        <inertial pos="0 0 0" mass="0.0025" diaginertia="4.16667e-08 4.16667e-08 4.16667e-08"/>
        <joint pos="0 0 0" axis="1 0 0" type="slide"/>
        <joint pos="0 0 0" axis="0 1 0" type="slide"/>
        <joint pos="0 0 0" axis="0 0 1" type="slide"/>
        <plugin instance="cloth_flexcomp_cloth"/>
      </body>
      <body name="cloth_179" pos="-0.19 0.18 0.00076">
        <inertial pos="0 0 0" mass="0.0025" diaginertia="4.16667e-08 4.16667e-08 4.16667e-08"/>
        <joint pos="0 0 0" axis="1 0 0" type="slide"/>
        <joint pos="0 0 0" axis="0 1 0" type="slide"/>
        <joint pos="0 0 0" axis="0 0 1" type="slide"/>
        <plugin instance="cloth_flexcomp_cloth"/>
      </body>
      <body name="cloth_180" pos="-0.049 0.098 0.033">
        <inertial pos="0 0 0" mass="0.0025" diaginertia="4.16667e-08 4.16667e-08 4.16667e-08"/>
        <joint pos="0 0 0" axis="1 0 0" type="slide"/>
        <joint pos="0 0 0" axis="0 1 0" type="slide"/>
        <joint pos="0 0 0" axis="0 0 1" type="slide"/>
        <plugin instance="cloth_flexcomp_cloth"/>
      </body>
      <body name="cloth_181" pos="-0.078 0.12 0.00056">
        <inertial pos="0 0 0" mass="0.0025" diaginertia="4.16667e-08 4.16667e-08 4.16667e-08"/>
        <joint pos="0 0 0" axis="1 0 0" type="slide"/>
        <joint pos="0 0 0" axis="0 1 0" type="slide"/>
        <joint pos="0 0 0" axis="0 0 1" type="slide"/>
        <plugin instance="cloth_flexcomp_cloth"/>
      </body>
      <body name="cloth_182" pos="-0.071 0.16 0.035">
        <inertial pos="0 0 0" mass="0.0025" diaginertia="4.16667e-08 4.16667e-08 4.16667e-08"/>
        <joint pos="0 0 0" axis="1 0 0" type="slide"/>
        <joint pos="0 0 0" axis="0 1 0" type="slide"/>
        <joint pos="0 0 0" axis="0 0 1" type="slide"/>
        <plugin instance="cloth_flexcomp_cloth"/>
      </body>
      <body name="cloth_183" pos="-0.037 0.19 0.048">
        <inertial pos="0 0 0" mass="0.0025" diaginertia="4.16667e-08 4.16667e-08 4.16667e-08"/>
        <joint pos="0 0 0" axis="1 0 0" type="slide"/>
        <joint pos="0 0 0" axis="0 1 0" type="slide"/>
        <joint pos="0 0 0" axis="0 0 1" type="slide"/>
        <plugin instance="cloth_flexcomp_cloth"/>
      </body>
      <body name="cloth_184" pos="-0.076 0.22 0.05">
        <inertial pos="0 0 0" mass="0.0025" diaginertia="4.16667e-08 4.16667e-08 4.16667e-08"/>
        <joint pos="0 0 0" axis="1 0 0" type="slide"/>
        <joint pos="0 0 0" axis="0 1 0" type="slide"/>
        <joint pos="0 0 0" axis="0 0 1" type="slide"/>
        <plugin instance="cloth_flexcomp_cloth"/>
      </body>
      <body name="cloth_185" pos="-0.12 0.2 0.049">
        <inertial pos="0 0 0" mass="0.0025" diaginertia="4.16667e-08 4.16667e-08 4.16667e-08"/>
        <joint pos="0 0 0" axis="1 0 0" type="slide"/>
        <joint pos="0 0 0" axis="0 1 0" type="slide"/>
        <joint pos="0 0 0" axis="0 0 1" type="slide"/>
        <plugin instance="cloth_flexcomp_cloth"/>
      </body>
      <body name="cloth_186" pos="-0.12 0.2 0.00015">
        <inertial pos="0 0 0" mass="0.0025" diaginertia="4.16667e-08 4.16667e-08 4.16667e-08"/>
        <joint pos="0 0 0" axis="1 0 0" type="slide"/>
        <joint pos="0 0 0" axis="0 1 0" type="slide"/>
        <joint pos="0 0 0" axis="0 0 1" type="slide"/>
        <plugin instance="cloth_flexcomp_cloth"/>
      </body>
      <body name="cloth_187" pos="-0.14 0.15 0.00059">
        <inertial pos="0 0 0" mass="0.0025" diaginertia="4.16667e-08 4.16667e-08 4.16667e-08"/>
        <joint pos="0 0 0" axis="1 0 0" type="slide"/>
        <joint pos="0 0 0" axis="0 1 0" type="slide"/>
        <joint pos="0 0 0" axis="0 0 1" type="slide"/>
        <plugin instance="cloth_flexcomp_cloth"/>
      </body>
      <body name="cloth_188" pos="-0.16 0.11 0.0089">
        <inertial pos="0 0 0" mass="0.0025" diaginertia="4.16667e-08 4.16667e-08 4.16667e-08"/>
        <joint pos="0 0 0" axis="1 0 0" type="slide"/>
        <joint pos="0 0 0" axis="0 1 0" type="slide"/>
        <joint pos="0 0 0" axis="0 0 1" type="slide"/>
        <plugin instance="cloth_flexcomp_cloth"/>
      </body>
      <body name="cloth_189" pos="-0.21 0.14 0.00063">
        <inertial pos="0 0 0" mass="0.0025" diaginertia="4.16667e-08 4.16667e-08 4.16667e-08"/>
        <joint pos="0 0 0" axis="1 0 0" type="slide"/>
        <joint pos="0 0 0" axis="0 1 0" type="slide"/>
        <joint pos="0 0 0" axis="0 0 1" type="slide"/>
        <plugin instance="cloth_flexcomp_cloth"/>
      </body>
      <body name="cloth_190" pos="-0.016 0.12 0.00077">
        <inertial pos="0 0 0" mass="0.0025" diaginertia="4.16667e-08 4.16667e-08 4.16667e-08"/>
        <joint pos="0 0 0" axis="1 0 0" type="slide"/>
        <joint pos="0 0 0" axis="0 1 0" type="slide"/>
        <joint pos="0 0 0" axis="0 0 1" type="slide"/>
        <plugin instance="cloth_flexcomp_cloth"/>
      </body>
      <body name="cloth_191" pos="-0.043 0.16 0.00071">
        <inertial pos="0 0 0" mass="0.0025" diaginertia="4.16667e-08 4.16667e-08 4.16667e-08"/>
        <joint pos="0 0 0" axis="1 0 0" type="slide"/>
        <joint pos="0 0 0" axis="0 1 0" type="slide"/>
        <joint pos="0 0 0" axis="0 0 1" type="slide"/>
        <plugin instance="cloth_flexcomp_cloth"/>
      </body>
      <body name="cloth_192" pos="-0.08 0.19 0.00079">
        <inertial pos="0 0 0" mass="0.0025" diaginertia="4.16667e-08 4.16667e-08 4.16667e-08"/>
        <joint pos="0 0 0" axis="1 0 0" type="slide"/>
        <joint pos="0 0 0" axis="0 1 0" type="slide"/>
        <joint pos="0 0 0" axis="0 0 1" type="slide"/>
        <plugin instance="cloth_flexcomp_cloth"/>
      </body>
      <body name="cloth_193" pos="-0.031 0.21 0.00068">
        <inertial pos="0 0 0" mass="0.0025" diaginertia="4.16667e-08 4.16667e-08 4.16667e-08"/>
        <joint pos="0 0 0" axis="1 0 0" type="slide"/>
        <joint pos="0 0 0" axis="0 1 0" type="slide"/>
        <joint pos="0 0 0" axis="0 0 1" type="slide"/>
        <plugin instance="cloth_flexcomp_cloth"/>
      </body>
      <body name="cloth_194" pos="-0.076 0.23 0.00063">
        <inertial pos="0 0 0" mass="0.0025" diaginertia="4.16667e-08 4.16667e-08 4.16667e-08"/>
        <joint pos="0 0 0" axis="1 0 0" type="slide"/>
        <joint pos="0 0 0" axis="0 1 0" type="slide"/>
        <joint pos="0 0 0" axis="0 0 1" type="slide"/>
        <plugin instance="cloth_flexcomp_cloth"/>
      </body>
      <body name="cloth_195" pos="-0.12 0.21 0.00062">
        <inertial pos="0 0 0" mass="0.0025" diaginertia="4.16667e-08 4.16667e-08 4.16667e-08"/>
        <joint pos="0 0 0" axis="1 0 0" type="slide"/>
        <joint pos="0 0 0" axis="0 1 0" type="slide"/>
        <joint pos="0 0 0" axis="0 0 1" type="slide"/>
        <plugin instance="cloth_flexcomp_cloth"/>
      </body>
      <body name="cloth_196" pos="-0.17 0.2 0.00099">
        <inertial pos="0 0 0" mass="0.0025" diaginertia="4.16667e-08 4.16667e-08 4.16667e-08"/>
        <joint pos="0 0 0" axis="1 0 0" type="slide"/>
        <joint pos="0 0 0" axis="0 1 0" type="slide"/>
        <joint pos="0 0 0" axis="0 0 1" type="slide"/>
        <plugin instance="cloth_flexcomp_cloth"/>
      </body>
      <body name="cloth_197" pos="-0.18 0.16 0.029">
        <inertial pos="0 0 0" mass="0.0025" diaginertia="4.16667e-08 4.16667e-08 4.16667e-08"/>
        <joint pos="0 0 0" axis="1 0 0" type="slide"/>
        <joint pos="0 0 0" axis="0 1 0" type="slide"/>
        <joint pos="0 0 0" axis="0 0 1" type="slide"/>
        <plugin instance="cloth_flexcomp_cloth"/>
      </body>
      <body name="cloth_198" pos="-0.21 0.14 0.0027">
        <inertial pos="0 0 0" mass="0.0025" diaginertia="4.16667e-08 4.16667e-08 4.16667e-08"/>
        <joint pos="0 0 0" axis="1 0 0" type="slide"/>
        <joint pos="0 0 0" axis="0 1 0" type="slide"/>
        <joint pos="0 0 0" axis="0 0 1" type="slide"/>
        <plugin instance="cloth_flexcomp_cloth"/>
      </body>
      <body name="cloth_199" pos="-0.19 0.18 0.00075">
        <inertial pos="0 0 0" mass="0.0025" diaginertia="4.16667e-08 4.16667e-08 4.16667e-08"/>
        <joint pos="0 0 0" axis="1 0 0" type="slide"/>
        <joint pos="0 0 0" axis="0 1 0" type="slide"/>
        <joint pos="0 0 0" axis="0 0 1" type="slide"/>
        <plugin instance="cloth_flexcomp_cloth"/>
      </body>
    </body>
  </worldbody>
  <deformable>
    <flex name="cloth_cloth" radius="0.001" rgba="255 0 0 0.4" body="cloth_0 cloth_1 cloth_2 cloth_3 cloth_4 cloth_5 cloth_6 cloth_7 cloth_8 cloth_9 cloth_10 cloth_11 cloth_12 cloth_13 cloth_14 cloth_15 cloth_16 cloth_17 cloth_18 cloth_19 cloth_20 cloth_21 cloth_22 cloth_23 cloth_24 cloth_25 cloth_26 cloth_27 cloth_28 cloth_29 cloth_30 cloth_31 cloth_32 cloth_33 cloth_34 cloth_35 cloth_36 cloth_37 cloth_38 cloth_39 cloth_40 cloth_41 cloth_42 cloth_43 cloth_44 cloth_45 cloth_46 cloth_47 cloth_48 cloth_49 cloth_50 cloth_51 cloth_52 cloth_53 cloth_54 cloth_55 cloth_56 cloth_57 cloth_58 cloth_59 cloth_60 cloth_61 cloth_62 cloth_63 cloth_64 cloth_65 cloth_66 cloth_67 cloth_68 cloth_69 cloth_70 cloth_71 cloth_72 cloth_73 cloth_74 cloth_75 cloth_76 cloth_77 cloth_78 cloth_79 cloth_80 cloth_81 cloth_82 cloth_83 cloth_84 cloth_85 cloth_86 cloth_87 cloth_88 cloth_89 cloth_90 cloth_91 cloth_92 cloth_93 cloth_94 cloth_95 cloth_96 cloth_97 cloth_98 cloth_99 cloth_100 cloth_101 cloth_102 cloth_103 cloth_104 cloth_105 cloth_106 cloth_107 cloth_108 cloth_109 cloth_110 cloth_111 cloth_112 cloth_113 cloth_114 cloth_115 cloth_116 cloth_117 cloth_118 cloth_119 cloth_120 cloth_121 cloth_122 cloth_123 cloth_124 cloth_125 cloth_126 cloth_127 cloth_128 cloth_129 cloth_130 cloth_131 cloth_132 cloth_133 cloth_134 cloth_135 cloth_136 cloth_137 cloth_138 cloth_139 cloth_140 cloth_141 cloth_142 cloth_143 cloth_144 cloth_145 cloth_146 cloth_147 cloth_148 cloth_149 cloth_150 cloth_151 cloth_152 cloth_153 cloth_154 cloth_155 cloth_156 cloth_157 cloth_158 cloth_159 cloth_160 cloth_161 cloth_162 cloth_163 cloth_164 cloth_165 cloth_166 cloth_167 cloth_168 cloth_169 cloth_170 cloth_171 cloth_172 cloth_173 cloth_174 cloth_175 cloth_176 cloth_177 cloth_178 cloth_179 cloth_180 cloth_181 cloth_182 cloth_183 cloth_184 cloth_185 cloth_186 cloth_187 cloth_188 cloth_189 cloth_190 cloth_191 cloth_192 cloth_193 cloth_194 cloth_195 cloth_196 cloth_197 cloth_198 cloth_199" element="0 10 11 0 11 1 1 11 12 1 12 2 2 12 13 2 13 3 3 13 14 3 14 4 4 14 15 4 15 5 5 15 16 5 16 6 6 16 17 6 17 7 7 17 18 7 18 8 8 18 19 8 19 9 10 20 21 10 21 11 11 21 22 11 22 12 12 22 23 12 23 13 13 23 24 13 24 14 14 24 25 14 25 15 15 25 26 15 26 16 16 26 27 16 27 17 17 27 28 17 28 18 18 28 29 18 29 19 20 30 31 20 31 21 21 31 32 21 32 22 22 32 33 22 33 23 23 33 34 23 34 24 24 34 35 24 35 25 25 35 36 25 36 26 26 36 37 26 37 27 27 37 38 27 38 28 28 38 39 28 39 29 30 40 41 30 41 31 31 41 42 31 42 32 32 42 43 32 43 33 33 43 44 33 44 34 34 44 45 34 45 35 35 45 46 35 46 36 36 46 47 36 47 37 37 47 48 37 48 38 38 48 49 38 49 39 40 50 51 40 51 41 41 51 52 41 52 42 42 52 53 42 53 43 43 53 54 43 54 44 44 54 55 44 55 45 45 55 56 45 56 46 46 56 57 46 57 47 47 57 58 47 58 48 48 58 59 48 59 49 50 60 61 50 61 51 51 61 62 51 62 52 52 62 63 52 63 53 53 63 64 53 64 54 54 64 65 54 65 55 55 65 66 55 66 56 56 66 67 56 67 57 57 67 68 57 68 58 58 68 69 58 69 59 60 70 71 60 71 61 61 71 72 61 72 62 62 72 73 62 73 63 63 73 74 63 74 64 64 74 75 64 75 65 65 75 76 65 76 66 66 76 77 66 77 67 67 77 78 67 78 68 68 78 79 68 79 69 70 80 81 70 81 71 71 81 82 71 82 72 72 82 83 72 83 73 73 83 84 73 84 74 74 84 85 74 85 75 75 85 86 75 86 76 76 86 87 76 87 77 77 87 88 77 88 78 78 88 89 78 89 79 80 90 91 80 91 81 81 91 92 81 92 82 82 92 93 82 93 83 83 93 94 83 94 84 84 94 95 84 95 85 85 95 96 85 96 86 86 96 97 86 97 87 87 97 98 87 98 88 88 98 99 88 99 89 90 100 101 90 101 91 91 101 102 91 102 92 92 102 103 92 103 93 93 103 104 93 104 94 94 104 105 94 105 95 95 105 106 95 106 96 96 106 107 96 107 97 97 107 108 97 108 98 98 108 109 98 109 99 100 110 111 100 111 101 101 111 112 101 112 102 102 112 113 102 113 103 103 113 114 103 114 104 104 114 115 104 115 105 105 115 116 105 116 106 106 116 117 106 117 107 107 117 118 107 118 108 108 118 119 108 119 109 110 120 121 110 121 111 111 121 122 111 122 112 112 122 123 112 123 113 113 123 124 113 124 114 114 124 125 114 125 115 115 125 126 115 126 116 116 126 127 116 127 117 117 127 128 117 128 118 118 128 129 118 129 119 120 130 131 120 131 121 121 131 132 121 132 122 122 132 133 122 133 123 123 133 134 123 134 124 124 134 135 124 135 125 125 135 136 125 136 126 126 136 137 126 137 127 127 137 138 127 138 128 128 138 139 128 139 129 130 140 141 130 141 131 131 141 142 131 142 132 132 142 143 132 143 133 133 143 144 133 144 134 134 144 145 134 145 135 135 145 146 135 146 136 136 146 147 136 147 137 137 147 148 137 148 138 138 148 149 138 149 139 140 150 151 140 151 141 141 151 152 141 152 142 142 152 153 142 153 143 143 153 154 143 154 144 144 154 155 144 155 145 145 155 156 145 156 146 146 156 157 146 157 147 147 157 158 147 158 148 148 158 159 148 159 149 150 160 161 150 161 151 151 161 162 151 162 152 152 162 163 152 163 153 153 163 164 153 164 154 154 164 165 154 165 155 155 165 166 155 166 156 156 166 167 156 167 157 157 167 168 157 168 158 158 168 169 158 169 159 160 170 171 160 171 161 161 171 172 161 172 162 162 172 173 162 173 163 163 173 174 163 174 164 164 174 175 164 175 165 165 175 176 165 176 166 166 176 177 166 177 167 167 177 178 167 178 168 168 178 179 168 179 169 170 180 181 170 181 171 171 181 182 171 182 172 172 182 183 172 183 173 173 183 184 173 184 174 174 184 185 174 185 175 175 185 186 175 186 176 176 186 187 176 187 177 177 187 188 177 188 178 178 188 189 178 189 179 180 190 191 180 191 181 181 191 192 181 192 182 182 192 193 182 193 183 183 193 194 183 194 184 184 194 195 184 195 185 185 195 196 185 196 186 186 196 197 186 197 187 187 197 198 187 198 188 188 198 199 188 199 189">
      <contact solref="0.01 1" solimp="0.95 0.99 0.0001 0.5 2" selfcollide="none"/>
      <edge damping="1"/>
    </flex>
  </deformable>
  <equality>
    <flex flex="cloth_cloth"/>
  </equality>
  <actuator>
    <general name="robot0_torq_j1" joint="robot0_joint1" ctrlrange="-80 80"/>
    <general name="robot0_torq_j2" joint="robot0_joint2" ctrlrange="-80 80"/>
    <general name="robot0_torq_j3" joint="robot0_joint3" ctrlrange="-80 80"/>
    <general name="robot0_torq_j4" joint="robot0_joint4" ctrlrange="-80 80"/>
    <general name="robot0_torq_j5" joint="robot0_joint5" ctrlrange="-80 80"/>
    <general name="robot0_torq_j6" joint="robot0_joint6" ctrlrange="-12 12"/>
    <general name="robot0_torq_j7" joint="robot0_joint7" ctrlrange="-12 12"/>
    <general name="gripper0_gripper_finger_joint1" joint="gripper0_finger_joint1" ctrlrange="0 0.04" forcerange="-20 20" biastype="affine" gainprm="1000 0 0 0 0 0 0 0 0 0" biasprm="0 -1000 0 0 0 0 0 0 0 0"/>
    <general name="gripper0_gripper_finger_joint2" joint="gripper0_finger_joint2" ctrlrange="-0.04 0" forcerange="-20 20" biastype="affine" gainprm="1000 0 0 0 0 0 0 0 0 0" biasprm="0 -1000 0 0 0 0 0 0 0 0"/>
  </actuator>
  <sensor>
    <force site="gripper0_ft_frame" name="gripper0_force_ee"/>
    <torque site="gripper0_ft_frame" name="gripper0_torque_ee"/>
  </sensor>
</mujoco>
