<?xml version="1.0" encoding="utf-8"?>
<mujoco model="cloth">
	<compiler angle="radian"></compiler>
	<option timestep="0.01" tolerance="1e-06" viscosity="0.3" integrator="implicitfast" solver="CG"></option>
	<size nkey="10"></size>
	<statistic meansize="0.0721882" extent="2" center="0 0 0"></statistic>
	<extension>
		<plugin plugin="mujoco.elasticity.shell">
			<instance name="cloth_flexcomp_cloth">
				<config key="face" value="0 10 11 0 11 1 1 11 12 1 12 2 2 12 13 2 13 3 3 13 14 3 14 4 4 14 15 4 15 5 5 15 16 5 16 6 6 16 17 6 17 7 7 17 18 7 18 8 8 18 19 8 19 9 10 20 21 10 21 11 11 21 22 11 22 12 12 22 23 12 23 13 13 23 24 13 24 14 14 24 25 14 25 15 15 25 26 15 26 16 16 26 27 16 27 17 17 27 28 17 28 18 18 28 29 18 29 19 20 30 31 20 31 21 21 31 32 21 32 22 22 32 33 22 33 23 23 33 34 23 34 24 24 34 35 24 35 25 25 35 36 25 36 26 26 36 37 26 37 27 27 37 38 27 38 28 28 38 39 28 39 29 30 40 41 30 41 31 31 41 42 31 42 32 32 42 43 32 43 33 33 43 44 33 44 34 34 44 45 34 45 35 35 45 46 35 46 36 36 46 47 36 47 37 37 47 48 37 48 38 38 48 49 38 49 39 40 50 51 40 51 41 41 51 52 41 52 42 42 52 53 42 53 43 43 53 54 43 54 44 44 54 55 44 55 45 45 55 56 45 56 46 46 56 57 46 57 47 47 57 58 47 58 48 48 58 59 48 59 49 50 60 61 50 61 51 51 61 62 51 62 52 52 62 63 52 63 53 53 63 64 53 64 54 54 64 65 54 65 55 55 65 66 55 66 56 56 66 67 56 67 57 57 67 68 57 68 58 58 68 69 58 69 59 60 70 71 60 71 61 61 71 72 61 72 62 62 72 73 62 73 63 63 73 74 63 74 64 64 74 75 64 75 65 65 75 76 65 76 66 66 76 77 66 77 67 67 77 78 67 78 68 68 78 79 68 79 69 70 80 81 70 81 71 71 81 82 71 82 72 72 82 83 72 83 73 73 83 84 73 84 74 74 84 85 74 85 75 75 85 86 75 86 76 76 86 87 76 87 77 77 87 88 77 88 78 78 88 89 78 89 79 80 90 91 80 91 81 81 91 92 81 92 82 82 92 93 82 93 83 83 93 94 83 94 84 84 94 95 84 95 85 85 95 96 85 96 86 86 96 97 86 97 87 87 97 98 87 98 88 88 98 99 88 99 89"></config>
				<config key="edge" value="0 1 2 3 4 1 5 6 3 7 8 6 9 10 7 11 12 10 13 14 11 15 16 14 17 18 15 19 20 18 21 22 19 23 24 22 25 26 23 27 28 26 29 30 27 31 32 30 33 34 31 35 36 34 37 38 39 40 0 38 41 42 40 43 5 42 44 45 43 46 9 45 47 48 46 49 13 48 50 51 49 52 17 51 53 54 52 55 21 54 56 57 55 58 25 57 59 60 58 61 29 60 62 63 61 64 33 63 65 66 67 68 37 66 69 70 68 71 41 70 72 73 71 74 44 73 75 76 74 77 47 76 78 79 77 80 50 79 81 82 80 83 53 82 84 85 83 86 56 85 87 88 86 89 59 88 90 91 89 92 62 91 93 94 95 96 65 94 97 98 96 99 69 98 100 101 99 102 72 101 103 104 102 105 75 104 106 107 105 108 78 107 109 110 108 111 81 110 112 113 111 114 84 113 115 116 114 117 87 116 118 119 117 120 90 119 121 122 123 124 93 122 125 126 124 127 97 126 128 129 127 130 100 129 131 132 130 133 103 132 134 135 133 136 106 135 137 138 136 139 109 138 140 141 139 142 112 141 143 144 142 145 115 144 146 147 145 148 118 147 149 150 151 152 121 150 153 154 152 155 125 154 156 157 155 158 128 157 159 160 158 161 131 160 162 163 161 164 134 163 165 166 164 167 137 166 168 169 167 170 140 169 171 172 170 173 143 172 174 175 173 176 146 175 177 178 179 180 149 178 181 182 180 183 153 182 184 185 183 186 156 185 187 188 186 189 159 188 190 191 189 192 162 191 193 194 192 195 165 194 196 197 195 198 168 197 199 200 198 201 171 200 202 203 201 204 174 203 205 206 207 208 177 206 209 210 208 211 181 210 212 213 211 214 184 213 215 216 214 217 187 216 218 219 217 220 190 219 221 222 220 223 193 222 224 225 223 226 196 225 227 228 226 229 199 228 230 231 229 232 202 231 233 234 235 236 205 234 237 238 236 239 209 238 240 241 239 242 212 241 243 244 242 245 215 244 246 247 245 248 218 247 249 250 248 251 221 250 252 253 251 254 224 253 255 256 254 257 227 256 258 259 257 260 230 259 0 0 0 0 0 0 0 0 0 0 0 0 0 0 0 0 0 0 0 0 0 0 0 0 0 0 0 0 0 0 0 0 0 0 0 0 0 0 0 0 0 0 0 0 0 0 0 0 0 0 0 0 0 0 0 0 0 0 0 0 0 0 0 0 0 0 0 0 0 0 0 0 0 0 0 0 0 0 0 0 0 0 0 0 0 0 0 0 0 0 0 0 0 0 0 0 0 0 0 0 0 0 0 0 0 0 0 0 0 0 0 0 0 0 0 0 0 0 0 0 0 0 0 0 0 0 0 0 0 0 0 0 0 0 0 0 0 0 0 0 0 0 0 0 0 0 0 0 0 0 0 0 0 0 0 0 0 0 0 0 0 0 0 0 0 0 0 0 0 0 0 0 0 0 0 0 0 0 0 0 0 0 0 0 0 0 0 0 0 0 0 0 0 0 0 0 0 0 0 0 0 0 0 0 0 0 0 0 0 0 0 0 0 0 0 0 0 0 0 0 0 0 0 0 0 0 0 0 0 0 0 0 0 0 0 0 0 0 0 0 0 0 0 0 0 0 0 0 0 0 0 0 0 0 0 0 0 0 0 0 0 0 0 0 0 0 0 0 0 0 0 0 0 0 0 0 0 0 0 0 0 0 0 0 0 0 0 0 0 0 0 0 0 0 0 0 0 0 0 0 0 0 0 0 0 0 0 0 0 0 0 0 0 0 0 0 0 0 0 0 0 0 0 0 0 0 0 0 0 0 0 0 0 0 0 0 0 0 0 0 0 0 0 0 0 0 0 0 0 0 0 0 0 0 0 0 0 0 0 0 0 0 0 0 0 0 0 0 0 0 0 0 0 0 0 0 0 0 0 0 0 0 0 0 0 0 0 0 0 0 0 0 0 0 0 0 0 0 0 0 0 0 0 0 0 0 0 0 0 0 0 0 0 0 0 0 0 0 0 0 0 0 0 0 0 0 0 0 0 0 0 0 0 0 0 0 0 0 0 0 0 0 0 0 0 0 0 0 0 0 0 0 0 0 0 0 0 0 0 0 0 0 0 0 0 0 0 0 0 0 0 0 0 0 0 0 0 0 0 0 0 0 0 0 0 0 0 0 0 0 0 0 0 0 0 0 0 0 0 0 0 0 0 0 0 0 0 0 0 0 0 0 0 0 0 0 0 0 0 0 0 0 0 0 0 0 0 0 0 0 0 0 0 0 0 0 0 0 0 0 0 0 0 0 0 0 0 0 0 0 0 0 0 0 0 0 0 0 0 0 0 0 0 0 0 0 0 0 0 0 0 0 0 0 0 0 0 0 0 0 0 0 0 0 0 0 0 0 0 0 0 0 0 0 0 0 0 0 0 0 0 0 0 0 0 0 0 0 0 0 0 0 0 0 0 0 0 0 0 0 0 0 0 0 0 0 0 0 0 0 0 0 0 0 0 0 0 0 0 0 0 0 0 0 0 0 0 0 0 0 0 0 0 0 0 0 0 0 0 0 0 0 0 0 0 0 0 0 0 0 0 0 0 0 0 0 0 0 0 0 0 0 0 0 0 0 0 0 0 0 0 0 0 0 0 0 0 0 0 0 0 0 0 0 0 0 0 0 0 0 0 0 0 0 0 0 0 0 0 0 0 0 0 0 0 0 0 0 0 0 0 0 0 0 0 0 0 0 0 0 0 0 0 0 0 0 0 0 0 0 0 0 0 0 0 0 0 0 0 0 0 0 0 0 0 0 0 0 0 0 0 0 0 0 0 0 0 0 0 0 0 0 0 0 0 0 0 0 0 0 0 0 0 0 0 0 0 0 0 0 0 0 0 0 0 0 0 0 0 0 0 0 0 0 0 0 0 0 0 0 0 0 0 0 0 0 0 0 0 0 0 0 0 0 0 0 0 0 0 0 0 0 0 0 0 0 0 0 0 0 0 0 0 0 0 0 0 0 0 0 0 0 0 0 0 0 0 0 0 0 0 0 0 0 0 0 0 0 0 0 0 0 0 0 0 0 0 0 0 0 0 0 0 0 0 0 0 0 0 0 0 0 0 0 0 0 0 0 0 0 0 0 0 0 0 0 0 0 0 0 0 0 0 0 0 0 0 0 0 0 0 0 0 0 0 0 0 0 0 0 0 0 0 0 0 0 0 0 0 0 0 0 0 0 0 0 0 0 0 0 0 0 0 0 0 0 0 0 0 0 0 0"></config>
				<config key="young" value="85242.02369946481"></config>
				<config key="poisson" value="0.4032740512363587"></config>
				<config key="thickness" value="0.0005"></config>
			</instance>
		</plugin>
	</extension>
	<worldbody>
		<geom name="floor" size="0 0 0.1" type="plane"></geom>
		<light pos="0 0 4" dir="0 0 -1" diffuse="0.6 0.6 0.6" specular="0.2 0.2 0.2"></light>
		<body>
			<body name="object" pos="0 0 0.83">
				<site name="bottom_site" pos="0 0 -0.045" rgba="0 0 0 0"></site>
				<site name="top_site" pos="0 0 0.03" rgba="0 0 0 0"></site>
				<site name="horizontal_radius_site" pos="0.03 0.03 0" rgba="0 0 0 0"></site>
				<body name="cloth_0" pos="0.0076   -0.11      0.00075">
					<inertial pos="0 0 0" mass="0.005" diaginertia="8.33333e-08 8.33333e-08 8.33333e-08"></inertial>
					<joint pos="0 0 0" axis="1 0 0" type="slide"></joint>
					<joint pos="0 0 0" axis="0 1 0" type="slide"></joint>
					<joint pos="0 0 0" axis="0 0 1" type="slide"></joint>
					<plugin instance="cloth_flexcomp_cloth"></plugin>
				</body>
				<body name="cloth_1" pos="-0.0033   -0.15      0.02">
					<inertial pos="0 0 0" mass="0.005" diaginertia="8.33333e-08 8.33333e-08 8.33333e-08"></inertial>
					<joint pos="0 0 0" axis="1 0 0" type="slide"></joint>
					<joint pos="0 0 0" axis="0 1 0" type="slide"></joint>
					<joint pos="0 0 0" axis="0 0 1" type="slide"></joint>
					<plugin instance="cloth_flexcomp_cloth"></plugin>
				</body>
				<body name="cloth_2" pos="-0.014    -0.11      0.00075">
					<inertial pos="0 0 0" mass="0.005" diaginertia="8.33333e-08 8.33333e-08 8.33333e-08"></inertial>
					<joint pos="0 0 0" axis="1 0 0" type="slide"></joint>
					<joint pos="0 0 0" axis="0 1 0" type="slide"></joint>
					<joint pos="0 0 0" axis="0 0 1" type="slide"></joint>
					<plugin instance="cloth_flexcomp_cloth"></plugin>
				</body>
				<body name="cloth_3" pos="-0.062    -0.12      0.004">
					<inertial pos="0 0 0" mass="0.005" diaginertia="8.33333e-08 8.33333e-08 8.33333e-08"></inertial>
					<joint pos="0 0 0" axis="1 0 0" type="slide"></joint>
					<joint pos="0 0 0" axis="0 1 0" type="slide"></joint>
					<joint pos="0 0 0" axis="0 0 1" type="slide"></joint>
					<plugin instance="cloth_flexcomp_cloth"></plugin>
				</body>
				<body name="cloth_4" pos="-0.11     -0.12      0.00064">
					<inertial pos="0 0 0" mass="0.005" diaginertia="8.33333e-08 8.33333e-08 8.33333e-08"></inertial>
					<joint pos="0 0 0" axis="1 0 0" type="slide"></joint>
					<joint pos="0 0 0" axis="0 1 0" type="slide"></joint>
					<joint pos="0 0 0" axis="0 0 1" type="slide"></joint>
					<plugin instance="cloth_flexcomp_cloth"></plugin>
				</body>
				<body name="cloth_5" pos="-0.13     -0.068     0.00077">
					<inertial pos="0 0 0" mass="0.005" diaginertia="8.33333e-08 8.33333e-08 8.33333e-08"></inertial>
					<joint pos="0 0 0" axis="1 0 0" type="slide"></joint>
					<joint pos="0 0 0" axis="0 1 0" type="slide"></joint>
					<joint pos="0 0 0" axis="0 0 1" type="slide"></joint>
					<plugin instance="cloth_flexcomp_cloth"></plugin>
				</body>
				<body name="cloth_6" pos="-0.078    -0.052     0.00057">
					<inertial pos="0 0 0" mass="0.005" diaginertia="8.33333e-08 8.33333e-08 8.33333e-08"></inertial>
					<joint pos="0 0 0" axis="1 0 0" type="slide"></joint>
					<joint pos="0 0 0" axis="0 1 0" type="slide"></joint>
					<joint pos="0 0 0" axis="0 0 1" type="slide"></joint>
					<plugin instance="cloth_flexcomp_cloth"></plugin>
				</body>
				<body name="cloth_7" pos="-0.031    -0.035     0.00076">
					<inertial pos="0 0 0" mass="0.005" diaginertia="8.33333e-08 8.33333e-08 8.33333e-08"></inertial>
					<joint pos="0 0 0" axis="1 0 0" type="slide"></joint>
					<joint pos="0 0 0" axis="0 1 0" type="slide"></joint>
					<joint pos="0 0 0" axis="0 0 1" type="slide"></joint>
					<plugin instance="cloth_flexcomp_cloth"></plugin>
				</body>
				<body name="cloth_8" pos="0.016    -0.019     0.00076">
					<inertial pos="0 0 0" mass="0.005" diaginertia="8.33333e-08 8.33333e-08 8.33333e-08"></inertial>
					<joint pos="0 0 0" axis="1 0 0" type="slide"></joint>
					<joint pos="0 0 0" axis="0 1 0" type="slide"></joint>
					<joint pos="0 0 0" axis="0 0 1" type="slide"></joint>
					<plugin instance="cloth_flexcomp_cloth"></plugin>
				</body>
				<body name="cloth_9" pos="0.063    -0.0026    0.00076">
					<inertial pos="0 0 0" mass="0.005" diaginertia="8.33333e-08 8.33333e-08 8.33333e-08"></inertial>
					<joint pos="0 0 0" axis="1 0 0" type="slide"></joint>
					<joint pos="0 0 0" axis="0 1 0" type="slide"></joint>
					<joint pos="0 0 0" axis="0 0 1" type="slide"></joint>
					<plugin instance="cloth_flexcomp_cloth"></plugin>
				</body>
				<body name="cloth_10" pos="-0.033    -0.14      0.00081">
					<inertial pos="0 0 0" mass="0.005" diaginertia="8.33333e-08 8.33333e-08 8.33333e-08"></inertial>
					<joint pos="0 0 0" axis="1 0 0" type="slide"></joint>
					<joint pos="0 0 0" axis="0 1 0" type="slide"></joint>
					<joint pos="0 0 0" axis="0 0 1" type="slide"></joint>
					<plugin instance="cloth_flexcomp_cloth"></plugin>
				</body>
				<body name="cloth_11" pos="-0.039    -0.13      0.049">
					<inertial pos="0 0 0" mass="0.005" diaginertia="8.33333e-08 8.33333e-08 8.33333e-08"></inertial>
					<joint pos="0 0 0" axis="1 0 0" type="slide"></joint>
					<joint pos="0 0 0" axis="0 1 0" type="slide"></joint>
					<joint pos="0 0 0" axis="0 0 1" type="slide"></joint>
					<plugin instance="cloth_flexcomp_cloth"></plugin>
				</body>
				<body name="cloth_12" pos="-0.062    -0.12      0.0061">
					<inertial pos="0 0 0" mass="0.005" diaginertia="8.33333e-08 8.33333e-08 8.33333e-08"></inertial>
					<joint pos="0 0 0" axis="1 0 0" type="slide"></joint>
					<joint pos="0 0 0" axis="0 1 0" type="slide"></joint>
					<joint pos="0 0 0" axis="0 0 1" type="slide"></joint>
					<plugin instance="cloth_flexcomp_cloth"></plugin>
				</body>
				<body name="cloth_13" pos="-0.072    -0.067     0.00078">
					<inertial pos="0 0 0" mass="0.005" diaginertia="8.33333e-08 8.33333e-08 8.33333e-08"></inertial>
					<joint pos="0 0 0" axis="1 0 0" type="slide"></joint>
					<joint pos="0 0 0" axis="0 1 0" type="slide"></joint>
					<joint pos="0 0 0" axis="0 0 1" type="slide"></joint>
					<plugin instance="cloth_flexcomp_cloth"></plugin>
				</body>
				<body name="cloth_14" pos="-0.12     -0.073     0.023">
					<inertial pos="0 0 0" mass="0.005" diaginertia="8.33333e-08 8.33333e-08 8.33333e-08"></inertial>
					<joint pos="0 0 0" axis="1 0 0" type="slide"></joint>
					<joint pos="0 0 0" axis="0 1 0" type="slide"></joint>
					<joint pos="0 0 0" axis="0 0 1" type="slide"></joint>
					<plugin instance="cloth_flexcomp_cloth"></plugin>
				</body>
				<body name="cloth_15" pos="-0.077    -0.053     0.0024">
					<inertial pos="0 0 0" mass="0.005" diaginertia="8.33333e-08 8.33333e-08 8.33333e-08"></inertial>
					<joint pos="0 0 0" axis="1 0 0" type="slide"></joint>
					<joint pos="0 0 0" axis="0 1 0" type="slide"></joint>
					<joint pos="0 0 0" axis="0 0 1" type="slide"></joint>
					<plugin instance="cloth_flexcomp_cloth"></plugin>
				</body>
				<body name="cloth_16" pos="-0.095    -0.0052    0.00077">
					<inertial pos="0 0 0" mass="0.005" diaginertia="8.33333e-08 8.33333e-08 8.33333e-08"></inertial>
					<joint pos="0 0 0" axis="1 0 0" type="slide"></joint>
					<joint pos="0 0 0" axis="0 1 0" type="slide"></joint>
					<joint pos="0 0 0" axis="0 0 1" type="slide"></joint>
					<plugin instance="cloth_flexcomp_cloth"></plugin>
				</body>
				<body name="cloth_17" pos="-0.048     0.012     0.00076">
					<inertial pos="0 0 0" mass="0.005" diaginertia="8.33333e-08 8.33333e-08 8.33333e-08"></inertial>
					<joint pos="0 0 0" axis="1 0 0" type="slide"></joint>
					<joint pos="0 0 0" axis="0 1 0" type="slide"></joint>
					<joint pos="0 0 0" axis="0 0 1" type="slide"></joint>
					<plugin instance="cloth_flexcomp_cloth"></plugin>
				</body>
				<body name="cloth_18" pos="-0.00069   0.028     0.00076">
					<inertial pos="0 0 0" mass="0.005" diaginertia="8.33333e-08 8.33333e-08 8.33333e-08"></inertial>
					<joint pos="0 0 0" axis="1 0 0" type="slide"></joint>
					<joint pos="0 0 0" axis="0 1 0" type="slide"></joint>
					<joint pos="0 0 0" axis="0 0 1" type="slide"></joint>
					<plugin instance="cloth_flexcomp_cloth"></plugin>
				</body>
				<body name="cloth_19" pos="0.047     0.045     0.00076">
					<inertial pos="0 0 0" mass="0.005" diaginertia="8.33333e-08 8.33333e-08 8.33333e-08"></inertial>
					<joint pos="0 0 0" axis="1 0 0" type="slide"></joint>
					<joint pos="0 0 0" axis="0 1 0" type="slide"></joint>
					<joint pos="0 0 0" axis="0 0 1" type="slide"></joint>
					<plugin instance="cloth_flexcomp_cloth"></plugin>
				</body>
				<body name="cloth_20" pos="-0.037    -0.13      0.051">
					<inertial pos="0 0 0" mass="0.005" diaginertia="8.33333e-08 8.33333e-08 8.33333e-08"></inertial>
					<joint pos="0 0 0" axis="1 0 0" type="slide"></joint>
					<joint pos="0 0 0" axis="0 1 0" type="slide"></joint>
					<joint pos="0 0 0" axis="0 0 1" type="slide"></joint>
					<plugin instance="cloth_flexcomp_cloth"></plugin>
				</body>
				<body name="cloth_21" pos="-0.077    -0.16      0.05">
					<inertial pos="0 0 0" mass="0.005" diaginertia="8.33333e-08 8.33333e-08 8.33333e-08"></inertial>
					<joint pos="0 0 0" axis="1 0 0" type="slide"></joint>
					<joint pos="0 0 0" axis="0 1 0" type="slide"></joint>
					<joint pos="0 0 0" axis="0 0 1" type="slide"></joint>
					<plugin instance="cloth_flexcomp_cloth"></plugin>
				</body>
				<body name="cloth_22" pos="-0.11     -0.12      0.03">
					<inertial pos="0 0 0" mass="0.005" diaginertia="8.33333e-08 8.33333e-08 8.33333e-08"></inertial>
					<joint pos="0 0 0" axis="1 0 0" type="slide"></joint>
					<joint pos="0 0 0" axis="0 1 0" type="slide"></joint>
					<joint pos="0 0 0" axis="0 0 1" type="slide"></joint>
					<plugin instance="cloth_flexcomp_cloth"></plugin>
				</body>
				<body name="cloth_23" pos="-0.12     -0.076     0.015">
					<inertial pos="0 0 0" mass="0.005" diaginertia="8.33333e-08 8.33333e-08 8.33333e-08"></inertial>
					<joint pos="0 0 0" axis="1 0 0" type="slide"></joint>
					<joint pos="0 0 0" axis="0 1 0" type="slide"></joint>
					<joint pos="0 0 0" axis="0 0 1" type="slide"></joint>
					<plugin instance="cloth_flexcomp_cloth"></plugin>
				</body>
				<body name="cloth_24" pos="-0.13     -0.026     0.0078">
					<inertial pos="0 0 0" mass="0.005" diaginertia="8.33333e-08 8.33333e-08 8.33333e-08"></inertial>
					<joint pos="0 0 0" axis="1 0 0" type="slide"></joint>
					<joint pos="0 0 0" axis="0 1 0" type="slide"></joint>
					<joint pos="0 0 0" axis="0 0 1" type="slide"></joint>
					<plugin instance="cloth_flexcomp_cloth"></plugin>
				</body>
				<body name="cloth_25" pos="-0.085    -0.01      0.028">
					<inertial pos="0 0 0" mass="0.005" diaginertia="8.33333e-08 8.33333e-08 8.33333e-08"></inertial>
					<joint pos="0 0 0" axis="1 0 0" type="slide"></joint>
					<joint pos="0 0 0" axis="0 1 0" type="slide"></joint>
					<joint pos="0 0 0" axis="0 0 1" type="slide"></joint>
					<plugin instance="cloth_flexcomp_cloth"></plugin>
				</body>
				<body name="cloth_26" pos="-0.048     0.012     0.0026">
					<inertial pos="0 0 0" mass="0.005" diaginertia="8.33333e-08 8.33333e-08 8.33333e-08"></inertial>
					<joint pos="0 0 0" axis="1 0 0" type="slide"></joint>
					<joint pos="0 0 0" axis="0 1 0" type="slide"></joint>
					<joint pos="0 0 0" axis="0 0 1" type="slide"></joint>
					<plugin instance="cloth_flexcomp_cloth"></plugin>
				</body>
				<body name="cloth_27" pos="-0.065     0.059     0.00075">
					<inertial pos="0 0 0" mass="0.005" diaginertia="8.33333e-08 8.33333e-08 8.33333e-08"></inertial>
					<joint pos="0 0 0" axis="1 0 0" type="slide"></joint>
					<joint pos="0 0 0" axis="0 1 0" type="slide"></joint>
					<joint pos="0 0 0" axis="0 0 1" type="slide"></joint>
					<plugin instance="cloth_flexcomp_cloth"></plugin>
				</body>
				<body name="cloth_28" pos="-0.017     0.076     0.00076">
					<inertial pos="0 0 0" mass="0.005" diaginertia="8.33333e-08 8.33333e-08 8.33333e-08"></inertial>
					<joint pos="0 0 0" axis="1 0 0" type="slide"></joint>
					<joint pos="0 0 0" axis="0 1 0" type="slide"></joint>
					<joint pos="0 0 0" axis="0 0 1" type="slide"></joint>
					<plugin instance="cloth_flexcomp_cloth"></plugin>
				</body>
				<body name="cloth_29" pos="0.03      0.092     0.00076">
					<inertial pos="0 0 0" mass="0.005" diaginertia="8.33333e-08 8.33333e-08 8.33333e-08"></inertial>
					<joint pos="0 0 0" axis="1 0 0" type="slide"></joint>
					<joint pos="0 0 0" axis="0 1 0" type="slide"></joint>
					<joint pos="0 0 0" axis="0 0 1" type="slide"></joint>
					<plugin instance="cloth_flexcomp_cloth"></plugin>
				</body>
				<body name="cloth_30" pos="-0.061    -0.17      0.05">
					<inertial pos="0 0 0" mass="0.005" diaginertia="8.33333e-08 8.33333e-08 8.33333e-08"></inertial>
					<joint pos="0 0 0" axis="1 0 0" type="slide"></joint>
					<joint pos="0 0 0" axis="0 1 0" type="slide"></joint>
					<joint pos="0 0 0" axis="0 0 1" type="slide"></joint>
					<plugin instance="cloth_flexcomp_cloth"></plugin>
				</body>
				<body name="cloth_31" pos="-0.062    -0.17      0.00072">
					<inertial pos="0 0 0" mass="0.005" diaginertia="8.33333e-08 8.33333e-08 8.33333e-08"></inertial>
					<joint pos="0 0 0" axis="1 0 0" type="slide"></joint>
					<joint pos="0 0 0" axis="0 1 0" type="slide"></joint>
					<joint pos="0 0 0" axis="0 0 1" type="slide"></joint>
					<plugin instance="cloth_flexcomp_cloth"></plugin>
				</body>
				<body name="cloth_32" pos="-0.067    -0.12      1.7e-05">
					<inertial pos="0 0 0" mass="0.005" diaginertia="8.33333e-08 8.33333e-08 8.33333e-08"></inertial>
					<joint pos="0 0 0" axis="1 0 0" type="slide"></joint>
					<joint pos="0 0 0" axis="0 1 0" type="slide"></joint>
					<joint pos="0 0 0" axis="0 0 1" type="slide"></joint>
					<plugin instance="cloth_flexcomp_cloth"></plugin>
				</body>
				<body name="cloth_33" pos="-0.074    -0.069     0.00067">
					<inertial pos="0 0 0" mass="0.005" diaginertia="8.33333e-08 8.33333e-08 8.33333e-08"></inertial>
					<joint pos="0 0 0" axis="1 0 0" type="slide"></joint>
					<joint pos="0 0 0" axis="0 1 0" type="slide"></joint>
					<joint pos="0 0 0" axis="0 0 1" type="slide"></joint>
					<plugin instance="cloth_flexcomp_cloth"></plugin>
				</body>
				<body name="cloth_34" pos="-0.08     -0.019     0.00075">
					<inertial pos="0 0 0" mass="0.005" diaginertia="8.33333e-08 8.33333e-08 8.33333e-08"></inertial>
					<joint pos="0 0 0" axis="1 0 0" type="slide"></joint>
					<joint pos="0 0 0" axis="0 1 0" type="slide"></joint>
					<joint pos="0 0 0" axis="0 0 1" type="slide"></joint>
					<plugin instance="cloth_flexcomp_cloth"></plugin>
				</body>
				<body name="cloth_35" pos="-0.085     0.031     0.00079">
					<inertial pos="0 0 0" mass="0.005" diaginertia="8.33333e-08 8.33333e-08 8.33333e-08"></inertial>
					<joint pos="0 0 0" axis="1 0 0" type="slide"></joint>
					<joint pos="0 0 0" axis="0 1 0" type="slide"></joint>
					<joint pos="0 0 0" axis="0 0 1" type="slide"></joint>
					<plugin instance="cloth_flexcomp_cloth"></plugin>
				</body>
				<body name="cloth_36" pos="-0.053     0.053     0.033">
					<inertial pos="0 0 0" mass="0.005" diaginertia="8.33333e-08 8.33333e-08 8.33333e-08"></inertial>
					<joint pos="0 0 0" axis="1 0 0" type="slide"></joint>
					<joint pos="0 0 0" axis="0 1 0" type="slide"></joint>
					<joint pos="0 0 0" axis="0 0 1" type="slide"></joint>
					<plugin instance="cloth_flexcomp_cloth"></plugin>
				</body>
				<body name="cloth_37" pos="-0.018     0.076     0.0051">
					<inertial pos="0 0 0" mass="0.005" diaginertia="8.33333e-08 8.33333e-08 8.33333e-08"></inertial>
					<joint pos="0 0 0" axis="1 0 0" type="slide"></joint>
					<joint pos="0 0 0" axis="0 1 0" type="slide"></joint>
					<joint pos="0 0 0" axis="0 0 1" type="slide"></joint>
					<plugin instance="cloth_flexcomp_cloth"></plugin>
				</body>
				<body name="cloth_38" pos="-0.033     0.12      0.00075">
					<inertial pos="0 0 0" mass="0.005" diaginertia="8.33333e-08 8.33333e-08 8.33333e-08"></inertial>
					<joint pos="0 0 0" axis="1 0 0" type="slide"></joint>
					<joint pos="0 0 0" axis="0 1 0" type="slide"></joint>
					<joint pos="0 0 0" axis="0 0 1" type="slide"></joint>
					<plugin instance="cloth_flexcomp_cloth"></plugin>
				</body>
				<body name="cloth_39" pos="0.014     0.14      0.0007">
					<inertial pos="0 0 0" mass="0.005" diaginertia="8.33333e-08 8.33333e-08 8.33333e-08"></inertial>
					<joint pos="0 0 0" axis="1 0 0" type="slide"></joint>
					<joint pos="0 0 0" axis="0 1 0" type="slide"></joint>
					<joint pos="0 0 0" axis="0 0 1" type="slide"></joint>
					<plugin instance="cloth_flexcomp_cloth"></plugin>
				</body>
				<body name="cloth_40" pos="-0.059    -0.17      0.00068">
					<inertial pos="0 0 0" mass="0.005" diaginertia="8.33333e-08 8.33333e-08 8.33333e-08"></inertial>
					<joint pos="0 0 0" axis="1 0 0" type="slide"></joint>
					<joint pos="0 0 0" axis="0 1 0" type="slide"></joint>
					<joint pos="0 0 0" axis="0 0 1" type="slide"></joint>
					<plugin instance="cloth_flexcomp_cloth"></plugin>
				</body>
				<body name="cloth_41" pos="-0.011    -0.16      0.00074">
					<inertial pos="0 0 0" mass="0.005" diaginertia="8.33333e-08 8.33333e-08 8.33333e-08"></inertial>
					<joint pos="0 0 0" axis="1 0 0" type="slide"></joint>
					<joint pos="0 0 0" axis="0 1 0" type="slide"></joint>
					<joint pos="0 0 0" axis="0 0 1" type="slide"></joint>
					<plugin instance="cloth_flexcomp_cloth"></plugin>
				</body>
				<body name="cloth_42" pos="-0.017    -0.11      0.00076">
					<inertial pos="0 0 0" mass="0.005" diaginertia="8.33333e-08 8.33333e-08 8.33333e-08"></inertial>
					<joint pos="0 0 0" axis="1 0 0" type="slide"></joint>
					<joint pos="0 0 0" axis="0 1 0" type="slide"></joint>
					<joint pos="0 0 0" axis="0 0 1" type="slide"></joint>
					<plugin instance="cloth_flexcomp_cloth"></plugin>
				</body>
				<body name="cloth_43" pos="-0.024    -0.064     0.00077">
					<inertial pos="0 0 0" mass="0.005" diaginertia="8.33333e-08 8.33333e-08 8.33333e-08"></inertial>
					<joint pos="0 0 0" axis="1 0 0" type="slide"></joint>
					<joint pos="0 0 0" axis="0 1 0" type="slide"></joint>
					<joint pos="0 0 0" axis="0 0 1" type="slide"></joint>
					<plugin instance="cloth_flexcomp_cloth"></plugin>
				</body>
				<body name="cloth_44" pos="-0.031    -0.014     0.00076">
					<inertial pos="0 0 0" mass="0.005" diaginertia="8.33333e-08 8.33333e-08 8.33333e-08"></inertial>
					<joint pos="0 0 0" axis="1 0 0" type="slide"></joint>
					<joint pos="0 0 0" axis="0 1 0" type="slide"></joint>
					<joint pos="0 0 0" axis="0 0 1" type="slide"></joint>
					<plugin instance="cloth_flexcomp_cloth"></plugin>
				</body>
				<body name="cloth_45" pos="-0.035     0.035     0.00076">
					<inertial pos="0 0 0" mass="0.005" diaginertia="8.33333e-08 8.33333e-08 8.33333e-08"></inertial>
					<joint pos="0 0 0" axis="1 0 0" type="slide"></joint>
					<joint pos="0 0 0" axis="0 1 0" type="slide"></joint>
					<joint pos="0 0 0" axis="0 0 1" type="slide"></joint>
					<plugin instance="cloth_flexcomp_cloth"></plugin>
				</body>
				<body name="cloth_46" pos="-0.037     0.085     0.00017">
					<inertial pos="0 0 0" mass="0.005" diaginertia="8.33333e-08 8.33333e-08 8.33333e-08"></inertial>
					<joint pos="0 0 0" axis="1 0 0" type="slide"></joint>
					<joint pos="0 0 0" axis="0 1 0" type="slide"></joint>
					<joint pos="0 0 0" axis="0 0 1" type="slide"></joint>
					<plugin instance="cloth_flexcomp_cloth"></plugin>
				</body>
				<body name="cloth_47" pos="-0.024     0.12      0.03">
					<inertial pos="0 0 0" mass="0.005" diaginertia="8.33333e-08 8.33333e-08 8.33333e-08"></inertial>
					<joint pos="0 0 0" axis="1 0 0" type="slide"></joint>
					<joint pos="0 0 0" axis="0 1 0" type="slide"></joint>
					<joint pos="0 0 0" axis="0 0 1" type="slide"></joint>
					<plugin instance="cloth_flexcomp_cloth"></plugin>
				</body>
				<body name="cloth_48" pos="0.015     0.14      0.0027">
					<inertial pos="0 0 0" mass="0.005" diaginertia="8.33333e-08 8.33333e-08 8.33333e-08"></inertial>
					<joint pos="0 0 0" axis="1 0 0" type="slide"></joint>
					<joint pos="0 0 0" axis="0 1 0" type="slide"></joint>
					<joint pos="0 0 0" axis="0 0 1" type="slide"></joint>
					<plugin instance="cloth_flexcomp_cloth"></plugin>
				</body>
				<body name="cloth_49" pos="-0.0012    0.19      0.0015">
					<inertial pos="0 0 0" mass="0.005" diaginertia="8.33333e-08 8.33333e-08 8.33333e-08"></inertial>
					<joint pos="0 0 0" axis="1 0 0" type="slide"></joint>
					<joint pos="0 0 0" axis="0 1 0" type="slide"></joint>
					<joint pos="0 0 0" axis="0 0 1" type="slide"></joint>
					<plugin instance="cloth_flexcomp_cloth"></plugin>
				</body>
				<body name="cloth_50" pos="-0.067    -0.12      0.00076">
					<inertial pos="0 0 0" mass="0.005" diaginertia="8.33333e-08 8.33333e-08 8.33333e-08"></inertial>
					<joint pos="0 0 0" axis="1 0 0" type="slide"></joint>
					<joint pos="0 0 0" axis="0 1 0" type="slide"></joint>
					<joint pos="0 0 0" axis="0 0 1" type="slide"></joint>
					<plugin instance="cloth_flexcomp_cloth"></plugin>
				</body>
				<body name="cloth_51" pos="-0.018    -0.12      0.0026">
					<inertial pos="0 0 0" mass="0.005" diaginertia="8.33333e-08 8.33333e-08 8.33333e-08"></inertial>
					<joint pos="0 0 0" axis="1 0 0" type="slide"></joint>
					<joint pos="0 0 0" axis="0 1 0" type="slide"></joint>
					<joint pos="0 0 0" axis="0 0 1" type="slide"></joint>
					<plugin instance="cloth_flexcomp_cloth"></plugin>
				</body>
				<body name="cloth_52" pos="0.032    -0.11      0.00083">
					<inertial pos="0 0 0" mass="0.005" diaginertia="8.33333e-08 8.33333e-08 8.33333e-08"></inertial>
					<joint pos="0 0 0" axis="1 0 0" type="slide"></joint>
					<joint pos="0 0 0" axis="0 1 0" type="slide"></joint>
					<joint pos="0 0 0" axis="0 0 1" type="slide"></joint>
					<plugin instance="cloth_flexcomp_cloth"></plugin>
				</body>
				<body name="cloth_53" pos="0.025    -0.057     0.00082">
					<inertial pos="0 0 0" mass="0.005" diaginertia="8.33333e-08 8.33333e-08 8.33333e-08"></inertial>
					<joint pos="0 0 0" axis="1 0 0" type="slide"></joint>
					<joint pos="0 0 0" axis="0 1 0" type="slide"></joint>
					<joint pos="0 0 0" axis="0 0 1" type="slide"></joint>
					<plugin instance="cloth_flexcomp_cloth"></plugin>
				</body>
				<body name="cloth_54" pos="0.018    -0.0085    0.00065">
					<inertial pos="0 0 0" mass="0.005" diaginertia="8.33333e-08 8.33333e-08 8.33333e-08"></inertial>
					<joint pos="0 0 0" axis="1 0 0" type="slide"></joint>
					<joint pos="0 0 0" axis="0 1 0" type="slide"></joint>
					<joint pos="0 0 0" axis="0 0 1" type="slide"></joint>
					<plugin instance="cloth_flexcomp_cloth"></plugin>
				</body>
				<body name="cloth_55" pos="0.014     0.04      0.00056">
					<inertial pos="0 0 0" mass="0.005" diaginertia="8.33333e-08 8.33333e-08 8.33333e-08"></inertial>
					<joint pos="0 0 0" axis="1 0 0" type="slide"></joint>
					<joint pos="0 0 0" axis="0 1 0" type="slide"></joint>
					<joint pos="0 0 0" axis="0 0 1" type="slide"></joint>
					<plugin instance="cloth_flexcomp_cloth"></plugin>
				</body>
				<body name="cloth_56" pos="0.013     0.087     0.00041">
					<inertial pos="0 0 0" mass="0.005" diaginertia="8.33333e-08 8.33333e-08 8.33333e-08"></inertial>
					<joint pos="0 0 0" axis="1 0 0" type="slide"></joint>
					<joint pos="0 0 0" axis="0 1 0" type="slide"></joint>
					<joint pos="0 0 0" axis="0 0 1" type="slide"></joint>
					<plugin instance="cloth_flexcomp_cloth"></plugin>
				</body>
				<body name="cloth_57" pos="0.013     0.14      0.00066">
					<inertial pos="0 0 0" mass="0.005" diaginertia="8.33333e-08 8.33333e-08 8.33333e-08"></inertial>
					<joint pos="0 0 0" axis="1 0 0" type="slide"></joint>
					<joint pos="0 0 0" axis="0 1 0" type="slide"></joint>
					<joint pos="0 0 0" axis="0 0 1" type="slide"></joint>
					<plugin instance="cloth_flexcomp_cloth"></plugin>
				</body>
				<body name="cloth_58" pos="-0.0028    0.18      0.00071">
					<inertial pos="0 0 0" mass="0.005" diaginertia="8.33333e-08 8.33333e-08 8.33333e-08"></inertial>
					<joint pos="0 0 0" axis="1 0 0" type="slide"></joint>
					<joint pos="0 0 0" axis="0 1 0" type="slide"></joint>
					<joint pos="0 0 0" axis="0 0 1" type="slide"></joint>
					<plugin instance="cloth_flexcomp_cloth"></plugin>
				</body>
				<body name="cloth_59" pos="-0.042     0.17      0.029">
					<inertial pos="0 0 0" mass="0.005" diaginertia="8.33333e-08 8.33333e-08 8.33333e-08"></inertial>
					<joint pos="0 0 0" axis="1 0 0" type="slide"></joint>
					<joint pos="0 0 0" axis="0 1 0" type="slide"></joint>
					<joint pos="0 0 0" axis="0 0 1" type="slide"></joint>
					<plugin instance="cloth_flexcomp_cloth"></plugin>
				</body>
				<body name="cloth_60" pos="-0.017    -0.12      0.00066">
					<inertial pos="0 0 0" mass="0.005" diaginertia="8.33333e-08 8.33333e-08 8.33333e-08"></inertial>
					<joint pos="0 0 0" axis="1 0 0" type="slide"></joint>
					<joint pos="0 0 0" axis="0 1 0" type="slide"></joint>
					<joint pos="0 0 0" axis="0 0 1" type="slide"></joint>
					<plugin instance="cloth_flexcomp_cloth"></plugin>
				</body>
				<body name="cloth_61" pos="-0.027    -0.067     0.00075">
					<inertial pos="0 0 0" mass="0.005" diaginertia="8.33333e-08 8.33333e-08 8.33333e-08"></inertial>
					<joint pos="0 0 0" axis="1 0 0" type="slide"></joint>
					<joint pos="0 0 0" axis="0 1 0" type="slide"></joint>
					<joint pos="0 0 0" axis="0 0 1" type="slide"></joint>
					<plugin instance="cloth_flexcomp_cloth"></plugin>
				</body>
				<body name="cloth_62" pos="0.023    -0.058     0.00078">
					<inertial pos="0 0 0" mass="0.005" diaginertia="8.33333e-08 8.33333e-08 8.33333e-08"></inertial>
					<joint pos="0 0 0" axis="1 0 0" type="slide"></joint>
					<joint pos="0 0 0" axis="0 1 0" type="slide"></joint>
					<joint pos="0 0 0" axis="0 0 1" type="slide"></joint>
					<plugin instance="cloth_flexcomp_cloth"></plugin>
				</body>
				<body name="cloth_63" pos="0.072    -0.046     0.0064">
					<inertial pos="0 0 0" mass="0.005" diaginertia="8.33333e-08 8.33333e-08 8.33333e-08"></inertial>
					<joint pos="0 0 0" axis="1 0 0" type="slide"></joint>
					<joint pos="0 0 0" axis="0 1 0" type="slide"></joint>
					<joint pos="0 0 0" axis="0 0 1" type="slide"></joint>
					<plugin instance="cloth_flexcomp_cloth"></plugin>
				</body>
				<body name="cloth_64" pos="0.06      0.00061   0.024">
					<inertial pos="0 0 0" mass="0.005" diaginertia="8.33333e-08 8.33333e-08 8.33333e-08"></inertial>
					<joint pos="0 0 0" axis="1 0 0" type="slide"></joint>
					<joint pos="0 0 0" axis="0 1 0" type="slide"></joint>
					<joint pos="0 0 0" axis="0 0 1" type="slide"></joint>
					<plugin instance="cloth_flexcomp_cloth"></plugin>
				</body>
				<body name="cloth_65" pos="0.04      0.046     0.041">
					<inertial pos="0 0 0" mass="0.005" diaginertia="8.33333e-08 8.33333e-08 8.33333e-08"></inertial>
					<joint pos="0 0 0" axis="1 0 0" type="slide"></joint>
					<joint pos="0 0 0" axis="0 1 0" type="slide"></joint>
					<joint pos="0 0 0" axis="0 0 1" type="slide"></joint>
					<plugin instance="cloth_flexcomp_cloth"></plugin>
				</body>
				<body name="cloth_66" pos="0.016     0.091     0.049">
					<inertial pos="0 0 0" mass="0.005" diaginertia="8.33333e-08 8.33333e-08 8.33333e-08"></inertial>
					<joint pos="0 0 0" axis="1 0 0" type="slide"></joint>
					<joint pos="0 0 0" axis="0 1 0" type="slide"></joint>
					<joint pos="0 0 0" axis="0 0 1" type="slide"></joint>
					<plugin instance="cloth_flexcomp_cloth"></plugin>
				</body>
				<body name="cloth_67" pos="-0.0093    0.14      0.046">
					<inertial pos="0 0 0" mass="0.005" diaginertia="8.33333e-08 8.33333e-08 8.33333e-08"></inertial>
					<joint pos="0 0 0" axis="1 0 0" type="slide"></joint>
					<joint pos="0 0 0" axis="0 1 0" type="slide"></joint>
					<joint pos="0 0 0" axis="0 0 1" type="slide"></joint>
					<plugin instance="cloth_flexcomp_cloth"></plugin>
				</body>
				<body name="cloth_68" pos="-0.042     0.17      0.028">
					<inertial pos="0 0 0" mass="0.005" diaginertia="8.33333e-08 8.33333e-08 8.33333e-08"></inertial>
					<joint pos="0 0 0" axis="1 0 0" type="slide"></joint>
					<joint pos="0 0 0" axis="0 1 0" type="slide"></joint>
					<joint pos="0 0 0" axis="0 0 1" type="slide"></joint>
					<plugin instance="cloth_flexcomp_cloth"></plugin>
				</body>
				<body name="cloth_69" pos="-0.07      0.2       0.00084">
					<inertial pos="0 0 0" mass="0.005" diaginertia="8.33333e-08 8.33333e-08 8.33333e-08"></inertial>
					<joint pos="0 0 0" axis="1 0 0" type="slide"></joint>
					<joint pos="0 0 0" axis="0 1 0" type="slide"></joint>
					<joint pos="0 0 0" axis="0 0 1" type="slide"></joint>
					<plugin instance="cloth_flexcomp_cloth"></plugin>
				</body>
				<body name="cloth_70" pos="0.032    -0.11      0.00076">
					<inertial pos="0 0 0" mass="0.005" diaginertia="8.33333e-08 8.33333e-08 8.33333e-08"></inertial>
					<joint pos="0 0 0" axis="1 0 0" type="slide"></joint>
					<joint pos="0 0 0" axis="0 1 0" type="slide"></joint>
					<joint pos="0 0 0" axis="0 0 1" type="slide"></joint>
					<plugin instance="cloth_flexcomp_cloth"></plugin>
				</body>
				<body name="cloth_71" pos="0.022    -0.058     0.00076">
					<inertial pos="0 0 0" mass="0.005" diaginertia="8.33333e-08 8.33333e-08 8.33333e-08"></inertial>
					<joint pos="0 0 0" axis="1 0 0" type="slide"></joint>
					<joint pos="0 0 0" axis="0 1 0" type="slide"></joint>
					<joint pos="0 0 0" axis="0 0 1" type="slide"></joint>
					<plugin instance="cloth_flexcomp_cloth"></plugin>
				</body>
				<body name="cloth_72" pos="0.012    -0.0096    0.00075">
					<inertial pos="0 0 0" mass="0.005" diaginertia="8.33333e-08 8.33333e-08 8.33333e-08"></inertial>
					<joint pos="0 0 0" axis="1 0 0" type="slide"></joint>
					<joint pos="0 0 0" axis="0 1 0" type="slide"></joint>
					<joint pos="0 0 0" axis="0 0 1" type="slide"></joint>
					<plugin instance="cloth_flexcomp_cloth"></plugin>
				</body>
				<body name="cloth_73" pos="0.061     0.0029    0.00071">
					<inertial pos="0 0 0" mass="0.005" diaginertia="8.33333e-08 8.33333e-08 8.33333e-08"></inertial>
					<joint pos="0 0 0" axis="1 0 0" type="slide"></joint>
					<joint pos="0 0 0" axis="0 1 0" type="slide"></joint>
					<joint pos="0 0 0" axis="0 0 1" type="slide"></joint>
					<plugin instance="cloth_flexcomp_cloth"></plugin>
				</body>
				<body name="cloth_74" pos="0.013    -0.0087    0.0064">
					<inertial pos="0 0 0" mass="0.005" diaginertia="8.33333e-08 8.33333e-08 8.33333e-08"></inertial>
					<joint pos="0 0 0" axis="1 0 0" type="slide"></joint>
					<joint pos="0 0 0" axis="0 1 0" type="slide"></joint>
					<joint pos="0 0 0" axis="0 0 1" type="slide"></joint>
					<plugin instance="cloth_flexcomp_cloth"></plugin>
				</body>
				<body name="cloth_75" pos="-0.0045    0.027     0.036">
					<inertial pos="0 0 0" mass="0.005" diaginertia="8.33333e-08 8.33333e-08 8.33333e-08"></inertial>
					<joint pos="0 0 0" axis="1 0 0" type="slide"></joint>
					<joint pos="0 0 0" axis="0 1 0" type="slide"></joint>
					<joint pos="0 0 0" axis="0 0 1" type="slide"></joint>
					<plugin instance="cloth_flexcomp_cloth"></plugin>
				</body>
				<body name="cloth_76" pos="-0.027     0.068     0.049">
					<inertial pos="0 0 0" mass="0.005" diaginertia="8.33333e-08 8.33333e-08 8.33333e-08"></inertial>
					<joint pos="0 0 0" axis="1 0 0" type="slide"></joint>
					<joint pos="0 0 0" axis="0 1 0" type="slide"></joint>
					<joint pos="0 0 0" axis="0 0 1" type="slide"></joint>
					<plugin instance="cloth_flexcomp_cloth"></plugin>
				</body>
				<body name="cloth_77" pos="-0.052     0.11      0.047">
					<inertial pos="0 0 0" mass="0.005" diaginertia="8.33333e-08 8.33333e-08 8.33333e-08"></inertial>
					<joint pos="0 0 0" axis="1 0 0" type="slide"></joint>
					<joint pos="0 0 0" axis="0 1 0" type="slide"></joint>
					<joint pos="0 0 0" axis="0 0 1" type="slide"></joint>
					<plugin instance="cloth_flexcomp_cloth"></plugin>
				</body>
				<body name="cloth_78" pos="-0.068     0.14      0.0053">
					<inertial pos="0 0 0" mass="0.005" diaginertia="8.33333e-08 8.33333e-08 8.33333e-08"></inertial>
					<joint pos="0 0 0" axis="1 0 0" type="slide"></joint>
					<joint pos="0 0 0" axis="0 1 0" type="slide"></joint>
					<joint pos="0 0 0" axis="0 0 1" type="slide"></joint>
					<plugin instance="cloth_flexcomp_cloth"></plugin>
				</body>
				<body name="cloth_79" pos="-0.11      0.17      0.00064">
					<inertial pos="0 0 0" mass="0.005" diaginertia="8.33333e-08 8.33333e-08 8.33333e-08"></inertial>
					<joint pos="0 0 0" axis="1 0 0" type="slide"></joint>
					<joint pos="0 0 0" axis="0 1 0" type="slide"></joint>
					<joint pos="0 0 0" axis="0 0 1" type="slide"></joint>
					<plugin instance="cloth_flexcomp_cloth"></plugin>
				</body>
				<body name="cloth_80" pos="0.081    -0.095     0.00076">
					<inertial pos="0 0 0" mass="0.005" diaginertia="8.33333e-08 8.33333e-08 8.33333e-08"></inertial>
					<joint pos="0 0 0" axis="1 0 0" type="slide"></joint>
					<joint pos="0 0 0" axis="0 1 0" type="slide"></joint>
					<joint pos="0 0 0" axis="0 0 1" type="slide"></joint>
					<plugin instance="cloth_flexcomp_cloth"></plugin>
				</body>
				<body name="cloth_81" pos="0.071    -0.047     0.00066">
					<inertial pos="0 0 0" mass="0.005" diaginertia="8.33333e-08 8.33333e-08 8.33333e-08"></inertial>
					<joint pos="0 0 0" axis="1 0 0" type="slide"></joint>
					<joint pos="0 0 0" axis="0 1 0" type="slide"></joint>
					<joint pos="0 0 0" axis="0 0 1" type="slide"></joint>
					<plugin instance="cloth_flexcomp_cloth"></plugin>
				</body>
				<body name="cloth_82" pos="0.061     0.0026    0.00062">
					<inertial pos="0 0 0" mass="0.005" diaginertia="8.33333e-08 8.33333e-08 8.33333e-08"></inertial>
					<joint pos="0 0 0" axis="1 0 0" type="slide"></joint>
					<joint pos="0 0 0" axis="0 1 0" type="slide"></joint>
					<joint pos="0 0 0" axis="0 0 1" type="slide"></joint>
					<plugin instance="cloth_flexcomp_cloth"></plugin>
				</body>
				<body name="cloth_83" pos="0.043     0.051     0.0015">
					<inertial pos="0 0 0" mass="0.005" diaginertia="8.33333e-08 8.33333e-08 8.33333e-08"></inertial>
					<joint pos="0 0 0" axis="1 0 0" type="slide"></joint>
					<joint pos="0 0 0" axis="0 1 0" type="slide"></joint>
					<joint pos="0 0 0" axis="0 0 1" type="slide"></joint>
					<plugin instance="cloth_flexcomp_cloth"></plugin>
				</body>
				<body name="cloth_84" pos="0.0064    0.034     0.032">
					<inertial pos="0 0 0" mass="0.005" diaginertia="8.33333e-08 8.33333e-08 8.33333e-08"></inertial>
					<joint pos="0 0 0" axis="1 0 0" type="slide"></joint>
					<joint pos="0 0 0" axis="0 1 0" type="slide"></joint>
					<joint pos="0 0 0" axis="0 0 1" type="slide"></joint>
					<plugin instance="cloth_flexcomp_cloth"></plugin>
				</body>
				<body name="cloth_85" pos="-0.033     0.044     0.00065">
					<inertial pos="0 0 0" mass="0.005" diaginertia="8.33333e-08 8.33333e-08 8.33333e-08"></inertial>
					<joint pos="0 0 0" axis="1 0 0" type="slide"></joint>
					<joint pos="0 0 0" axis="0 1 0" type="slide"></joint>
					<joint pos="0 0 0" axis="0 0 1" type="slide"></joint>
					<plugin instance="cloth_flexcomp_cloth"></plugin>
				</body>
				<body name="cloth_86" pos="-0.017     0.09      0.0058">
					<inertial pos="0 0 0" mass="0.005" diaginertia="8.33333e-08 8.33333e-08 8.33333e-08"></inertial>
					<joint pos="0 0 0" axis="1 0 0" type="slide"></joint>
					<joint pos="0 0 0" axis="0 1 0" type="slide"></joint>
					<joint pos="0 0 0" axis="0 0 1" type="slide"></joint>
					<plugin instance="cloth_flexcomp_cloth"></plugin>
				</body>
				<body name="cloth_87" pos="-0.064     0.1       0.00039">
					<inertial pos="0 0 0" mass="0.005" diaginertia="8.33333e-08 8.33333e-08 8.33333e-08"></inertial>
					<joint pos="0 0 0" axis="1 0 0" type="slide"></joint>
					<joint pos="0 0 0" axis="0 1 0" type="slide"></joint>
					<joint pos="0 0 0" axis="0 0 1" type="slide"></joint>
					<plugin instance="cloth_flexcomp_cloth"></plugin>
				</body>
				<body name="cloth_88" pos="-0.11      0.11      0.007">
					<inertial pos="0 0 0" mass="0.005" diaginertia="8.33333e-08 8.33333e-08 8.33333e-08"></inertial>
					<joint pos="0 0 0" axis="1 0 0" type="slide"></joint>
					<joint pos="0 0 0" axis="0 1 0" type="slide"></joint>
					<joint pos="0 0 0" axis="0 0 1" type="slide"></joint>
					<plugin instance="cloth_flexcomp_cloth"></plugin>
				</body>
				<body name="cloth_89" pos="-0.13      0.15      0.039">
					<inertial pos="0 0 0" mass="0.005" diaginertia="8.33333e-08 8.33333e-08 8.33333e-08"></inertial>
					<joint pos="0 0 0" axis="1 0 0" type="slide"></joint>
					<joint pos="0 0 0" axis="0 1 0" type="slide"></joint>
					<joint pos="0 0 0" axis="0 0 1" type="slide"></joint>
					<plugin instance="cloth_flexcomp_cloth"></plugin>
				</body>
				<body name="cloth_90" pos="0.071    -0.046     0.0026">
					<inertial pos="0 0 0" mass="0.005" diaginertia="8.33333e-08 8.33333e-08 8.33333e-08"></inertial>
					<joint pos="0 0 0" axis="1 0 0" type="slide"></joint>
					<joint pos="0 0 0" axis="0 1 0" type="slide"></joint>
					<joint pos="0 0 0" axis="0 0 1" type="slide"></joint>
					<plugin instance="cloth_flexcomp_cloth"></plugin>
				</body>
				<body name="cloth_91" pos="0.022    -0.056     0.00076">
					<inertial pos="0 0 0" mass="0.005" diaginertia="8.33333e-08 8.33333e-08 8.33333e-08"></inertial>
					<joint pos="0 0 0" axis="1 0 0" type="slide"></joint>
					<joint pos="0 0 0" axis="0 1 0" type="slide"></joint>
					<joint pos="0 0 0" axis="0 0 1" type="slide"></joint>
					<plugin instance="cloth_flexcomp_cloth"></plugin>
				</body>
				<body name="cloth_92" pos="0.012    -0.0069    0.00082">
					<inertial pos="0 0 0" mass="0.005" diaginertia="8.33333e-08 8.33333e-08 8.33333e-08"></inertial>
					<joint pos="0 0 0" axis="1 0 0" type="slide"></joint>
					<joint pos="0 0 0" axis="0 1 0" type="slide"></joint>
					<joint pos="0 0 0" axis="0 0 1" type="slide"></joint>
					<plugin instance="cloth_flexcomp_cloth"></plugin>
				</body>
				<body name="cloth_93" pos="0.0065    0.032     0.032">
					<inertial pos="0 0 0" mass="0.005" diaginertia="8.33333e-08 8.33333e-08 8.33333e-08"></inertial>
					<joint pos="0 0 0" axis="1 0 0" type="slide"></joint>
					<joint pos="0 0 0" axis="0 1 0" type="slide"></joint>
					<joint pos="0 0 0" axis="0 0 1" type="slide"></joint>
					<plugin instance="cloth_flexcomp_cloth"></plugin>
				</body>
				<body name="cloth_94" pos="-0.029     0.045     0.00048">
					<inertial pos="0 0 0" mass="0.005" diaginertia="8.33333e-08 8.33333e-08 8.33333e-08"></inertial>
					<joint pos="0 0 0" axis="1 0 0" type="slide"></joint>
					<joint pos="0 0 0" axis="0 1 0" type="slide"></joint>
					<joint pos="0 0 0" axis="0 0 1" type="slide"></joint>
					<plugin instance="cloth_flexcomp_cloth"></plugin>
				</body>
				<body name="cloth_95" pos="-0.018     0.092     0.00073">
					<inertial pos="0 0 0" mass="0.005" diaginertia="8.33333e-08 8.33333e-08 8.33333e-08"></inertial>
					<joint pos="0 0 0" axis="1 0 0" type="slide"></joint>
					<joint pos="0 0 0" axis="0 1 0" type="slide"></joint>
					<joint pos="0 0 0" axis="0 0 1" type="slide"></joint>
					<plugin instance="cloth_flexcomp_cloth"></plugin>
				</body>
				<body name="cloth_96" pos="-0.066     0.11      0.00089">
					<inertial pos="0 0 0" mass="0.005" diaginertia="8.33333e-08 8.33333e-08 8.33333e-08"></inertial>
					<joint pos="0 0 0" axis="1 0 0" type="slide"></joint>
					<joint pos="0 0 0" axis="0 1 0" type="slide"></joint>
					<joint pos="0 0 0" axis="0 0 1" type="slide"></joint>
					<plugin instance="cloth_flexcomp_cloth"></plugin>
				</body>
				<body name="cloth_97" pos="-0.052     0.15      0.00077">
					<inertial pos="0 0 0" mass="0.005" diaginertia="8.33333e-08 8.33333e-08 8.33333e-08"></inertial>
					<joint pos="0 0 0" axis="1 0 0" type="slide"></joint>
					<joint pos="0 0 0" axis="0 1 0" type="slide"></joint>
					<joint pos="0 0 0" axis="0 0 1" type="slide"></joint>
					<plugin instance="cloth_flexcomp_cloth"></plugin>
				</body>
				<body name="cloth_98" pos="-0.1       0.16      0.00078">
					<inertial pos="0 0 0" mass="0.005" diaginertia="8.33333e-08 8.33333e-08 8.33333e-08"></inertial>
					<joint pos="0 0 0" axis="1 0 0" type="slide"></joint>
					<joint pos="0 0 0" axis="0 1 0" type="slide"></joint>
					<joint pos="0 0 0" axis="0 0 1" type="slide"></joint>
					<plugin instance="cloth_flexcomp_cloth"></plugin>
				</body>
				<body name="cloth_99" pos="-0.15      0.17      0.00077">
					<inertial pos="0 0 0" mass="0.005" diaginertia="8.33333e-08 8.33333e-08 8.33333e-08"></inertial>
					<joint pos="0 0 0" axis="1 0 0" type="slide"></joint>
					<joint pos="0 0 0" axis="0 1 0" type="slide"></joint>
					<joint pos="0 0 0" axis="0 0 1" type="slide"></joint>
					<plugin instance="cloth_flexcomp_cloth"></plugin>
				</body>
			</body>
		</body>
	</worldbody>
	<deformable>
		<flex name="cloth" rgba="255 0 0 0.4" radius="0.001" body="cloth_0 cloth_1 cloth_2 cloth_3 cloth_4 cloth_5 cloth_6 cloth_7 cloth_8 cloth_9 cloth_10 cloth_11 cloth_12 cloth_13 cloth_14 cloth_15 cloth_16 cloth_17 cloth_18 cloth_19 cloth_20 cloth_21 cloth_22 cloth_23 cloth_24 cloth_25 cloth_26 cloth_27 cloth_28 cloth_29 cloth_30 cloth_31 cloth_32 cloth_33 cloth_34 cloth_35 cloth_36 cloth_37 cloth_38 cloth_39 cloth_40 cloth_41 cloth_42 cloth_43 cloth_44 cloth_45 cloth_46 cloth_47 cloth_48 cloth_49 cloth_50 cloth_51 cloth_52 cloth_53 cloth_54 cloth_55 cloth_56 cloth_57 cloth_58 cloth_59 cloth_60 cloth_61 cloth_62 cloth_63 cloth_64 cloth_65 cloth_66 cloth_67 cloth_68 cloth_69 cloth_70 cloth_71 cloth_72 cloth_73 cloth_74 cloth_75 cloth_76 cloth_77 cloth_78 cloth_79 cloth_80 cloth_81 cloth_82 cloth_83 cloth_84 cloth_85 cloth_86 cloth_87 cloth_88 cloth_89 cloth_90 cloth_91 cloth_92 cloth_93 cloth_94 cloth_95 cloth_96 cloth_97 cloth_98 cloth_99" element="0 10 11 0 11 1 1 11 12 1 12 2 2 12 13 2 13 3 3 13 14 3 14 4 4 14 15 4 15 5 5 15 16 5 16 6 6 16 17 6 17 7 7 17 18 7 18 8 8 18 19 8 19 9 10 20 21 10 21 11 11 21 22 11 22 12 12 22 23 12 23 13 13 23 24 13 24 14 14 24 25 14 25 15 15 25 26 15 26 16 16 26 27 16 27 17 17 27 28 17 28 18 18 28 29 18 29 19 20 30 31 20 31 21 21 31 32 21 32 22 22 32 33 22 33 23 23 33 34 23 34 24 24 34 35 24 35 25 25 35 36 25 36 26 26 36 37 26 37 27 27 37 38 27 38 28 28 38 39 28 39 29 30 40 41 30 41 31 31 41 42 31 42 32 32 42 43 32 43 33 33 43 44 33 44 34 34 44 45 34 45 35 35 45 46 35 46 36 36 46 47 36 47 37 37 47 48 37 48 38 38 48 49 38 49 39 40 50 51 40 51 41 41 51 52 41 52 42 42 52 53 42 53 43 43 53 54 43 54 44 44 54 55 44 55 45 45 55 56 45 56 46 46 56 57 46 57 47 47 57 58 47 58 48 48 58 59 48 59 49 50 60 61 50 61 51 51 61 62 51 62 52 52 62 63 52 63 53 53 63 64 53 64 54 54 64 65 54 65 55 55 65 66 55 66 56 56 66 67 56 67 57 57 67 68 57 68 58 58 68 69 58 69 59 60 70 71 60 71 61 61 71 72 61 72 62 62 72 73 62 73 63 63 73 74 63 74 64 64 74 75 64 75 65 65 75 76 65 76 66 66 76 77 66 77 67 67 77 78 67 78 68 68 78 79 68 79 69 70 80 81 70 81 71 71 81 82 71 82 72 72 82 83 72 83 73 73 83 84 73 84 74 74 84 85 74 85 75 75 85 86 75 86 76 76 86 87 76 87 77 77 87 88 77 88 78 78 88 89 78 89 79 80 90 91 80 91 81 81 91 92 81 92 82 82 92 93 82 93 83 83 93 94 83 94 84 84 94 95 84 95 85 85 95 96 85 96 86 86 96 97 86 97 87 87 97 98 87 98 88 88 98 99 88 99 89">
			<contact solref="0.01 1" solimp=".95 .99 .0001" condim="4" selfcollide="none"></contact>
<!--			<contact solref="0.001 1" solimp="0.1 0.15" condim="4" friction="3 0.01" selfcollide="none"></contact>-->
			<edge damping="1"></edge>
		</flex>
	</deformable>
	<equality>
<!--		<flex flex="cloth"></flex>-->
		<flex flex="cloth_cloth"></flex>
	</equality>
</mujoco>