<?xml version="1.0" encoding="utf-8"?>
<mujoco model="cloth">
	<compiler angle="radian"></compiler>
	<option timestep="0.01" tolerance="1e-06" viscosity="0.3" integrator="implicitfast" solver="CG"></option>
	<size nkey="10"></size>
	<statistic meansize="0.0723053" extent="2" center="0 0 0"></statistic>
	<extension>
		<plugin plugin="mujoco.elasticity.shell">
			<instance name="cloth_flexcomp_cloth">
				<config key="face" value="0 5 6 0 6 1 1 6 7 1 7 2 2 7 8 2 8 3 3 8 9 3 9 4 5 10 11 5 11 6 6 11 12 6 12 7 7 12 13 7 13 8 8 13 14 8 14 9 10 15 16 10 16 11 11 16 17 11 17 12 12 17 18 12 18 13 13 18 19 13 19 14 15 20 21 15 21 16 16 21 22 16 22 17 17 22 23 17 23 18 18 23 24 18 24 19 20 25 26 20 26 21 21 26 27 21 27 22 22 27 28 22 28 23 23 28 29 23 29 24 25 30 31 25 31 26 26 31 32 26 32 27 27 32 33 27 33 28 28 33 34 28 34 29 30 35 36 30 36 31 31 36 37 31 37 32 32 37 38 32 38 33 33 38 39 33 39 34 35 40 41 35 41 36 36 41 42 36 42 37 37 42 43 37 43 38 38 43 44 38 44 39 40 45 46 40 46 41 41 46 47 41 47 42 42 47 48 42 48 43 43 48 49 43 49 44"></config>
				<config key="edge" value="0 1 2 3 4 1 5 6 3 7 8 6 9 10 7 11 12 10 13 14 11 15 16 14 17 18 19 20 0 18 21 22 20 23 5 22 24 25 23 26 9 25 27 28 26 29 13 28 30 31 32 33 17 31 34 35 33 36 21 35 37 38 36 39 24 38 40 41 39 42 27 41 43 44 45 46 30 44 47 48 46 49 34 48 50 51 49 52 37 51 53 54 52 55 40 54 56 57 58 59 43 57 60 61 59 62 47 61 63 64 62 65 50 64 66 67 65 68 53 67 69 70 71 72 56 70 73 74 72 75 60 74 76 77 75 78 63 77 79 80 78 81 66 80 82 83 84 85 69 83 86 87 85 88 73 87 89 90 88 91 76 90 92 93 91 94 79 93 95 96 97 98 82 96 99 100 98 101 86 100 102 103 101 104 89 103 105 106 104 107 92 106 108 109 110 111 95 109 112 113 111 114 99 113 115 116 114 117 102 116 118 119 117 120 105 119 0 0 0 0 0 0 0 0 0 0 0 0 0 0 0 0 0 0 0 0 0 0 0 0 0 0 0 0 0 0 0 0 0 0 0 0 0 0 0 0 0 0 0 0 0 0 0 0 0 0 0 0 0 0 0 0 0 0 0 0 0 0 0 0 0 0 0 0 0 0 0 0 0 0 0 0 0 0 0 0 0 0 0 0 0 0 0 0 0 0 0 0 0 0 0 0 0 0 0 0 0 0 0 0 0 0 0 0 0 0 0 0 0 0 0 0 0 0 0 0 0 0 0 0 0 0 0 0 0 0 0 0 0 0 0 0 0 0 0 0 0 0 0 0 0 0 0 0 0 0 0 0 0 0 0 0 0 0 0 0 0 0 0 0 0 0 0 0 0 0 0 0 0 0 0 0 0 0 0 0 0 0 0 0 0 0 0 0 0 0 0 0 0 0 0 0 0 0 0 0 0 0 0 0 0 0 0 0 0 0 0 0 0 0 0 0 0 0 0 0 0 0 0 0 0 0 0 0 0 0 0 0 0 0 0 0 0 0 0 0 0 0 0 0 0 0 0 0 0 0 0 0 0 0 0 0 0 0 0 0 0 0 0 0 0 0 0 0 0 0 0 0 0 0 0 0 0 0 0 0 0 0 0 0 0 0 0 0 0 0 0 0 0 0 0 0 0 0 0 0 0 0 0 0 0 0 0 0 0 0 0 0 0 0 0 0 0 0 0 0 0 0 0 0 0 0 0 0 0 0 0 0 0 0 0 0 0 0 0 0 0 0 0 0 0 0 0 0 0 0 0 0 0 0 0 0 0 0 0 0 0 0 0 0 0 0 0 0 0 0 0 0 0 0 0 0 0 0 0 0 0 0 0 0 0 0 0 0 0 0 0 0 0 0 0 0 0 0 0 0 0 0 0 0 0 0 0 0 0 0 0 0 0 0 0 0 0 0 0 0 0 0 0 0 0 0 0 0 0 0 0 0"></config>
				<config key="young" value="85242.02369946481"></config>
				<config key="poisson" value="0.4032740512363587"></config>
				<config key="thickness" value="0.0005"></config>
			</instance>
		</plugin>
	</extension>
	<worldbody>
		<geom name="floor" size="0 0 0.1" type="plane"></geom>
		<light pos="0 0 4" dir="0 0 -1" diffuse="0.6 0.6 0.6" specular="0.2 0.2 0.2"></light>
		<body>
			<body name="object" pos="0 0 0.83">
				<site name="bottom_site" pos="0 0 -0.045" rgba="0 0 0 0"></site>
				<site name="top_site" pos="0 0 0.03" rgba="0 0 0 0"></site>
				<site name="horizontal_radius_site" pos="0.03 0.03 0" rgba="0 0 0 0"></site>
				<body name="cloth_0" pos="-0.23 0.2 0.00075">
					<inertial pos="0 0 0" mass="0.01" diaginertia="1.66667e-07 1.66667e-07 1.66667e-07"></inertial>
					<joint pos="0 0 0" axis="1 0 0" type="slide"></joint>
					<joint pos="0 0 0" axis="0 1 0" type="slide"></joint>
					<joint pos="0 0 0" axis="0 0 1" type="slide"></joint>
					<plugin instance="cloth_flexcomp_cloth"></plugin>
				</body>
				<body name="cloth_1" pos="-0.23 0.15 0.00076">
					<inertial pos="0 0 0" mass="0.01" diaginertia="1.66667e-07 1.66667e-07 1.66667e-07"></inertial>
					<joint pos="0 0 0" axis="1 0 0" type="slide"></joint>
					<joint pos="0 0 0" axis="0 1 0" type="slide"></joint>
					<joint pos="0 0 0" axis="0 0 1" type="slide"></joint>
					<plugin instance="cloth_flexcomp_cloth"></plugin>
				</body>
				<body name="cloth_2" pos="-0.22 0.096 0.00084">
					<inertial pos="0 0 0" mass="0.01" diaginertia="1.66667e-07 1.66667e-07 1.66667e-07"></inertial>
					<joint pos="0 0 0" axis="1 0 0" type="slide"></joint>
					<joint pos="0 0 0" axis="0 1 0" type="slide"></joint>
					<joint pos="0 0 0" axis="0 0 1" type="slide"></joint>
					<plugin instance="cloth_flexcomp_cloth"></plugin>
				</body>
				<body name="cloth_3" pos="-0.2 0.05 0.00064">
					<inertial pos="0 0 0" mass="0.01" diaginertia="1.66667e-07 1.66667e-07 1.66667e-07"></inertial>
					<joint pos="0 0 0" axis="1 0 0" type="slide"></joint>
					<joint pos="0 0 0" axis="0 1 0" type="slide"></joint>
					<joint pos="0 0 0" axis="0 0 1" type="slide"></joint>
					<plugin instance="cloth_flexcomp_cloth"></plugin>
				</body>
				<body name="cloth_4" pos="-0.18 0.096 0.00076">
					<inertial pos="0 0 0" mass="0.01" diaginertia="1.66667e-07 1.66667e-07 1.66667e-07"></inertial>
					<joint pos="0 0 0" axis="1 0 0" type="slide"></joint>
					<joint pos="0 0 0" axis="0 1 0" type="slide"></joint>
					<joint pos="0 0 0" axis="0 0 1" type="slide"></joint>
					<plugin instance="cloth_flexcomp_cloth"></plugin>
				</body>
				<body name="cloth_5" pos="-0.18 0.2 0.00075">
					<inertial pos="0 0 0" mass="0.01" diaginertia="1.66667e-07 1.66667e-07 1.66667e-07"></inertial>
					<joint pos="0 0 0" axis="1 0 0" type="slide"></joint>
					<joint pos="0 0 0" axis="0 1 0" type="slide"></joint>
					<joint pos="0 0 0" axis="0 0 1" type="slide"></joint>
					<plugin instance="cloth_flexcomp_cloth"></plugin>
				</body>
				<body name="cloth_6" pos="-0.18 0.15 0.0025">
					<inertial pos="0 0 0" mass="0.01" diaginertia="1.66667e-07 1.66667e-07 1.66667e-07"></inertial>
					<joint pos="0 0 0" axis="1 0 0" type="slide"></joint>
					<joint pos="0 0 0" axis="0 1 0" type="slide"></joint>
					<joint pos="0 0 0" axis="0 0 1" type="slide"></joint>
					<plugin instance="cloth_flexcomp_cloth"></plugin>
				</body>
				<body name="cloth_7" pos="-0.17 0.11 0.02">
					<inertial pos="0 0 0" mass="0.01" diaginertia="1.66667e-07 1.66667e-07 1.66667e-07"></inertial>
					<joint pos="0 0 0" axis="1 0 0" type="slide"></joint>
					<joint pos="0 0 0" axis="0 1 0" type="slide"></joint>
					<joint pos="0 0 0" axis="0 0 1" type="slide"></joint>
					<plugin instance="cloth_flexcomp_cloth"></plugin>
				</body>
				<body name="cloth_8" pos="-0.16 0.061 0.035">
					<inertial pos="0 0 0" mass="0.01" diaginertia="1.66667e-07 1.66667e-07 1.66667e-07"></inertial>
					<joint pos="0 0 0" axis="1 0 0" type="slide"></joint>
					<joint pos="0 0 0" axis="0 1 0" type="slide"></joint>
					<joint pos="0 0 0" axis="0 0 1" type="slide"></joint>
					<plugin instance="cloth_flexcomp_cloth"></plugin>
				</body>
				<body name="cloth_9" pos="-0.13 0.076 0.00066">
					<inertial pos="0 0 0" mass="0.01" diaginertia="1.66667e-07 1.66667e-07 1.66667e-07"></inertial>
					<joint pos="0 0 0" axis="1 0 0" type="slide"></joint>
					<joint pos="0 0 0" axis="0 1 0" type="slide"></joint>
					<joint pos="0 0 0" axis="0 0 1" type="slide"></joint>
					<plugin instance="cloth_flexcomp_cloth"></plugin>
				</body>
				<body name="cloth_10" pos="-0.18 0.15 0.00061">
					<inertial pos="0 0 0" mass="0.01" diaginertia="1.66667e-07 1.66667e-07 1.66667e-07"></inertial>
					<joint pos="0 0 0" axis="1 0 0" type="slide"></joint>
					<joint pos="0 0 0" axis="0 1 0" type="slide"></joint>
					<joint pos="0 0 0" axis="0 0 1" type="slide"></joint>
					<plugin instance="cloth_flexcomp_cloth"></plugin>
				</body>
				<body name="cloth_11" pos="-0.13 0.16 0.0016">
					<inertial pos="0 0 0" mass="0.01" diaginertia="1.66667e-07 1.66667e-07 1.66667e-07"></inertial>
					<joint pos="0 0 0" axis="1 0 0" type="slide"></joint>
					<joint pos="0 0 0" axis="0 1 0" type="slide"></joint>
					<joint pos="0 0 0" axis="0 0 1" type="slide"></joint>
					<plugin instance="cloth_flexcomp_cloth"></plugin>
				</body>
				<body name="cloth_12" pos="-0.13 0.11 0.00053">
					<inertial pos="0 0 0" mass="0.01" diaginertia="1.66667e-07 1.66667e-07 1.66667e-07"></inertial>
					<joint pos="0 0 0" axis="1 0 0" type="slide"></joint>
					<joint pos="0 0 0" axis="0 1 0" type="slide"></joint>
					<joint pos="0 0 0" axis="0 0 1" type="slide"></joint>
					<plugin instance="cloth_flexcomp_cloth"></plugin>
				</body>
				<body name="cloth_13" pos="-0.13 0.056 0.00086">
					<inertial pos="0 0 0" mass="0.01" diaginertia="1.66667e-07 1.66667e-07 1.66667e-07"></inertial>
					<joint pos="0 0 0" axis="1 0 0" type="slide"></joint>
					<joint pos="0 0 0" axis="0 1 0" type="slide"></joint>
					<joint pos="0 0 0" axis="0 0 1" type="slide"></joint>
					<plugin instance="cloth_flexcomp_cloth"></plugin>
				</body>
				<body name="cloth_14" pos="-0.093 0.074 0.034">
					<inertial pos="0 0 0" mass="0.01" diaginertia="1.66667e-07 1.66667e-07 1.66667e-07"></inertial>
					<joint pos="0 0 0" axis="1 0 0" type="slide"></joint>
					<joint pos="0 0 0" axis="0 1 0" type="slide"></joint>
					<joint pos="0 0 0" axis="0 0 1" type="slide"></joint>
					<plugin instance="cloth_flexcomp_cloth"></plugin>
				</body>
				<body name="cloth_15" pos="-0.13 0.16 0.00064">
					<inertial pos="0 0 0" mass="0.01" diaginertia="1.66667e-07 1.66667e-07 1.66667e-07"></inertial>
					<joint pos="0 0 0" axis="1 0 0" type="slide"></joint>
					<joint pos="0 0 0" axis="0 1 0" type="slide"></joint>
					<joint pos="0 0 0" axis="0 0 1" type="slide"></joint>
					<plugin instance="cloth_flexcomp_cloth"></plugin>
				</body>
				<body name="cloth_16" pos="-0.13 0.14 0.047">
					<inertial pos="0 0 0" mass="0.01" diaginertia="1.66667e-07 1.66667e-07 1.66667e-07"></inertial>
					<joint pos="0 0 0" axis="1 0 0" type="slide"></joint>
					<joint pos="0 0 0" axis="0 1 0" type="slide"></joint>
					<joint pos="0 0 0" axis="0 0 1" type="slide"></joint>
					<plugin instance="cloth_flexcomp_cloth"></plugin>
				</body>
				<body name="cloth_17" pos="-0.091 0.1 0.034">
					<inertial pos="0 0 0" mass="0.01" diaginertia="1.66667e-07 1.66667e-07 1.66667e-07"></inertial>
					<joint pos="0 0 0" axis="1 0 0" type="slide"></joint>
					<joint pos="0 0 0" axis="0 1 0" type="slide"></joint>
					<joint pos="0 0 0" axis="0 0 1" type="slide"></joint>
					<plugin instance="cloth_flexcomp_cloth"></plugin>
				</body>
				<body name="cloth_18" pos="-0.077 0.059 0.015">
					<inertial pos="0 0 0" mass="0.01" diaginertia="1.66667e-07 1.66667e-07 1.66667e-07"></inertial>
					<joint pos="0 0 0" axis="1 0 0" type="slide"></joint>
					<joint pos="0 0 0" axis="0 1 0" type="slide"></joint>
					<joint pos="0 0 0" axis="0 0 1" type="slide"></joint>
					<plugin instance="cloth_flexcomp_cloth"></plugin>
				</body>
				<body name="cloth_19" pos="-0.078 0.11 0.00075">
					<inertial pos="0 0 0" mass="0.01" diaginertia="1.66667e-07 1.66667e-07 1.66667e-07"></inertial>
					<joint pos="0 0 0" axis="1 0 0" type="slide"></joint>
					<joint pos="0 0 0" axis="0 1 0" type="slide"></joint>
					<joint pos="0 0 0" axis="0 0 1" type="slide"></joint>
					<plugin instance="cloth_flexcomp_cloth"></plugin>
				</body>
				<body name="cloth_20" pos="-0.12 0.11 0.00073">
					<inertial pos="0 0 0" mass="0.01" diaginertia="1.66667e-07 1.66667e-07 1.66667e-07"></inertial>
					<joint pos="0 0 0" axis="1 0 0" type="slide"></joint>
					<joint pos="0 0 0" axis="0 1 0" type="slide"></joint>
					<joint pos="0 0 0" axis="0 0 1" type="slide"></joint>
					<plugin instance="cloth_flexcomp_cloth"></plugin>
				</body>
				<body name="cloth_21" pos="-0.16 0.098 0.03">
					<inertial pos="0 0 0" mass="0.01" diaginertia="1.66667e-07 1.66667e-07 1.66667e-07"></inertial>
					<joint pos="0 0 0" axis="1 0 0" type="slide"></joint>
					<joint pos="0 0 0" axis="0 1 0" type="slide"></joint>
					<joint pos="0 0 0" axis="0 0 1" type="slide"></joint>
					<plugin instance="cloth_flexcomp_cloth"></plugin>
				</body>
				<body name="cloth_22" pos="-0.12 0.067 0.047">
					<inertial pos="0 0 0" mass="0.01" diaginertia="1.66667e-07 1.66667e-07 1.66667e-07"></inertial>
					<joint pos="0 0 0" axis="1 0 0" type="slide"></joint>
					<joint pos="0 0 0" axis="0 1 0" type="slide"></joint>
					<joint pos="0 0 0" axis="0 0 1" type="slide"></joint>
					<plugin instance="cloth_flexcomp_cloth"></plugin>
				</body>
				<body name="cloth_23" pos="-0.12 0.054 0.0004">
					<inertial pos="0 0 0" mass="0.01" diaginertia="1.66667e-07 1.66667e-07 1.66667e-07"></inertial>
					<joint pos="0 0 0" axis="1 0 0" type="slide"></joint>
					<joint pos="0 0 0" axis="0 1 0" type="slide"></joint>
					<joint pos="0 0 0" axis="0 0 1" type="slide"></joint>
					<plugin instance="cloth_flexcomp_cloth"></plugin>
				</body>
				<body name="cloth_24" pos="-0.13 0.1 0.00071">
					<inertial pos="0 0 0" mass="0.01" diaginertia="1.66667e-07 1.66667e-07 1.66667e-07"></inertial>
					<joint pos="0 0 0" axis="1 0 0" type="slide"></joint>
					<joint pos="0 0 0" axis="0 1 0" type="slide"></joint>
					<joint pos="0 0 0" axis="0 0 1" type="slide"></joint>
					<plugin instance="cloth_flexcomp_cloth"></plugin>
				</body>
				<body name="cloth_25" pos="-0.12 0.056 0.0043">
					<inertial pos="0 0 0" mass="0.01" diaginertia="1.66667e-07 1.66667e-07 1.66667e-07"></inertial>
					<joint pos="0 0 0" axis="1 0 0" type="slide"></joint>
					<joint pos="0 0 0" axis="0 1 0" type="slide"></joint>
					<joint pos="0 0 0" axis="0 0 1" type="slide"></joint>
					<plugin instance="cloth_flexcomp_cloth"></plugin>
				</body>
				<body name="cloth_26" pos="-0.17 0.06 0.0016">
					<inertial pos="0 0 0" mass="0.01" diaginertia="1.66667e-07 1.66667e-07 1.66667e-07"></inertial>
					<joint pos="0 0 0" axis="1 0 0" type="slide"></joint>
					<joint pos="0 0 0" axis="0 1 0" type="slide"></joint>
					<joint pos="0 0 0" axis="0 0 1" type="slide"></joint>
					<plugin instance="cloth_flexcomp_cloth"></plugin>
				</body>
				<body name="cloth_27" pos="-0.15 0.029 0.037">
					<inertial pos="0 0 0" mass="0.01" diaginertia="1.66667e-07 1.66667e-07 1.66667e-07"></inertial>
					<joint pos="0 0 0" axis="1 0 0" type="slide"></joint>
					<joint pos="0 0 0" axis="0 1 0" type="slide"></joint>
					<joint pos="0 0 0" axis="0 0 1" type="slide"></joint>
					<plugin instance="cloth_flexcomp_cloth"></plugin>
				</body>
				<body name="cloth_28" pos="-0.17 0.053 0.00061">
					<inertial pos="0 0 0" mass="0.01" diaginertia="1.66667e-07 1.66667e-07 1.66667e-07"></inertial>
					<joint pos="0 0 0" axis="1 0 0" type="slide"></joint>
					<joint pos="0 0 0" axis="0 1 0" type="slide"></joint>
					<joint pos="0 0 0" axis="0 0 1" type="slide"></joint>
					<plugin instance="cloth_flexcomp_cloth"></plugin>
				</body>
				<body name="cloth_29" pos="-0.18 0.1 0.00076">
					<inertial pos="0 0 0" mass="0.01" diaginertia="1.66667e-07 1.66667e-07 1.66667e-07"></inertial>
					<joint pos="0 0 0" axis="1 0 0" type="slide"></joint>
					<joint pos="0 0 0" axis="0 1 0" type="slide"></joint>
					<joint pos="0 0 0" axis="0 0 1" type="slide"></joint>
					<plugin instance="cloth_flexcomp_cloth"></plugin>
				</body>
				<body name="cloth_30" pos="-0.17 0.056 0.00093">
					<inertial pos="0 0 0" mass="0.01" diaginertia="1.66667e-07 1.66667e-07 1.66667e-07"></inertial>
					<joint pos="0 0 0" axis="1 0 0" type="slide"></joint>
					<joint pos="0 0 0" axis="0 1 0" type="slide"></joint>
					<joint pos="0 0 0" axis="0 0 1" type="slide"></joint>
					<plugin instance="cloth_flexcomp_cloth"></plugin>
				</body>
				<body name="cloth_31" pos="-0.18 0.055 0.051">
					<inertial pos="0 0 0" mass="0.01" diaginertia="1.66667e-07 1.66667e-07 1.66667e-07"></inertial>
					<joint pos="0 0 0" axis="1 0 0" type="slide"></joint>
					<joint pos="0 0 0" axis="0 1 0" type="slide"></joint>
					<joint pos="0 0 0" axis="0 0 1" type="slide"></joint>
					<plugin instance="cloth_flexcomp_cloth"></plugin>
				</body>
				<body name="cloth_32" pos="-0.2 0.011 0.043">
					<inertial pos="0 0 0" mass="0.01" diaginertia="1.66667e-07 1.66667e-07 1.66667e-07"></inertial>
					<joint pos="0 0 0" axis="1 0 0" type="slide"></joint>
					<joint pos="0 0 0" axis="0 1 0" type="slide"></joint>
					<joint pos="0 0 0" axis="0 0 1" type="slide"></joint>
					<plugin instance="cloth_flexcomp_cloth"></plugin>
				</body>
				<body name="cloth_33" pos="-0.22 0.054 0.022">
					<inertial pos="0 0 0" mass="0.01" diaginertia="1.66667e-07 1.66667e-07 1.66667e-07"></inertial>
					<joint pos="0 0 0" axis="1 0 0" type="slide"></joint>
					<joint pos="0 0 0" axis="0 1 0" type="slide"></joint>
					<joint pos="0 0 0" axis="0 0 1" type="slide"></joint>
					<plugin instance="cloth_flexcomp_cloth"></plugin>
				</body>
				<body name="cloth_34" pos="-0.23 0.098 0.00083">
					<inertial pos="0 0 0" mass="0.01" diaginertia="1.66667e-07 1.66667e-07 1.66667e-07"></inertial>
					<joint pos="0 0 0" axis="1 0 0" type="slide"></joint>
					<joint pos="0 0 0" axis="0 1 0" type="slide"></joint>
					<joint pos="0 0 0" axis="0 0 1" type="slide"></joint>
					<plugin instance="cloth_flexcomp_cloth"></plugin>
				</body>
				<body name="cloth_35" pos="-0.19 0.0081 0.0011">
					<inertial pos="0 0 0" mass="0.01" diaginertia="1.66667e-07 1.66667e-07 1.66667e-07"></inertial>
					<joint pos="0 0 0" axis="1 0 0" type="slide"></joint>
					<joint pos="0 0 0" axis="0 1 0" type="slide"></joint>
					<joint pos="0 0 0" axis="0 0 1" type="slide"></joint>
					<plugin instance="cloth_flexcomp_cloth"></plugin>
				</body>
				<body name="cloth_36" pos="-0.17 0.0045 0.049">
					<inertial pos="0 0 0" mass="0.01" diaginertia="1.66667e-07 1.66667e-07 1.66667e-07"></inertial>
					<joint pos="0 0 0" axis="1 0 0" type="slide"></joint>
					<joint pos="0 0 0" axis="0 1 0" type="slide"></joint>
					<joint pos="0 0 0" axis="0 0 1" type="slide"></joint>
					<plugin instance="cloth_flexcomp_cloth"></plugin>
				</body>
				<body name="cloth_37" pos="-0.17 0.0087 0.00043">
					<inertial pos="0 0 0" mass="0.01" diaginertia="1.66667e-07 1.66667e-07 1.66667e-07"></inertial>
					<joint pos="0 0 0" axis="1 0 0" type="slide"></joint>
					<joint pos="0 0 0" axis="0 1 0" type="slide"></joint>
					<joint pos="0 0 0" axis="0 0 1" type="slide"></joint>
					<plugin instance="cloth_flexcomp_cloth"></plugin>
				</body>
				<body name="cloth_38" pos="-0.17 0.059 0.00055">
					<inertial pos="0 0 0" mass="0.01" diaginertia="1.66667e-07 1.66667e-07 1.66667e-07"></inertial>
					<joint pos="0 0 0" axis="1 0 0" type="slide"></joint>
					<joint pos="0 0 0" axis="0 1 0" type="slide"></joint>
					<joint pos="0 0 0" axis="0 0 1" type="slide"></joint>
					<plugin instance="cloth_flexcomp_cloth"></plugin>
				</body>
				<body name="cloth_39" pos="-0.18 0.11 0.00081">
					<inertial pos="0 0 0" mass="0.01" diaginertia="1.66667e-07 1.66667e-07 1.66667e-07"></inertial>
					<joint pos="0 0 0" axis="1 0 0" type="slide"></joint>
					<joint pos="0 0 0" axis="0 1 0" type="slide"></joint>
					<joint pos="0 0 0" axis="0 0 1" type="slide"></joint>
					<plugin instance="cloth_flexcomp_cloth"></plugin>
				</body>
				<body name="cloth_40" pos="-0.17 -0.038 0.0009">
					<inertial pos="0 0 0" mass="0.01" diaginertia="1.66667e-07 1.66667e-07 1.66667e-07"></inertial>
					<joint pos="0 0 0" axis="1 0 0" type="slide"></joint>
					<joint pos="0 0 0" axis="0 1 0" type="slide"></joint>
					<joint pos="0 0 0" axis="0 0 1" type="slide"></joint>
					<plugin instance="cloth_flexcomp_cloth"></plugin>
				</body>
				<body name="cloth_41" pos="-0.13 -0.022 0.033">
					<inertial pos="0 0 0" mass="0.01" diaginertia="1.66667e-07 1.66667e-07 1.66667e-07"></inertial>
					<joint pos="0 0 0" axis="1 0 0" type="slide"></joint>
					<joint pos="0 0 0" axis="0 1 0" type="slide"></joint>
					<joint pos="0 0 0" axis="0 0 1" type="slide"></joint>
					<plugin instance="cloth_flexcomp_cloth"></plugin>
				</body>
				<body name="cloth_42" pos="-0.12 0.013 0.00047">
					<inertial pos="0 0 0" mass="0.01" diaginertia="1.66667e-07 1.66667e-07 1.66667e-07"></inertial>
					<joint pos="0 0 0" axis="1 0 0" type="slide"></joint>
					<joint pos="0 0 0" axis="0 1 0" type="slide"></joint>
					<joint pos="0 0 0" axis="0 0 1" type="slide"></joint>
					<plugin instance="cloth_flexcomp_cloth"></plugin>
				</body>
				<body name="cloth_43" pos="-0.12 0.062 0.00076">
					<inertial pos="0 0 0" mass="0.01" diaginertia="1.66667e-07 1.66667e-07 1.66667e-07"></inertial>
					<joint pos="0 0 0" axis="1 0 0" type="slide"></joint>
					<joint pos="0 0 0" axis="0 1 0" type="slide"></joint>
					<joint pos="0 0 0" axis="0 0 1" type="slide"></joint>
					<plugin instance="cloth_flexcomp_cloth"></plugin>
				</body>
				<body name="cloth_44" pos="-0.13 0.11 0.00076">
					<inertial pos="0 0 0" mass="0.01" diaginertia="1.66667e-07 1.66667e-07 1.66667e-07"></inertial>
					<joint pos="0 0 0" axis="1 0 0" type="slide"></joint>
					<joint pos="0 0 0" axis="0 1 0" type="slide"></joint>
					<joint pos="0 0 0" axis="0 0 1" type="slide"></joint>
					<plugin instance="cloth_flexcomp_cloth"></plugin>
				</body>
				<body name="cloth_45" pos="-0.12 -0.034 0.00076">
					<inertial pos="0 0 0" mass="0.01" diaginertia="1.66667e-07 1.66667e-07 1.66667e-07"></inertial>
					<joint pos="0 0 0" axis="1 0 0" type="slide"></joint>
					<joint pos="0 0 0" axis="0 1 0" type="slide"></joint>
					<joint pos="0 0 0" axis="0 0 1" type="slide"></joint>
					<plugin instance="cloth_flexcomp_cloth"></plugin>
				</body>
				<body name="cloth_46" pos="-0.12 0.016 0.00086">
					<inertial pos="0 0 0" mass="0.01" diaginertia="1.66667e-07 1.66667e-07 1.66667e-07"></inertial>
					<joint pos="0 0 0" axis="1 0 0" type="slide"></joint>
					<joint pos="0 0 0" axis="0 1 0" type="slide"></joint>
					<joint pos="0 0 0" axis="0 0 1" type="slide"></joint>
					<plugin instance="cloth_flexcomp_cloth"></plugin>
				</body>
				<body name="cloth_47" pos="-0.075 0.014 0.0099">
					<inertial pos="0 0 0" mass="0.01" diaginertia="1.66667e-07 1.66667e-07 1.66667e-07"></inertial>
					<joint pos="0 0 0" axis="1 0 0" type="slide"></joint>
					<joint pos="0 0 0" axis="0 1 0" type="slide"></joint>
					<joint pos="0 0 0" axis="0 0 1" type="slide"></joint>
					<plugin instance="cloth_flexcomp_cloth"></plugin>
				</body>
				<body name="cloth_48" pos="-0.075 0.064 0.0008">
					<inertial pos="0 0 0" mass="0.01" diaginertia="1.66667e-07 1.66667e-07 1.66667e-07"></inertial>
					<joint pos="0 0 0" axis="1 0 0" type="slide"></joint>
					<joint pos="0 0 0" axis="0 1 0" type="slide"></joint>
					<joint pos="0 0 0" axis="0 0 1" type="slide"></joint>
					<plugin instance="cloth_flexcomp_cloth"></plugin>
				</body>
				<body name="cloth_49" pos="-0.078 0.11 0.00076">
					<inertial pos="0 0 0" mass="0.01" diaginertia="1.66667e-07 1.66667e-07 1.66667e-07"></inertial>
					<joint pos="0 0 0" axis="1 0 0" type="slide"></joint>
					<joint pos="0 0 0" axis="0 1 0" type="slide"></joint>
					<joint pos="0 0 0" axis="0 0 1" type="slide"></joint>
					<plugin instance="cloth_flexcomp_cloth"></plugin>
				</body>
			</body>
		</body>
	</worldbody>
	<deformable>
		<flex name="cloth" radius="0.001" body="cloth_0 cloth_1 cloth_2 cloth_3 cloth_4 cloth_5 cloth_6 cloth_7 cloth_8 cloth_9 cloth_10 cloth_11 cloth_12 cloth_13 cloth_14 cloth_15 cloth_16 cloth_17 cloth_18 cloth_19 cloth_20 cloth_21 cloth_22 cloth_23 cloth_24 cloth_25 cloth_26 cloth_27 cloth_28 cloth_29 cloth_30 cloth_31 cloth_32 cloth_33 cloth_34 cloth_35 cloth_36 cloth_37 cloth_38 cloth_39 cloth_40 cloth_41 cloth_42 cloth_43 cloth_44 cloth_45 cloth_46 cloth_47 cloth_48 cloth_49" element="0 5 6 0 6 1 1 6 7 1 7 2 2 7 8 2 8 3 3 8 9 3 9 4 5 10 11 5 11 6 6 11 12 6 12 7 7 12 13 7 13 8 8 13 14 8 14 9 10 15 16 10 16 11 11 16 17 11 17 12 12 17 18 12 18 13 13 18 19 13 19 14 15 20 21 15 21 16 16 21 22 16 22 17 17 22 23 17 23 18 18 23 24 18 24 19 20 25 26 20 26 21 21 26 27 21 27 22 22 27 28 22 28 23 23 28 29 23 29 24 25 30 31 25 31 26 26 31 32 26 32 27 27 32 33 27 33 28 28 33 34 28 34 29 30 35 36 30 36 31 31 36 37 31 37 32 32 37 38 32 38 33 33 38 39 33 39 34 35 40 41 35 41 36 36 41 42 36 42 37 37 42 43 37 43 38 38 43 44 38 44 39 40 45 46 40 46 41 41 46 47 41 47 42 42 47 48 42 48 43 43 48 49 43 49 44">
			<contact solref="0.01 1" solimp="0.95 0.99 0.0001 0.5 2" condim="4" selfcollide="none"></contact>
			<edge damping="0.5"></edge>
		</flex>
	</deformable>
	<equality>
<!--		<flex flex="cloth"></flex>-->
		<flex flex="cloth_cloth"></flex>

	</equality>
</mujoco>